Workbook
Name Departamentos: '[1]BD Competencias'!$F$14:$F$41
Name Display_Week: [2]ProjectSchedule!$I$3
Name Project_Start: [2]ProjectSchedule!$I$2

Sheet SERVICIO
A1: GEOLIS
A2: PROYECTO:
A3: INGRESOS 2025 | B3: [USD] | C3: INSTALACIÓN | D3: M1 | E3: M2 | F3: M3 | G3: M4 | H3: M5 | I3: M6 | J3: M7 | K3: M8 | L3: M9 | M3: M10 | N3: M11 | O3: M12 | P3: M13
A4: DESCRIPCIÓN | B4: Total Presupuestado | C4: - | D4: ENE | E4: FEB | F4: MAR | G4: ABR | H4: MAY | I4: JUN | J4: JUL | K4: AGO | L4: SEP | M4: OCT | N4: NOV | O4: DIC | P4: ENE | Q4: Meses
A5: FACTURACION | B5: =SUM(C5:P5) -> 2633114.9 | C5: ='F08 INGRESOS'!M15 -> 0 | D5: ='F08 INGRESOS'!N15 -> 206127.68 | E5: ='F08 INGRESOS'!O15 -> 186179.84 | F5: ='F08 INGRESOS'!P15 -> 206127.68 | G5: ='F08 INGRESOS'!Q15 -> 199478.4 | H5: ='F08 INGRESOS'!R15 -> 206127.68 | I5: ='F08 INGRESOS'!S15 -> 199478.4 | J5: ='F08 INGRESOS'!T15 -> 206127.68 | ... P5: ='F08 INGRESOS'!Z15 -> 206127.68 | Q5: =COUNTA(E4:P4) -> 12 | S5: ='F08 INGRESOS'!M17 -> 2633114.9 | T5: =+B5-S5 -> 0
A6: INGRESOS 2025 | B6: [USD]
A7: DESCRIPCIÓN | B7: TOTAL PRESUPUESTADO | C7: - | D7: ENERO | E7: FEBRERO | F7: MARZO | G7: ABRIL | H7: MAYO | I7: JUNIO | J7: JULIO | K7: AGOSTO | L7: SEPTIEMBRE | M7: OCTUBRE | N7: NOVIEMBRE | O7: DICIEMBRE | P7: ENERO
A8: EQUIPO DE TRANSPORTE | B8: =SUM(C8:P8) -> 31800 | C8: ='F00 INVERSIÓN'!L11 -> 0 | D8: ='F00 INVERSIÓN'!M11 -> 0 | E8: ='F00 INVERSIÓN'!N11 -> 31800 | F8: ='F00 INVERSIÓN'!O11 -> 0 | G8: ='F00 INVERSIÓN'!P11 -> 0 | H8: ='F00 INVERSIÓN'!Q11 -> 0 | I8: ='F00 INVERSIÓN'!R11 -> 0 | J8: ='F00 INVERSIÓN'!S11 -> 0 | ... P8: ='F00 INVERSIÓN'!Y11 -> 0 | Q8: =B8/$B$166 -> 0.025042387
A9: EQUIPO DE MOBILIARIO | B9: =SUM(C9:P9) -> 0 | C9: ='F00 INVERSIÓN'!L17 -> 0 | D9: ='F00 INVERSIÓN'!M17 -> 0 | E9: ='F00 INVERSIÓN'!N17 -> 0 | F9: ='F00 INVERSIÓN'!O17 -> 0 | G9: ='F00 INVERSIÓN'!P17 -> 0 | H9: ='F00 INVERSIÓN'!Q17 -> 0 | I9: ='F00 INVERSIÓN'!R17 -> 0 | J9: ='F00 INVERSIÓN'!S17 -> 0 | ... P9: ='F00 INVERSIÓN'!Y17 -> 0 | Q9: =B9/$B$166 -> 0
A10: MAQUINARIA Y EQUIPO | B10: =SUM(C10:P10) -> 0 | C10: ='F00 INVERSIÓN'!L26 -> 0 | D10: ='F00 INVERSIÓN'!M26 -> 0 | E10: ='F00 INVERSIÓN'!N26 -> 0 | F10: ='F00 INVERSIÓN'!O26 -> 0 | G10: ='F00 INVERSIÓN'!P26 -> 0 | H10: ='F00 INVERSIÓN'!Q26 -> 0 | I10: ='F00 INVERSIÓN'!R26 -> 0 | J10: ='F00 INVERSIÓN'!S26 -> 0 | ... P10: ='F00 INVERSIÓN'!Y26 -> 0 | Q10: =B10/$B$166 -> 0
A11: OTROS ACTIVOS | B11: =SUM(C11:P11) -> 0 | C11: ='F00 INVERSIÓN'!L32 -> 0 | D11: ='F00 INVERSIÓN'!M32 -> 0 | E11: ='F00 INVERSIÓN'!N32 -> 0 | F11: ='F00 INVERSIÓN'!O32 -> 0 | G11: ='F00 INVERSIÓN'!P32 -> 0 | H11: ='F00 INVERSIÓN'!Q32 -> 0 | I11: ='F00 INVERSIÓN'!R32 -> 0 | J11: ='F00 INVERSIÓN'!S32 -> 0 | ... P11: ='F00 INVERSIÓN'!Y32 -> 0 | Q11: =B11/$B$166 -> 0
A12: SOFTWARE Y LICICENCIAS | B12: =SUM(C12:P12) -> 0 | C12: ='F00 INVERSIÓN'!L38 -> 0 | D12: ='F00 INVERSIÓN'!M38 -> 0 | E12: ='F00 INVERSIÓN'!N38 -> 0 | F12: ='F00 INVERSIÓN'!O38 -> 0 | G12: ='F00 INVERSIÓN'!P38 -> 0 | H12: ='F00 INVERSIÓN'!Q38 -> 0 | I12: ='F00 INVERSIÓN'!R38 -> 0 | J12: ='F00 INVERSIÓN'!S38 -> 0 | ... P12: ='F00 INVERSIÓN'!Y38 -> 0 | Q12: =B12/$B$166 -> 0
A13: ACTIVOS | B13: =SUM(B8:B12) -> 31800 | C13: =SUM(C8:C12) -> 0 | D13: =SUM(D8:D12) -> 0 | E13: =SUM(E8:E12) -> 31800 | F13: =SUM(F8:F12) -> 0 | G13: =SUM(G8:G12) -> 0 | H13: =SUM(H8:H12) -> 0 | I13: =SUM(I8:I12) -> 0 | ... P13: =SUM(P8:P12) -> 0 | Q13: =B13/$B$166 -> 0.025042387 | S13: ='F00 INVERSIÓN'!L42 -> 31800 | T13: =+B13-S13 -> 0
A14: ARRENDAMIENTO DE INMUEBLES | B14: =SUM(C14:P14) -> 0 | C14: ='F02 INMUEBLES Y S'!M7 -> 0 | D14: ='F02 INMUEBLES Y S'!N7 -> 0 | E14: ='F02 INMUEBLES Y S'!O7 -> 0 | F14: ='F02 INMUEBLES Y S'!P7 -> 0 | G14: ='F02 INMUEBLES Y S'!Q7 -> 0 | H14: ='F02 INMUEBLES Y S'!R7 -> 0 | I14: ='F02 INMUEBLES Y S'!S7 -> 0 | J14: ='F02 INMUEBLES Y S'!T7 -> 0 | ... P14: ='F02 INMUEBLES Y S'!Z7 -> 0 | Q14: =B14/$B$166 -> 0
A15: ENERGIA ELECTRICA | B15: =SUM(C15:P15) -> 0 | C15: ='F02 INMUEBLES Y S'!M8 -> 0 | D15: ='F02 INMUEBLES Y S'!N8 -> 0 | E15: ='F02 INMUEBLES Y S'!O8 -> 0 | F15: ='F02 INMUEBLES Y S'!P8 -> 0 | G15: ='F02 INMUEBLES Y S'!Q8 -> 0 | H15: ='F02 INMUEBLES Y S'!R8 -> 0 | I15: ='F02 INMUEBLES Y S'!S8 -> 0 | J15: ='F02 INMUEBLES Y S'!T8 -> 0 | ... P15: ='F02 INMUEBLES Y S'!Z8 -> 0 | Q15: =B15/$B$166 -> 0
A16: RENTA DE CASAS NO DEDUCIBLE | B16: =SUM(C16:P16) -> 0 | C16: ='F02 INMUEBLES Y S'!M9 -> 0 | D16: ='F02 INMUEBLES Y S'!N9 -> 0 | E16: ='F02 INMUEBLES Y S'!O9 -> 0 | F16: ='F02 INMUEBLES Y S'!P9 -> 0 | G16: ='F02 INMUEBLES Y S'!Q9 -> 0 | H16: ='F02 INMUEBLES Y S'!R9 -> 0 | I16: ='F02 INMUEBLES Y S'!S9 -> 0 | J16: ='F02 INMUEBLES Y S'!T9 -> 0 | ... P16: ='F02 INMUEBLES Y S'!Z9 -> 0 | Q16: =B16/$B$166 -> 0
A17: SERVICIOS DE LIMPIEZA | B17: =SUM(C17:P17) -> 0 | C17: ='F02 INMUEBLES Y S'!M10 -> 0 | D17: ='F02 INMUEBLES Y S'!N10 -> 0 | E17: ='F02 INMUEBLES Y S'!O10 -> 0 | F17: ='F02 INMUEBLES Y S'!P10 -> 0 | G17: ='F02 INMUEBLES Y S'!Q10 -> 0 | H17: ='F02 INMUEBLES Y S'!R10 -> 0 | I17: ='F02 INMUEBLES Y S'!S10 -> 0 | J17: ='F02 INMUEBLES Y S'!T10 -> 0 | ... P17: ='F02 INMUEBLES Y S'!Z10 -> 0 | Q17: =B17/$B$166 -> 0
A18: SERVICIOS DE VIGILANCIA | B18: =SUM(C18:P18) -> 0 | C18: ='F02 INMUEBLES Y S'!M11 -> 0 | D18: ='F02 INMUEBLES Y S'!N11 -> 0 | E18: ='F02 INMUEBLES Y S'!O11 -> 0 | F18: ='F02 INMUEBLES Y S'!P11 -> 0 | G18: ='F02 INMUEBLES Y S'!Q11 -> 0 | H18: ='F02 INMUEBLES Y S'!R11 -> 0 | I18: ='F02 INMUEBLES Y S'!S11 -> 0 | J18: ='F02 INMUEBLES Y S'!T11 -> 0 | ... P18: ='F02 INMUEBLES Y S'!Z11 -> 0 | Q18: =B18/$B$166 -> 0
A19: SERVICIOS DE FUMIGACION | B19: =SUM(C19:P19) -> 0 | C19: ='F02 INMUEBLES Y S'!M12 -> 0 | D19: ='F02 INMUEBLES Y S'!N12 -> 0 | E19: ='F02 INMUEBLES Y S'!O12 -> 0 | F19: ='F02 INMUEBLES Y S'!P12 -> 0 | G19: ='F02 INMUEBLES Y S'!Q12 -> 0 | H19: ='F02 INMUEBLES Y S'!R12 -> 0 | I19: ='F02 INMUEBLES Y S'!S12 -> 0 | J19: ='F02 INMUEBLES Y S'!T12 -> 0 | ... P19: ='F02 INMUEBLES Y S'!Z12 -> 0 | Q19: =B19/$B$166 -> 0
A20: TELEFONIA FIJA | B20: =SUM(C20:P20) -> 0 | C20: ='F02 INMUEBLES Y S'!M13 -> 0 | D20: ='F02 INMUEBLES Y S'!N13 -> 0 | E20: ='F02 INMUEBLES Y S'!O13 -> 0 | F20: ='F02 INMUEBLES Y S'!P13 -> 0 | G20: ='F02 INMUEBLES Y S'!Q13 -> 0 | H20: ='F02 INMUEBLES Y S'!R13 -> 0 | I20: ='F02 INMUEBLES Y S'!S13 -> 0 | J20: ='F02 INMUEBLES Y S'!T13 -> 0 | ... P20: ='F02 INMUEBLES Y S'!Z13 -> 0 | Q20: =B20/$B$166 -> 0
A21: AGUA Y ALCANTARILLADO | B21: =SUM(C21:P21) -> 11310 | C21: ='F02 INMUEBLES Y S'!M14 -> 0 | D21: ='F02 INMUEBLES Y S'!N14 -> 870 | E21: ='F02 INMUEBLES Y S'!O14 -> 870 | F21: ='F02 INMUEBLES Y S'!P14 -> 870 | G21: ='F02 INMUEBLES Y S'!Q14 -> 870 | H21: ='F02 INMUEBLES Y S'!R14 -> 870 | I21: ='F02 INMUEBLES Y S'!S14 -> 870 | J21: ='F02 INMUEBLES Y S'!T14 -> 870 | ... P21: ='F02 INMUEBLES Y S'!Z14 -> 870 | Q21: =B21/$B$166 -> 0.0089065849
A22: ARRENDAMIENTO DE OF. MOVILES | B22: =SUM(C22:P22) -> 14950 | C22: ='F02 INMUEBLES Y S'!M15 -> 0 | D22: ='F02 INMUEBLES Y S'!N15 -> 1150 | E22: ='F02 INMUEBLES Y S'!O15 -> 1150 | F22: ='F02 INMUEBLES Y S'!P15 -> 1150 | G22: ='F02 INMUEBLES Y S'!Q15 -> 1150 | H22: ='F02 INMUEBLES Y S'!R15 -> 1150 | I22: ='F02 INMUEBLES Y S'!S15 -> 1150 | J22: ='F02 INMUEBLES Y S'!T15 -> 1150 | ... P22: ='F02 INMUEBLES Y S'!Z15 -> 1150 | Q22: =B22/$B$166 -> 0.011773072
A23: ARRENDA DE INMUEBLES Y SERV | B23: =SUM(B14:B22) -> 26260 | C23: =SUM(C14:C22) -> 0 | D23: =SUM(D14:D22) -> 2020 | E23: =SUM(E14:E22) -> 2020 | F23: =SUM(F14:F22) -> 2020 | G23: =SUM(G14:G22) -> 2020 | H23: =SUM(H14:H22) -> 2020 | I23: =SUM(I14:I22) -> 2020 | ... P23: =SUM(P14:P22) -> 2020 | Q23: =B23/$B$166 -> 0.020679657 | S23: ='F02 INMUEBLES Y S'!M21 -> 26260 | T23: =+B23-S23 -> 0
A24: ROPA Y ARTICULOS DE PROTECCION | B24: =SUM(C24:P24) -> 5265 | C24: ='F01 EPP'!M19 -> 0 | D24: ='F01 EPP'!N19 -> 405 | E24: ='F01 EPP'!O19 -> 405 | F24: ='F01 EPP'!P19 -> 405 | G24: ='F01 EPP'!Q19 -> 405 | H24: ='F01 EPP'!R19 -> 405 | I24: ='F01 EPP'!S19 -> 405 | J24: ='F01 EPP'!T19 -> 405 | ... P24: ='F01 EPP'!Z19 -> 405 | Q24: =B24/$B$166 -> 0.0041461688
A25: ARTICULOS DE SEGURIDAD | B25: =B24 -> 5265 | C25: =C24 -> 0 | D25: =D24 -> 405 | E25: =E24 -> 405 | F25: =F24 -> 405 | G25: =G24 -> 405 | H25: =H24 -> 405 | I25: =I24 -> 405 | ... P25: =P24 -> 405 | Q25: =B25/$B$166 -> 0.0041461688 | S25: ='F01 EPP'!M21 -> 5265 | T25: =+B25-S25 -> 0
A26: EQUIPO DE COMPUTO (Adquisición) | B26: =SUM(C26:P26) -> 0 | C26: ='F03 COM Y EQ COM'!L47 -> 0 | D26: ='F03 COM Y EQ COM'!M47 -> 0 | E26: ='F03 COM Y EQ COM'!N47 -> 0 | F26: ='F03 COM Y EQ COM'!O47 -> 0 | G26: ='F03 COM Y EQ COM'!P47 -> 0 | H26: ='F03 COM Y EQ COM'!Q47 -> 0 | I26: ='F03 COM Y EQ COM'!R47 -> 0 | J26: ='F03 COM Y EQ COM'!S47 -> 0 | ... P26: ='F03 COM Y EQ COM'!Y47 -> 0 | Q26: =B26/$B$166 -> 0
A27: ARRENDAMIENTO DE EQ. COMPUTO | B27: =SUM(C27:P27) -> 0 | C27: ='F03 COM Y EQ COM'!L48 -> 0 | D27: ='F03 COM Y EQ COM'!M48 -> 0 | E27: ='F03 COM Y EQ COM'!N48 -> 0 | F27: ='F03 COM Y EQ COM'!O48 -> 0 | G27: ='F03 COM Y EQ COM'!P48 -> 0 | H27: ='F03 COM Y EQ COM'!Q48 -> 0 | I27: ='F03 COM Y EQ COM'!R48 -> 0 | J27: ='F03 COM Y EQ COM'!S48 -> 0 | ... P27: ='F03 COM Y EQ COM'!Y48 -> 0 | Q27: =B27/$B$166 -> 0
A28: EQUIPO DE COMPUTO | B28: =SUM(B26:B27) -> 0 | C28: =SUM(C26:C27) -> 0 | D28: =SUM(D26:D27) -> 0 | E28: =SUM(E26:E27) -> 0 | F28: =SUM(F26:F27) -> 0 | G28: =SUM(G26:G27) -> 0 | H28: =SUM(H26:H27) -> 0 | I28: =SUM(I26:I27) -> 0 | ... P28: =SUM(P26:P27) -> 0 | Q28: =B28/$B$166 -> 0 | S28: ='F03 COM Y EQ COM'!L52 -> 0 | T28: =+B28-S28 -> 0
A29: ENSERES MENORES DIVERSOS | B29: =SUM(C29:P29) -> 1072.5 | C29: ='F07 OPERAC. (MAT,SERV & EQUIPO)'!L21 -> 0 | D29: ='F07 OPERAC. (MAT,SERV & EQUIPO)'!M21 -> 82.5 | E29: ='F07 OPERAC. (MAT,SERV & EQUIPO)'!N21 -> 82.5 | F29: ='F07 OPERAC. (MAT,SERV & EQUIPO)'!O21 -> 82.5 | G29: ='F07 OPERAC. (MAT,SERV & EQUIPO)'!P21 -> 82.5 | H29: ='F07 OPERAC. (MAT,SERV & EQUIPO)'!Q21 -> 82.5 | I29: ='F07 OPERAC. (MAT,SERV & EQUIPO)'!R21 -> 82.5 | J29: ='F07 OPERAC. (MAT,SERV & EQUIPO)'!S21 -> 82.5 | ... P29: ='F07 OPERAC. (MAT,SERV & EQUIPO)'!Y21 -> 82.5 | Q29: =B29/$B$166 -> 0.00084458995
A30: EQUIPOS Y ENSERES | B30: =B29 -> 1072.5 | C30: =C29 -> 0 | D30: =D29 -> 82.5 | E30: =E29 -> 82.5 | F30: =F29 -> 82.5 | G30: =G29 -> 82.5 | H30: =H29 -> 82.5 | I30: =I29 -> 82.5 | ... P30: =P29 -> 82.5 | Q30: =B30/$B$166 -> 0.00084458995 | S30: ='F07 OPERAC. (MAT,SERV & EQUIPO)'!L23 -> 1072.5 | T30: =+B30-S30 -> 0
A31: INSUMOS AGRICOLAS | B31: =SUM(C31:P31) -> 750.2495 | C31: ='F07 OPERAC. (MAT,SERV & EQUIPO)'!L43 -> 0 | D31: ='F07 OPERAC. (MAT,SERV & EQUIPO)'!M43 -> 57.7115 | E31: ='F07 OPERAC. (MAT,SERV & EQUIPO)'!N43 -> 57.7115 | F31: ='F07 OPERAC. (MAT,SERV & EQUIPO)'!O43 -> 57.7115 | G31: ='F07 OPERAC. (MAT,SERV & EQUIPO)'!P43 -> 57.7115 | H31: ='F07 OPERAC. (MAT,SERV & EQUIPO)'!Q43 -> 57.7115 | I31: ='F07 OPERAC. (MAT,SERV & EQUIPO)'!R43 -> 57.7115 | J31: ='F07 OPERAC. (MAT,SERV & EQUIPO)'!S43 -> 57.7115 | ... P31: ='F07 OPERAC. (MAT,SERV & EQUIPO)'!Y43 -> 57.7115 | Q31: =B31/$B$166 -> 0.00059081882
A32: INSUMOS AGRICOLAS | B32: =B31 -> 750.2495 | C32: =C31 -> 0 | D32: =D31 -> 57.7115 | E32: =E31 -> 57.7115 | F32: =F31 -> 57.7115 | G32: =G31 -> 57.7115 | H32: =H31 -> 57.7115 | I32: =I31 -> 57.7115 | ... P32: =P31 -> 57.7115 | Q32: =B32/$B$166 -> 0.00059081882 | S32: ='F07 OPERAC. (MAT,SERV & EQUIPO)'!L45 -> 750.2495 | T32: =+B32-S32 -> 0
A33: PAPELERIA Y UTILES DE OFICINA | B33: =SUM(C33:P33) -> 325 | C33: ='F07 OPERAC. (MAT,SERV & EQUIPO)'!L125 -> 0 | D33: ='F07 OPERAC. (MAT,SERV & EQUIPO)'!M125 -> 25 | E33: ='F07 OPERAC. (MAT,SERV & EQUIPO)'!N125 -> 25 | F33: ='F07 OPERAC. (MAT,SERV & EQUIPO)'!O125 -> 25 | G33: ='F07 OPERAC. (MAT,SERV & EQUIPO)'!P125 -> 25 | H33: ='F07 OPERAC. (MAT,SERV & EQUIPO)'!Q125 -> 25 | I33: ='F07 OPERAC. (MAT,SERV & EQUIPO)'!R125 -> 25 | J33: ='F07 OPERAC. (MAT,SERV & EQUIPO)'!S125 -> 25 | ... P33: ='F07 OPERAC. (MAT,SERV & EQUIPO)'!Y125 -> 25 | Q33: =B33/$B$166 -> 0.00025593635
A34: ARTICULOS DE ASEO Y SANITARIOS | B34: =SUM(C34:P34) -> 195 | C34: ='F07 OPERAC. (MAT,SERV & EQUIPO)'!L126 -> 0 | D34: ='F07 OPERAC. (MAT,SERV & EQUIPO)'!M126 -> 15 | E34: ='F07 OPERAC. (MAT,SERV & EQUIPO)'!N126 -> 15 | F34: ='F07 OPERAC. (MAT,SERV & EQUIPO)'!O126 -> 15 | G34: ='F07 OPERAC. (MAT,SERV & EQUIPO)'!P126 -> 15 | H34: ='F07 OPERAC. (MAT,SERV & EQUIPO)'!Q126 -> 15 | I34: ='F07 OPERAC. (MAT,SERV & EQUIPO)'!R126 -> 15 | J34: ='F07 OPERAC. (MAT,SERV & EQUIPO)'!S126 -> 15 | ... P34: ='F07 OPERAC. (MAT,SERV & EQUIPO)'!Y126 -> 15 | Q34: =B34/$B$166 -> 0.00015356181
A35: ARTICULOS DE CAFETERIA | B35: =SUM(C35:P35) -> 0 | C35: ='F07 OPERAC. (MAT,SERV & EQUIPO)'!L127 -> 0 | D35: ='F07 OPERAC. (MAT,SERV & EQUIPO)'!M127 -> 0 | E35: ='F07 OPERAC. (MAT,SERV & EQUIPO)'!N127 -> 0 | F35: ='F07 OPERAC. (MAT,SERV & EQUIPO)'!O127 -> 0 | G35: ='F07 OPERAC. (MAT,SERV & EQUIPO)'!P127 -> 0 | H35: ='F07 OPERAC. (MAT,SERV & EQUIPO)'!Q127 -> 0 | I35: ='F07 OPERAC. (MAT,SERV & EQUIPO)'!R127 -> 0 | J35: ='F07 OPERAC. (MAT,SERV & EQUIPO)'!S127 -> 0 | ... P35: ='F07 OPERAC. (MAT,SERV & EQUIPO)'!Y127 -> 0 | Q35: =B35/$B$166 -> 0
A36: ARTICULOS DIGITALES Y DE COMPUTO | B36: =SUM(C36:P36) -> 0 | C36: ='F07 OPERAC. (MAT,SERV & EQUIPO)'!L128 -> 0 | D36: ='F07 OPERAC. (MAT,SERV & EQUIPO)'!M128 -> 0 | E36: ='F07 OPERAC. (MAT,SERV & EQUIPO)'!N128 -> 0 | F36: ='F07 OPERAC. (MAT,SERV & EQUIPO)'!O128 -> 0 | G36: ='F07 OPERAC. (MAT,SERV & EQUIPO)'!P128 -> 0 | H36: ='F07 OPERAC. (MAT,SERV & EQUIPO)'!Q128 -> 0 | I36: ='F07 OPERAC. (MAT,SERV & EQUIPO)'!R128 -> 0 | J36: ='F07 OPERAC. (MAT,SERV & EQUIPO)'!S128 -> 0 | ... P36: ='F07 OPERAC. (MAT,SERV & EQUIPO)'!Y128 -> 0 | Q36: =B36/$B$166 -> 0
A37: INSUMOS DE OFICINA | B37: =SUM(B33:B36) -> 520 | C37: =SUM(C33:C36) -> 0 | D37: =SUM(D33:D36) -> 40 | E37: =SUM(E33:E36) -> 40 | F37: =SUM(F33:F36) -> 40 | G37: =SUM(G33:G36) -> 40 | H37: =SUM(H33:H36) -> 40 | I37: =SUM(I33:I36) -> 40 | ... P37: =SUM(P33:P36) -> 40 | Q37: =B37/$B$166 -> 0.00040949816 | S37: ='F07 OPERAC. (MAT,SERV & EQUIPO)'!L132 -> 520 | T37: =+B37-S37 -> 0
A38: SERVICIOS DE MERCADOTECNIA | B38: =SUM(C38:P38) -> 0 | C38: ='F07 OPERAC. (MAT,SERV & EQUIPO)'!L139 -> 0 | D38: ='F07 OPERAC. (MAT,SERV & EQUIPO)'!M139 -> 0 | E38: ='F07 OPERAC. (MAT,SERV & EQUIPO)'!N139 -> 0 | F38: ='F07 OPERAC. (MAT,SERV & EQUIPO)'!O139 -> 0 | G38: ='F07 OPERAC. (MAT,SERV & EQUIPO)'!P139 -> 0 | H38: ='F07 OPERAC. (MAT,SERV & EQUIPO)'!Q139 -> 0 | I38: ='F07 OPERAC. (MAT,SERV & EQUIPO)'!R139 -> 0 | J38: ='F07 OPERAC. (MAT,SERV & EQUIPO)'!S139 -> 0 | ... P38: ='F07 OPERAC. (MAT,SERV & EQUIPO)'!Y139 -> 0 | Q38: =B38/$B$166 -> 0
A39: PUBLICIDAD Y PROPAGANDA | B39: =SUM(C39:P39) -> 0 | C39: ='F07 OPERAC. (MAT,SERV & EQUIPO)'!L140 -> 0 | D39: ='F07 OPERAC. (MAT,SERV & EQUIPO)'!M140 -> 0 | E39: ='F07 OPERAC. (MAT,SERV & EQUIPO)'!N140 -> 0 | F39: ='F07 OPERAC. (MAT,SERV & EQUIPO)'!O140 -> 0 | G39: ='F07 OPERAC. (MAT,SERV & EQUIPO)'!P140 -> 0 | H39: ='F07 OPERAC. (MAT,SERV & EQUIPO)'!Q140 -> 0 | I39: ='F07 OPERAC. (MAT,SERV & EQUIPO)'!R140 -> 0 | J39: ='F07 OPERAC. (MAT,SERV & EQUIPO)'!S140 -> 0 | ... P39: ='F07 OPERAC. (MAT,SERV & EQUIPO)'!Y140 -> 0 | Q39: =B39/$B$166 -> 0
A40: MARKETING | B40: =SUM(B38:B39) -> 0 | C40: =SUM(C38:C39) -> 0 | D40: =SUM(D38:D39) -> 0 | E40: =SUM(E38:E39) -> 0 | F40: =SUM(F38:F39) -> 0 | G40: =SUM(G38:G39) -> 0 | H40: =SUM(H38:H39) -> 0 | I40: =SUM(I38:I39) -> 0 | ... P40: =SUM(P38:P39) -> 0 | Q40: =B40/$B$166 -> 0 | S40: ='F07 OPERAC. (MAT,SERV & EQUIPO)'!L144 -> 0 | T40: =+B40-S40 -> 0
...

Sheet GRÁFICA

Sheet GRÁFICA II
B32: OPEX | C32: Mes 0 | D32: Instalación | E32: Mes 2 | F32: Mes 3 | G32: Mes 4 | H32: Mes 5 | I32: Mes 6 | J32: Mes 7 | K32: Mes 8 | L32: Mes 9 | M32: Mes 10 | N32: Mes 11 | O32: Mes 12 | P32: Mes 13 | Q32: Mes 14 | R32: Total
A33: 1 | B33: =SERVICIO!A23 -> ARRENDA DE INMUEBLES Y SERV | C33: =SERVICIO!C23 -> 0 | D33: =SERVICIO!D23 -> 2020 | E33: =SERVICIO!E23 -> 2020 | F33: =SERVICIO!F23 -> 2020 | G33: =SERVICIO!G23 -> 2020 | H33: =SERVICIO!H23 -> 2020 | I33: =SERVICIO!I23 -> 2020 | J33: =SERVICIO!J23 -> 2020 | ... P33: =SERVICIO!P23 -> 2020 | Q33: =SERVICIO!#REF! -> #REF! | R33: =SERVICIO!B23 -> 26260
A34: 2 | B34: =SERVICIO!A25 -> ARTICULOS DE SEGURIDAD | C34: =SERVICIO!C25 -> 0 | D34: =SERVICIO!D25 -> 405 | E34: =SERVICIO!E25 -> 405 | F34: =SERVICIO!F25 -> 405 | G34: =SERVICIO!G25 -> 405 | H34: =SERVICIO!H25 -> 405 | I34: =SERVICIO!I25 -> 405 | J34: =SERVICIO!J25 -> 405 | ... P34: =SERVICIO!P25 -> 405 | Q34: =SERVICIO!#REF! -> #REF! | R34: =SERVICIO!B25 -> 5265
A35: 3 | B35: =SERVICIO!A28 -> EQUIPO DE COMPUTO | C35: =SERVICIO!C28 -> 0 | D35: =SERVICIO!D28 -> 0 | E35: =SERVICIO!E28 -> 0 | F35: =SERVICIO!F28 -> 0 | G35: =SERVICIO!G28 -> 0 | H35: =SERVICIO!H28 -> 0 | I35: =SERVICIO!I28 -> 0 | J35: =SERVICIO!J28 -> 0 | ... P35: =SERVICIO!P28 -> 0 | Q35: =SERVICIO!#REF! -> #REF! | R35: =SERVICIO!B28 -> 0
A36: 4 | B36: =SERVICIO!A30 -> EQUIPOS Y ENSERES | C36: =SERVICIO!C30 -> 0 | D36: =SERVICIO!D30 -> 82.5 | E36: =SERVICIO!E30 -> 82.5 | F36: =SERVICIO!F30 -> 82.5 | G36: =SERVICIO!G30 -> 82.5 | H36: =SERVICIO!H30 -> 82.5 | I36: =SERVICIO!I30 -> 82.5 | J36: =SERVICIO!J30 -> 82.5 | ... P36: =SERVICIO!P30 -> 82.5 | Q36: =SERVICIO!#REF! -> #REF! | R36: =SERVICIO!B30 -> 1072.5
A37: 5 | B37: =SERVICIO!A32 -> INSUMOS AGRICOLAS | C37: =SERVICIO!C32 -> 0 | D37: =SERVICIO!D32 -> 57.7115 | E37: =SERVICIO!E32 -> 57.7115 | F37: =SERVICIO!F32 -> 57.7115 | G37: =SERVICIO!G32 -> 57.7115 | H37: =SERVICIO!H32 -> 57.7115 | I37: =SERVICIO!I32 -> 57.7115 | J37: =SERVICIO!J32 -> 57.7115 | ... P37: =SERVICIO!P32 -> 57.7115 | Q37: =SERVICIO!#REF! -> #REF! | R37: =SERVICIO!B32 -> 750.2495
A38: 6 | B38: =SERVICIO!A37 -> INSUMOS DE OFICINA | C38: =SERVICIO!C37 -> 0 | D38: =SERVICIO!D37 -> 40 | E38: =SERVICIO!E37 -> 40 | F38: =SERVICIO!F37 -> 40 | G38: =SERVICIO!G37 -> 40 | H38: =SERVICIO!H37 -> 40 | I38: =SERVICIO!I37 -> 40 | J38: =SERVICIO!J37 -> 40 | ... P38: =SERVICIO!P37 -> 40 | Q38: =SERVICIO!#REF! -> #REF! | R38: =SERVICIO!B37 -> 520
A39: 7 | B39: =SERVICIO!A40 -> MARKETING | C39: =SERVICIO!C40 -> 0 | D39: =SERVICIO!D40 -> 0 | E39: =SERVICIO!E40 -> 0 | F39: =SERVICIO!F40 -> 0 | G39: =SERVICIO!G40 -> 0 | H39: =SERVICIO!H40 -> 0 | I39: =SERVICIO!I40 -> 0 | J39: =SERVICIO!J40 -> 0 | ... P39: =SERVICIO!P40 -> 0 | Q39: =SERVICIO!#REF! -> #REF! | R39: =SERVICIO!B40 -> 0
A40: 8 | B40: =SERVICIO!A76 -> MATERIALES | C40: =SERVICIO!C76 -> 0 | D40: =SERVICIO!D76 -> 2760 | E40: =SERVICIO!E76 -> 1260 | F40: =SERVICIO!F76 -> 1260 | G40: =SERVICIO!G76 -> 3510 | H40: =SERVICIO!H76 -> 1260 | I40: =SERVICIO!I76 -> 2963 | J40: =SERVICIO!J76 -> 1260 | ... P40: =SERVICIO!P76 -> 1260 | Q40: =SERVICIO!#REF! -> #REF! | R40: =SERVICIO!B76 -> 23333
A41: 9 | B41: =SERVICIO!A78 -> MATERIALES DE SALUD | C41: =SERVICIO!C78 -> 0 | D41: =SERVICIO!D78 -> 35 | E41: =SERVICIO!E78 -> 35 | F41: =SERVICIO!F78 -> 35 | G41: =SERVICIO!G78 -> 35 | H41: =SERVICIO!H78 -> 35 | I41: =SERVICIO!I78 -> 35 | J41: =SERVICIO!J78 -> 35 | ... P41: =SERVICIO!P78 -> 35 | Q41: =SERVICIO!#REF! -> #REF! | R41: =SERVICIO!B78 -> 455
A42: 10 | B42: =SERVICIO!A80 -> NOMINA Y ADICIONALES | C42: =SERVICIO!C80 -> 0 | D42: =SERVICIO!D80 -> 16104.273 | E42: =SERVICIO!E80 -> 16104.273 | F42: =SERVICIO!F80 -> 16104.273 | G42: =SERVICIO!G80 -> 16104.273 | H42: =SERVICIO!H80 -> 21436.773 | I42: =SERVICIO!I80 -> 16104.273 | J42: =SERVICIO!J80 -> 16104.273 | ... P42: =SERVICIO!P80 -> 16104.273 | Q42: =SERVICIO!#REF! -> #REF! | R42: =SERVICIO!B80 -> 228019.29
A43: 11 | B43: =SERVICIO!A84 -> SERV TELEFONIA CELULAR Y RADIO | C43: =SERVICIO!C84 -> 0 | D43: =SERVICIO!D84 -> 75 | E43: =SERVICIO!E84 -> 75 | F43: =SERVICIO!F84 -> 75 | G43: =SERVICIO!G84 -> 75 | H43: =SERVICIO!H84 -> 75 | I43: =SERVICIO!I84 -> 75 | J43: =SERVICIO!J84 -> 75 | ... P43: =SERVICIO!P84 -> 75 | Q43: =SERVICIO!#REF! -> #REF! | R43: =SERVICIO!B84 -> 975
A44: 12 | B44: =SERVICIO!A148 -> SERVICIOS | C44: =SERVICIO!C148 -> 0 | D44: =SERVICIO!D148 -> 70537.5 | E44: =SERVICIO!E148 -> 70837.5 | F44: =SERVICIO!F148 -> 70387.5 | G44: =SERVICIO!G148 -> 70387.5 | H44: =SERVICIO!H148 -> 70387.5 | I44: =SERVICIO!I148 -> 70537.5 | J44: =SERVICIO!J148 -> 70387.5 | ... P44: =SERVICIO!P148 -> 75387.5 | Q44: =SERVICIO!#REF! -> #REF! | R44: =SERVICIO!B148 -> 920937.5
A45: 13 | B45: =SERVICIO!A150 -> SERVICIOS DE CAPACITACION | C45: =SERVICIO!C150 -> 0 | D45: =SERVICIO!D150 -> 250 | E45: =SERVICIO!E150 -> 250 | F45: =SERVICIO!F150 -> 250 | G45: =SERVICIO!G150 -> 250 | H45: =SERVICIO!H150 -> 250 | I45: =SERVICIO!I150 -> 250 | J45: =SERVICIO!J150 -> 250 | ... P45: =SERVICIO!P150 -> 250 | Q45: =SERVICIO!#REF! -> #REF! | R45: =SERVICIO!B150 -> 3250
A46: 14 | B46: =SERVICIO!A152 -> SERVICIOS DE SALUD | C46: =SERVICIO!C152 -> 0 | D46: =SERVICIO!D152 -> 113.034 | E46: =SERVICIO!E152 -> 113.034 | F46: =SERVICIO!F152 -> 113.034 | G46: =SERVICIO!G152 -> 113.034 | H46: =SERVICIO!H152 -> 113.034 | I46: =SERVICIO!I152 -> 113.034 | J46: =SERVICIO!J152 -> 113.034 | ... P46: =SERVICIO!P152 -> 113.034 | Q46: =SERVICIO!#REF! -> #REF! | R46: =SERVICIO!B152 -> 1469.442
A47: 15 | B47: =SERVICIO!A154 -> UNIFORMES | C47: =SERVICIO!C154 -> 0 | D47: =SERVICIO!D154 -> 144 | E47: =SERVICIO!E154 -> 144 | F47: =SERVICIO!F154 -> 144 | G47: =SERVICIO!G154 -> 144 | H47: =SERVICIO!H154 -> 144 | I47: =SERVICIO!I154 -> 144 | J47: =SERVICIO!J154 -> 144 | ... P47: =SERVICIO!P154 -> 144 | Q47: =SERVICIO!#REF! -> #REF! | R47: =SERVICIO!B154 -> 1872
A48: 16 | B48: =SERVICIO!A157 -> VEHICULOS Y COMBUSTIBLE | C48: =SERVICIO!C157 -> 0 | D48: =SERVICIO!D157 -> 1386 | E48: =SERVICIO!E157 -> 1386 | F48: =SERVICIO!F157 -> 1386 | G48: =SERVICIO!G157 -> 1386 | H48: =SERVICIO!H157 -> 1386 | I48: =SERVICIO!I157 -> 1386 | J48: =SERVICIO!J157 -> 1386 | ... P48: =SERVICIO!P157 -> 1386 | Q48: =SERVICIO!#REF! -> #REF! | R48: =SERVICIO!B157 -> 18018
A49: 17 | B49: =SERVICIO!A165 -> VIATICOS | C49: =SERVICIO!C165 -> 0 | D49: =SERVICIO!D165 -> 450 | E49: =SERVICIO!E165 -> 450 | F49: =SERVICIO!F165 -> 450 | G49: =SERVICIO!G165 -> 450 | H49: =SERVICIO!H165 -> 450 | I49: =SERVICIO!I165 -> 450 | J49: =SERVICIO!J165 -> 450 | ... P49: =SERVICIO!P165 -> 450 | Q49: =SERVICIO!#REF! -> #REF! | R49: =SERVICIO!B165 -> 5850
R50: =SUM(R33:R49) -> 1238047

Sheet FLUJO
D1: 0 | E1: 1 | F1: 2 | G1: 3 | H1: 4 | I1: 5 | J1: 6 | K1: 7 | L1: 8 | M1: 9 | N1: 10 | O1: 11 | P1: 12
C3: Instalación | D3: Instalación | E3: Mes 1 | F3: Mes 2 | G3: Mes 3 | H3: Mes 4 | I3: Mes 5 | J3: Mes 6 | K3: Mes 7 | L3: Mes 8 | M3: Mes 9 | N3: Mes 10 | O3: Mes 11 | P3: Mes 12 | R3: =SUM(R6:R9) -> 0 | T3: =R3*1.16 -> 0 | V3: =+R3/$E$37 -> 0 | X3: =V3*1.16 -> 0
C4: JUN | D4: JUL | E4: AGO | F4: SEP | G4: OCT | H4: NOV | I4: DIC | J4: ENE | K4: FEB | L4: MAR | M4: ABR | N4: MAY | O4: JUN | P4: JUL | R4: TOTAL PROYECTO (MN) | T4: TOTAL PROYECTO IVA (MN) | V4: TOTAL PROYECTO (USD) | X4: TOTAL PROYECTO IVA (USD)
A5: Ingresos (MN) | C5: 31 | D5: 30 | E5: 31 | F5: 30 | G5: 31 | H5: 30 | I5: 31 | J5: 31 | K5: 28 | L5: 31 | M5: 30 | N5: 31 | O5: 30 | P5: 31
A6: =PREMISAS!C9 -> Patín con bomba electrocentrifuga horizontal con gasto de 10,000-20,000 BPD incluye la operación continua. | C6: ='F08 INGRESOS'!M7 -> 0 | D6: ='F08 INGRESOS'!N7 -> 0 | E6: ='F08 INGRESOS'!O7 -> 0 | F6: ='F08 INGRESOS'!P7 -> 0 | G6: ='F08 INGRESOS'!Q7 -> 0 | H6: ='F08 INGRESOS'!R7 -> 0 | I6: ='F08 INGRESOS'!S7 -> 0 | J6: ='F08 INGRESOS'!T7 -> 0 | ... P6: ='F08 INGRESOS'!Z7 -> 0 | R6: =SUM(C6:P6) -> 0 | T6: =R6*1.16 -> 0 | V6: =+R6/$E$37 -> 0 | X6: =V6*1.16 -> 0
A7: =PREMISAS!C10 -> Patín con bomba electrocentrifuga horizontal con gasto de 20,000-30,000 BPD incluye la operación continua. | C7: ='F08 INGRESOS'!M8 -> 0 | D7: ='F08 INGRESOS'!N8 -> 0 | E7: ='F08 INGRESOS'!O8 -> 0 | F7: ='F08 INGRESOS'!P8 -> 0 | G7: ='F08 INGRESOS'!Q8 -> 0 | H7: ='F08 INGRESOS'!R8 -> 0 | I7: ='F08 INGRESOS'!S8 -> 0 | J7: ='F08 INGRESOS'!T8 -> 0 | ... P7: ='F08 INGRESOS'!Z8 -> 0 | R7: =SUM(C7:P7) -> 0 | T7: =R7*1.16 -> 0 | V7: =+R7/$E$37 -> 0 | X7: =V7*1.16 -> 0
A8: =PREMISAS!C11 -> Generador de energía a gas de 300 KW/375 KVA. | C8: ='F08 INGRESOS'!M12 -> 0 | D8: ='F08 INGRESOS'!N12 -> 0 | E8: ='F08 INGRESOS'!O12 -> 0 | F8: ='F08 INGRESOS'!P12 -> 0 | G8: ='F08 INGRESOS'!Q12 -> 0 | H8: ='F08 INGRESOS'!R12 -> 0 | I8: ='F08 INGRESOS'!S12 -> 0 | J8: ='F08 INGRESOS'!T12 -> 0 | ... P8: ='F08 INGRESOS'!Z12 -> 0 | R8: =SUM(C8:P8) -> 0 | T8: =R8*1.16 -> 0 | V8: =+R8/$E$37 -> 0 | X8: =V8*1.16 -> 0
A9: =PREMISAS!C15 -> 0 | C9: ='F08 INGRESOS'!M13 -> 0 | D9: ='F08 INGRESOS'!N13 -> 0 | E9: ='F08 INGRESOS'!O13 -> 0 | F9: ='F08 INGRESOS'!P13 -> 0 | G9: ='F08 INGRESOS'!Q13 -> 0 | H9: ='F08 INGRESOS'!R13 -> 0 | I9: ='F08 INGRESOS'!S13 -> 0 | J9: ='F08 INGRESOS'!T13 -> 0 | ... P9: ='F08 INGRESOS'!Z13 -> 0 | R9: =SUM(C9:P9) -> 0 | T9: =R9*1.16 -> 0 | V9: =+R9/$E$37 -> 0 | X9: =V9*1.16 -> 0
A11: Ingresos Totales (MN) | C11: =SUM(C6:C10) -> 0 | D11: =SUM(D6:D10) -> 0 | E11: =SUM(E6:E10) -> 0 | F11: =SUM(F6:F10) -> 0 | G11: =SUM(G6:G10) -> 0 | H11: =SUM(H6:H10) -> 0 | I11: =SUM(I6:I10) -> 0 | J11: =SUM(J6:J10) -> 0 | ... P11: =SUM(P6:P10) -> 0 | R11: =SUM(C11:P11) -> 0
A13: Ingresos Totales (MN) IVA | C13: =+C11*1.16 -> 0 | D13: =+D11*1.16 -> 0 | E13: =+E11*1.16 -> 0 | F13: =+F11*1.16 -> 0 | G13: =+G11*1.16 -> 0 | H13: =+H11*1.16 -> 0 | I13: =+I11*1.16 -> 0 | J13: =+J11*1.16 -> 0 | ... P13: =+P11*1.16 -> 0 | R13: =SUM(C13:P13) -> 0
A15: Egresos (MX)
A16: OPEX | C16: =EGRESOS!D37 -> 0 | D16: =EGRESOS!E37 -> 94460.018 | E16: =EGRESOS!F37 -> 93260.018 | F16: =EGRESOS!G37 -> 92810.018 | G16: =EGRESOS!H37 -> 95060.018 | H16: =EGRESOS!I37 -> 98142.518 | I16: =EGRESOS!J37 -> 94663.018 | J16: =EGRESOS!K37 -> 92810.018 | ... P16: =EGRESOS!Q37 -> 97810.018 | R16: =SUM(C16:P16) -> 1238047 | V16: =+R16/$E$37 -> 61902.349 | X16: =+V16*1.16 -> 71806.725
A17: FINANCIAMIENTO
A18: CAPEX | C18: =EGRESOS!D35 -> 0 | D18: =EGRESOS!E35 -> 0 | E18: =EGRESOS!F35 -> 31800 | F18: =EGRESOS!G35 -> 0 | G18: =EGRESOS!H35 -> 0 | H18: =EGRESOS!I35 -> 0 | I18: =EGRESOS!J35 -> 0 | J18: =EGRESOS!K35 -> 0 | ... P18: =EGRESOS!Q35 -> 0 | R18: =SUM(C18:P18) -> 31800 | V18: =+R18/$E$37 -> 1590 | X18: =+V18*1.16 -> 1844.4
A20: Egresos Totales (MN) | C20: =SUM(C16:C19) -> 0 | D20: =SUM(D16:D19) -> 94460.018 | E20: =SUM(E16:E19) -> 125060.02 | F20: =SUM(F16:F19) -> 92810.018 | G20: =SUM(G16:G19) -> 95060.018 | H20: =SUM(H16:H19) -> 98142.518 | I20: =SUM(I16:I19) -> 94663.018 | J20: =SUM(J16:J19) -> 92810.018 | ... P20: =SUM(P16:P19) -> 97810.018 | R20: =SUM(C20:P20) -> 1269847 | T20: =+R20*1.16 -> 1473022.5 | V20: =+R20/$E$37 -> 63492.349 | X20: =+V20*1.16 -> 73651.125
A22: Egresos Totales (MN) IVA | C22: =+C20*1.16 -> 0 | D22: =+D20*1.16 -> 109573.62 | E22: =+E20*1.16 -> 145069.62 | F22: =+F20*1.16 -> 107659.62 | G22: =+G20*1.16 -> 110269.62 | H22: =+H20*1.16 -> 113845.32 | I22: =+I20*1.16 -> 109809.1 | J22: =+J20*1.16 -> 107659.62 | ... P22: =+P20*1.16 -> 113459.62 | R22: =SUM(C22:P22) -> 1473022.5 | T22: =+R22*1.16 -> 1708706.1 | V22: =+R22/$E$37 -> 73651.125 | X22: =+V22*1.16 -> 85435.305
A24: FLUJO EFECTIVO | C24: =C11-C20 -> 0 | D24: =D11-D20 -> -94460.018 | E24: =E11-E20 -> -125060.02 | F24: =F11-F20 -> -92810.018 | G24: =G11-G20 -> -95060.018 | H24: =H11-H20 -> -98142.518 | I24: =I11-I20 -> -94663.018 | J24: =J11-J20 -> -92810.018 | ... P24: =P11-P20 -> -97810.018
A26: FLUJO EFECTIVO IVA | C26: =+C24*1.16 -> 0 | D26: =+D24*1.16 -> -109573.62 | E26: =+E24*1.16 -> -145069.62 | F26: =+F24*1.16 -> -107659.62 | G26: =+G24*1.16 -> -110269.62 | H26: =+H24*1.16 -> -113845.32 | I26: =+I24*1.16 -> -109809.1 | J26: =+J24*1.16 -> -107659.62 | ... P26: =+P24*1.16 -> -113459.62
A28: FLUJO ACUMULADO | C28: =+C24 -> 0 | D28: =+D24+C28 -> -94460.018 | E28: =+E24+D28 -> -219520.04 | F28: =+F24+E28 -> -312330.05 | G28: =+G24+F28 -> -407390.07 | H28: =+H24+G28 -> -505532.59 | I28: =+I24+H28 -> -600195.61 | J28: =+J24+I28 -> -693005.63 | K28: =+K24+J28 -> -785815.64 | ... P28: =+P24+O28 -> -1269847
A30: FLUJO ACUMULADO IVA | C30: =+C28*1.16 -> 0 | D30: =+D28*1.16 -> -109573.62 | E30: =+E28*1.16 -> -254643.24 | F30: =+F28*1.16 -> -362302.86 | G30: =+G28*1.16 -> -472572.48 | H30: =+H28*1.16 -> -586417.81 | I30: =+I28*1.16 -> -696226.91 | J30: =+J28*1.16 -> -803886.53 | ... P30: =+P28*1.16 -> -1473022.5
C32: OPEX Promedio | D32: =AVERAGE(C16:P16) -> 88431.928
C33: CAPEX | D33: =SUM(C18:G18) -> 31800
C34: Opex Total | D34: =SUM(C16:P16) -> 1238047
C36: FACTORES DE SENSIBILIDAD | G36: RESULTADOS (MMMN)
C37: Tipo de Cambio | E37: =PREMISAS!I23 -> 20 | I37: Total Ingresos | J37: =SUM(R11)/1000000 -> 0
F38: USD | I38: Total Egresos | J38: =SUM(R20)/1000000 -> 1.269847
F39: USD
C40: Equipo sup. | F40: USD
C41: Instalación | F41: USD
C42: Gas lp | F42: (USD/L)
C43: Desinstalación | F43: USD
C44: Telemetría | F44: USD
C46: Préstamo | F46: USD | G46: EBTDA Acumulado | H46: =(R11-R20)/1000000 -> -1.269847 | I46: EBTDA Anual | J46: =H46/E50 -> -0.84656466
C47: Capital de trabajo | E47: =MIN(C30:P30) -> -1473022.5 | G47: VPN | H47: =(NPV(E48/18,D24:P24))/1000000 -> -1.2130659 | I47: VPN Anual | J47: =H47/E50 -> -0.80871058
C48: Tasa de VPN y VPI Anual | E48: 0.12 | G48: VPI | H48: =(NPV(E48/18,D18:P18))/1000000 -> 0.031380203
C49: Meses de Préstamo | G49: Punto de Equilibrio | I49: meses
C50: Años del proyecto | E50: 1.5 | G50: TIR | H50: =XIRR(D24:P24,D4:P4) -> #VALUE! | I50: %
G51: Utilidades | H51: =+H46/J37 -> #DIV/0!
C52: OPEX mensual (MMMN) | E52: =((AVERAGE(C16:P16)/1000000)) -> 0.088431928
C53: CAPEX total (MMMN) | E53: =R18/1000000 -> 0.0318 | G53: VPN/VPI | H53: =H47/H48 -> -38.657044

Sheet EGRESOS
A2: REFERENCIA EGRESO - JD EDWARDS
D4: Instalación | E4: Instalación | F4: Mes 1 | G4: Mes 2 | H4: Mes 3 | I4: Mes 4 | J4: Mes 5 | K4: Mes 6 | L4: Mes 7 | M4: Mes 8 | N4: Mes 9 | O4: Mes 10 | P4: Mes 11 | Q4: Mes 12
D5: JUN | E5: JUL | F5: AGO | G5: SEP | H5: OCT | I5: NOV | J5: DIC | K5: ENE | L5: FEB | M5: MAR | N5: ABR | O5: MAY | P5: JUN | Q5: JUL | R5: TOTAL PROYECTO (MXN) | T5: TOTAL PROYECTO (USD)
D6: 31 | E6: 30 | F6: 31 | G6: 30 | H6: 31 | I6: 30 | J6: 31 | K6: 31 | L6: 28 | M6: 31 | N6: 30 | O6: 31 | P6: 30 | Q6: 31
A8: INVERSIÓN | D8: ='F00 INVERSIÓN'!L40 -> 0 | E8: ='F00 INVERSIÓN'!M40 -> 0 | F8: ='F00 INVERSIÓN'!N40 -> 31800 | G8: ='F00 INVERSIÓN'!O40 -> 0 | H8: ='F00 INVERSIÓN'!P40 -> 0 | I8: ='F00 INVERSIÓN'!Q40 -> 0 | J8: ='F00 INVERSIÓN'!R40 -> 0 | K8: ='F00 INVERSIÓN'!S40 -> 0 | ... Q8: ='F00 INVERSIÓN'!Y40 -> 0 | R8: =SUM(D8:Q8) -> 31800 | T8: =R8/$E$42 -> 1590 | V8: ='F00 INVERSIÓN'!L42 -> 31800 | W8: =SERVICIO!B13 -> 31800 | X8: =V8-R8 -> 0 | Y8: =V8-W8 -> 0
B9: ACTIVOS
A10: NOMINA Y ADICIONALES | D10: =NOMINA!V19+'F01 EPP'!M19+'F01 UNIFORMES'!M12 -> 0 | E10: =NOMINA!W19+'F01 EPP'!N19+'F01 UNIFORMES'!N12 -> 16653.273 | F10: =NOMINA!X19+'F01 EPP'!O19+'F01 UNIFORMES'!O12 -> 16653.273 | G10: =NOMINA!Y19+'F01 EPP'!P19+'F01 UNIFORMES'!P12 -> 16653.273 | H10: =NOMINA!Z19+'F01 EPP'!Q19+'F01 UNIFORMES'!Q12 -> 16653.273 | I10: =NOMINA!AA19+'F01 EPP'!R19+'F01 UNIFORMES'!R12 -> 21985.773 | J10: =NOMINA!AB19+'F01 EPP'!S19+'F01 UNIFORMES'!S12 -> 16653.273 | K10: =NOMINA!AC19+'F01 EPP'!T19+'F01 UNIFORMES'!T12 -> 16653.273 | ... Q10: =NOMINA!AI19+'F01 EPP'!Z19+'F01 UNIFORMES'!Z12 -> 16653.273 | R10: =SUM(D10:Q10) -> 235156.29 | T10: =R10/$E$42 -> 11757.815 | V10: =+NOMINA!V21+'F01 EPP'!M21+'F01 UNIFORMES'!M14 -> 235156.29 | W10: =SERVICIO!B80+SERVICIO!B25+SERVICIO!B154 -> 235156.29 | X10: =V10-R10 -> 0 | Y10: =V10-W10 -> 0
B11: NÓMINA + EPP + UNIFORMES
A12: INMUEBLES Y SERVICIOS | D12: ='F02 INMUEBLES Y S'!M19 -> 0 | E12: ='F02 INMUEBLES Y S'!N19 -> 2020 | F12: ='F02 INMUEBLES Y S'!O19 -> 2020 | G12: ='F02 INMUEBLES Y S'!P19 -> 2020 | H12: ='F02 INMUEBLES Y S'!Q19 -> 2020 | I12: ='F02 INMUEBLES Y S'!R19 -> 2020 | J12: ='F02 INMUEBLES Y S'!S19 -> 2020 | K12: ='F02 INMUEBLES Y S'!T19 -> 2020 | ... Q12: ='F02 INMUEBLES Y S'!Z19 -> 2020 | R12: =SUM(D12:Q12) -> 26260 | T12: =R12/$E$42 -> 1313 | V12: ='F02 INMUEBLES Y S'!M21 -> 26260 | W12: =SERVICIO!B23 -> 26260 | X12: =V12-R12 -> 0 | Y12: =V12-W12 -> 0
B13: INMUEBLES
A14: TELEFONIA Y COMUNICACIÓN | D14: ='F03 COM Y EQ COM'!L35 -> 0 | E14: ='F03 COM Y EQ COM'!M35 -> 75 | F14: ='F03 COM Y EQ COM'!N35 -> 75 | G14: ='F03 COM Y EQ COM'!O35 -> 75 | H14: ='F03 COM Y EQ COM'!P35 -> 75 | I14: ='F03 COM Y EQ COM'!Q35 -> 75 | J14: ='F03 COM Y EQ COM'!R35 -> 75 | K14: ='F03 COM Y EQ COM'!S35 -> 75 | ... Q14: ='F03 COM Y EQ COM'!Y35 -> 75 | R14: =SUM(D14:Q14) -> 975 | T14: =R14/$E$42 -> 48.75 | V14: ='F03 COM Y EQ COM'!L37 -> 975 | W14: =SERVICIO!B84 -> 975 | X14: =V14-R14 -> 0 | Y14: =V14-W14 -> 0
B15: COM Y EQ COM
A16: VEHICULOS Y COMBUSTIBLE | D16: ='F04 VEHÍCULOS Y COMB. '!R30 -> 0 | E16: ='F04 VEHÍCULOS Y COMB. '!S30 -> 1386 | F16: ='F04 VEHÍCULOS Y COMB. '!T30 -> 1386 | G16: ='F04 VEHÍCULOS Y COMB. '!U30 -> 1386 | H16: ='F04 VEHÍCULOS Y COMB. '!V30 -> 1386 | I16: ='F04 VEHÍCULOS Y COMB. '!W30 -> 1386 | J16: ='F04 VEHÍCULOS Y COMB. '!X30 -> 1386 | K16: ='F04 VEHÍCULOS Y COMB. '!Y30 -> 1386 | ... Q16: ='F04 VEHÍCULOS Y COMB. '!AE30 -> 1386 | R16: =SUM(D16:Q16) -> 18018 | T16: =R16/$E$42 -> 900.9 | V16: ='F04 VEHÍCULOS Y COMB. '!R32 -> 18018 | W16: =SERVICIO!B157 -> 18018 | X16: =V16-R16 -> 0 | Y16: =V16-W16 -> 0
B17: VEHÍCULOS Y COMB
A18: VIATICOS | D18: ='F05 VIÁTICOS'!K27 -> 0 | E18: ='F05 VIÁTICOS'!L27 -> 450 | F18: ='F05 VIÁTICOS'!M27 -> 450 | G18: ='F05 VIÁTICOS'!N27 -> 450 | H18: ='F05 VIÁTICOS'!O27 -> 450 | I18: ='F05 VIÁTICOS'!P27 -> 450 | J18: ='F05 VIÁTICOS'!Q27 -> 450 | K18: ='F05 VIÁTICOS'!R27 -> 450 | ... Q18: ='F05 VIÁTICOS'!X27 -> 450 | R18: =SUM(D18:Q18) -> 5850 | T18: =R18/$E$42 -> 292.5 | V18: ='F05 VIÁTICOS'!K29 -> 5850 | W18: =SERVICIO!B165 -> 5850 | X18: =V18-R18 -> 0 | Y18: =V18-W18 -> 0
B19: VIATICOS CAJA CHICA Y REEMBOLSO
A20: MAT, SERV & EQUIPO | D20: ='F06 (MAT,SERV & EQUIPO)'!L43 -> 0 | E20: ='F06 (MAT,SERV & EQUIPO)'!M43 -> 2760 | F20: ='F06 (MAT,SERV & EQUIPO)'!N43 -> 1260 | G20: ='F06 (MAT,SERV & EQUIPO)'!O43 -> 1260 | H20: ='F06 (MAT,SERV & EQUIPO)'!P43 -> 3510 | I20: ='F06 (MAT,SERV & EQUIPO)'!Q43 -> 1260 | J20: ='F06 (MAT,SERV & EQUIPO)'!R43 -> 2963 | K20: ='F06 (MAT,SERV & EQUIPO)'!S43 -> 1260 | ... Q20: ='F06 (MAT,SERV & EQUIPO)'!Y43 -> 1260 | R20: =SUM(D20:Q20) -> 23333 | T20: =R20/$E$42 -> 1166.65 | V20: ='F06 (MAT,SERV & EQUIPO)'!L45 -> 23333 | W20: =SERVICIO!B76 -> 23333 | X20: =V20-R20 -> 0 | Y20: =V20-W20 -> 0
B21: MAT,SERV & EQUIPO
A22: SERVICIOS | D22: ='F07 OPERAC. (MAT,SERV & EQUIPO)'!L116 -> 0 | E22: ='F07 OPERAC. (MAT,SERV & EQUIPO)'!M116 -> 70537.5 | F22: ='F07 OPERAC. (MAT,SERV & EQUIPO)'!N116 -> 70837.5 | G22: ='F07 OPERAC. (MAT,SERV & EQUIPO)'!O116 -> 70387.5 | H22: ='F07 OPERAC. (MAT,SERV & EQUIPO)'!P116 -> 70387.5 | I22: ='F07 OPERAC. (MAT,SERV & EQUIPO)'!Q116 -> 70387.5 | J22: ='F07 OPERAC. (MAT,SERV & EQUIPO)'!R116 -> 70537.5 | K22: ='F07 OPERAC. (MAT,SERV & EQUIPO)'!S116 -> 70387.5 | ... Q22: ='F07 OPERAC. (MAT,SERV & EQUIPO)'!Y116 -> 75387.5 | R22: =SUM(D22:Q22) -> 920937.5 | T22: =R22/$E$42 -> 46046.875 | V22: ='F07 OPERAC. (MAT,SERV & EQUIPO)'!L118 -> 920937.5 | W22: =SERVICIO!B148 -> 920937.5 | X22: =V22-R22 -> 0 | Y22: =V22-W22 -> 0
B23: MAT,SERV & EQUIPO (CONSTRUCCION)
A24: ACTIVOS (CONSTRUCCION) | D24: ='F07 OPERAC. (MAT,SERV & EQUIPO)'!L21 -> 0 | E24: ='F07 OPERAC. (MAT,SERV & EQUIPO)'!M21 -> 82.5 | F24: ='F07 OPERAC. (MAT,SERV & EQUIPO)'!N21 -> 82.5 | G24: ='F07 OPERAC. (MAT,SERV & EQUIPO)'!O21 -> 82.5 | H24: ='F07 OPERAC. (MAT,SERV & EQUIPO)'!P21 -> 82.5 | I24: ='F07 OPERAC. (MAT,SERV & EQUIPO)'!Q21 -> 82.5 | J24: ='F07 OPERAC. (MAT,SERV & EQUIPO)'!R21 -> 82.5 | K24: ='F07 OPERAC. (MAT,SERV & EQUIPO)'!S21 -> 82.5 | ... Q24: ='F07 OPERAC. (MAT,SERV & EQUIPO)'!Y21 -> 82.5 | R24: =SUM(D24:Q24) -> 1072.5 | T24: =R24/$E$42 -> 53.625 | V24: ='F07 OPERAC. (MAT,SERV & EQUIPO)'!L23 -> 1072.5 | W24: =SERVICIO!B30 -> 1072.5 | X24: =V24-R24 -> 0 | Y24: =V24-W24 -> 0
B25: ENSERES MENORES DIVERSOS
A26: MATERIALES (OPERACION) | D26: ='F07 OPERAC. (MAT,SERV & EQUIPO)'!L43 -> 0 | E26: ='F07 OPERAC. (MAT,SERV & EQUIPO)'!M43 -> 57.7115 | F26: ='F07 OPERAC. (MAT,SERV & EQUIPO)'!N43 -> 57.7115 | G26: ='F07 OPERAC. (MAT,SERV & EQUIPO)'!O43 -> 57.7115 | H26: ='F07 OPERAC. (MAT,SERV & EQUIPO)'!P43 -> 57.7115 | I26: ='F07 OPERAC. (MAT,SERV & EQUIPO)'!Q43 -> 57.7115 | J26: ='F07 OPERAC. (MAT,SERV & EQUIPO)'!R43 -> 57.7115 | K26: ='F07 OPERAC. (MAT,SERV & EQUIPO)'!S43 -> 57.7115 | ... Q26: ='F07 OPERAC. (MAT,SERV & EQUIPO)'!Y43 -> 57.7115 | R26: =SUM(D26:Q26) -> 750.2495 | T26: =R26/$E$42 -> 37.512475 | V26: ='F07 OPERAC. (MAT,SERV & EQUIPO)'!L45 -> 750.2495 | W26: =SERVICIO!B32 -> 750.2495 | X26: =V26-R26 -> 0 | Y26: =V26-W26 -> 0
B27: INSUMOS AGRICOLAS
A28: SERVICIOS (OPERACION) | D28: ='F07 OPERAC. (MAT,SERV & EQUIPO)'!L193 -> 0 | E28: ='F07 OPERAC. (MAT,SERV & EQUIPO)'!M193 -> 438.034 | F28: ='F07 OPERAC. (MAT,SERV & EQUIPO)'!N193 -> 438.034 | G28: ='F07 OPERAC. (MAT,SERV & EQUIPO)'!O193 -> 438.034 | H28: ='F07 OPERAC. (MAT,SERV & EQUIPO)'!P193 -> 438.034 | I28: ='F07 OPERAC. (MAT,SERV & EQUIPO)'!Q193 -> 438.034 | J28: ='F07 OPERAC. (MAT,SERV & EQUIPO)'!R193 -> 438.034 | K28: ='F07 OPERAC. (MAT,SERV & EQUIPO)'!S193 -> 438.034 | ... Q28: ='F07 OPERAC. (MAT,SERV & EQUIPO)'!Y193 -> 438.034 | R28: =SUM(D28:Q28) -> 5694.442 | T28: =R28/$E$42 -> 284.7221 | V28: ='F07 OPERAC. (MAT,SERV & EQUIPO)'!L195 -> 5694.442 | W28: =SERVICIO!B37+SERVICIO!B40+SERVICIO!B78+SERVICIO!B150+SERVICIO!B152 -> 5694.442 | X28: =V28-R28 -> 0 | Y28: =V28-W28 -> 0
B29: " SERVICIOS DE SALUD / SERVICIOS DE CAPACITACION / MATERIALES DE SALUD / MARKETING / INSUMOS DE OFICINA
A30: ACTIVOS (OPERACION) (Computadoras) | D30: ='F03 COM Y EQ COM'!L50 -> 0 | E30: ='F03 COM Y EQ COM'!M50 -> 0 | F30: ='F03 COM Y EQ COM'!N50 -> 0 | G30: ='F03 COM Y EQ COM'!O50 -> 0 | H30: ='F03 COM Y EQ COM'!P50 -> 0 | I30: ='F03 COM Y EQ COM'!Q50 -> 0 | J30: ='F03 COM Y EQ COM'!R50 -> 0 | K30: ='F03 COM Y EQ COM'!S50 -> 0 | ... Q30: ='F03 COM Y EQ COM'!Y50 -> 0 | R30: =SUM(D30:Q30) -> 0 | T30: =R30/$E$42 -> 0 | V30: ='F03 COM Y EQ COM'!L52 -> 0 | W30: =SERVICIO!B28 -> 0 | X30: =V30-R30 -> 0 | Y30: =V30-W30 -> 0
B31: EQUIPO DE COMPUTO Y ARRENDAMIENTO DE EQ. COMPUTO
A33: EGRESO TOTAL MENSUAL | D33: =SUM(D8:D30) -> 0 | E33: =SUM(E8:E30) -> 94460.018 | F33: =SUM(F8:F30) -> 125060.02 | G33: =SUM(G8:G30) -> 92810.018 | H33: =SUM(H8:H30) -> 95060.018 | I33: =SUM(I8:I30) -> 98142.518 | J33: =SUM(J8:J30) -> 94663.018 | K33: =SUM(K8:K30) -> 92810.018 | ... Q33: =SUM(Q8:Q30) -> 97810.018 | R33: =SUM(D33:Q33) -> 1269847 | T33: =R33/$E$42 -> 63492.349 | V33: =SERVICIO!B166 -> 1269847 | X33: =V33-R33 -> 0
A35: CAPEX TOTAL MENSUAL | D35: =D8 -> 0 | E35: =E8 -> 0 | F35: =F8 -> 31800 | G35: =G8 -> 0 | H35: =H8 -> 0 | I35: =I8 -> 0 | J35: =J8 -> 0 | K35: =K8 -> 0 | ... Q35: =Q8 -> 0 | R35: =SUM(D35:Q35) -> 31800 | T35: =R35/$E$42 -> 1590
A37: OPEX TOTAL MENSUAL | D37: =+D33-D35 -> 0 | E37: =+E33-E35 -> 94460.018 | F37: =+F33-F35 -> 93260.018 | G37: =+G33-G35 -> 92810.018 | H37: =+H33-H35 -> 95060.018 | I37: =+I33-I35 -> 98142.518 | J37: =+J33-J35 -> 94663.018 | K37: =+K33-K35 -> 92810.018 | ... Q37: =+Q33-Q35 -> 97810.018 | R37: =SUM(D37:Q37) -> 1238047 | T37: =R37/$E$42 -> 61902.349
A39: OPEX TOTAL MENSUAL REAL | R39: =SUM(D39:Q39) -> 0 | T39: =+R39*PREMISAS!$I$23 -> 0
D41: PREMISAS
D42: PARIDAD | E42: =PREMISAS!I23 -> 20
D43: MES | E43: =PREMISAS!I24 -> 30.4
D44: CRÉDITO | E44: =PREMISAS!I25 -> 45
D45: GAS LP | E45: =PREMISAS!I26 -> 10.5
D46: GASOLINA | E46: =PREMISAS!I27 -> 22
D47: DIESEL | E47: =PREMISAS!I28 -> 23
D48: https://www.google.com/search?client=firefox-b-d&q=precio+del+dolar+hoy

Sheet PREMISAS
B2: PREMISAS
B4: PARTIDAS | C4: DESCRIPCIÓN | D4: UNIDAD | E4: CANTIDAD | F4: PU [USD] | G4: TOTAL [USD] | H4: PU [MN] | I4: TOTAL [MN] | K4: Instalación | L4: M1 | M4: M2 | N4: M3 | O4: M4 | P4: M5 | Q4: M6 | R4: M7 | S4: M8 | T4: M9 | U4: M10 | V4: M11 | W4: M12 | X4: M13
K5: - | L5: ENE | M5: FEB | N5: MAR | O5: ABR | P5: MAY | Q5: JUN | R5: JUL | S5: AGO | T5: SEP | U5: OCT | V5: NOV | W5: DIC | X5: ENE
K6: - | L6: 31 | M6: 28 | N6: 31 | O6: 30 | P6: 31 | Q6: 30 | R6: 31 | S6: 31 | T6: 30 | U6: 31 | V6: 30 | W6: 31 | X6: 31
B8: - | C8: NOMBRE Y OBJETIVO DEL SRVICIO | D8: TIPO
B9: 1 | C9: Patín con bomba electrocentrifuga horizontal con gasto de 10,000-20,000 BPD incluye la operación continua. | D9: Día | E9: 0 | F9: 602.496 | G9: =F9*E9 -> 0 | H9: =F9*$I$23 -> 12049.92 | I9: =E9*H9 -> 0 | K9: 0 | L9: =$G$9*L6 -> 0 | M9: =$G$9*M6 -> 0 | N9: =$G$9*N6 -> 0 | O9: =$G$9*O6 -> 0 | P9: =$G$9*P6 -> 0 | Q9: =$G$9*Q6 -> 0 | R9: =$G$9*R6 -> 0 | S9: =$G$9*S6 -> 0 | ... X9: =$G$9*X6 -> 0
B10: 2 | C10: Patín con bomba electrocentrifuga horizontal con gasto de 20,000-30,000 BPD incluye la operación continua. | D10: Día | E10: 0 | F10: 470.01 | G10: =F10*E10 -> 0 | H10: =F10*$I$23 -> 9400.2 | I10: =E10*H10 -> 0 | K10: 0 | L10: =$G$10*L6 -> 0 | M10: =$G$10*M6 -> 0 | N10: =$G$10*N6 -> 0 | O10: =$G$10*O6 -> 0 | P10: =$G$10*P6 -> 0 | Q10: =$G$10*Q6 -> 0 | R10: =$G$10*R6 -> 0 | S10: =$G$10*S6 -> 0 | ... X10: =$G$10*X6 -> 0
B11: 3 | C11: Generador de energía a gas de 300 KW/375 KVA. | D11: Día | E11: 4 | F11: 1662.32 | G11: =F11*E11 -> 6649.28 | H11: =F11*$I$23 -> 33246.4 | I11: =E11*H11 -> 132985.6 | K11: 0 | L11: =$G$11*L6 -> 206127.68 | M11: =$G$11*M6 -> 186179.84 | N11: =$G$11*N6 -> 206127.68 | O11: =$G$11*O6 -> 199478.4 | P11: =$G$11*P6 -> 206127.68 | Q11: =$G$11*Q6 -> 199478.4 | R11: =$G$11*R6 -> 206127.68 | S11: =$G$11*S6 -> 206127.68 | ... X11: =$G$11*X6 -> 206127.68
B12: 4 | C12: Generador de energía a gas de 300 KW/375 KVA a disposición. | D12: Día | E12: 0 | F12: 1079.64 | G12: =F12*E12 -> 0 | H12: =F12*$I$23 -> 21592.8 | I12: =E12*H12 -> 0 | K12: 0 | L12: =$G$12*L6 -> 0 | M12: =$G$12*M6 -> 0 | N12: =$G$12*N6 -> 0 | O12: =$G$12*O6 -> 0 | P12: =$G$12*P6 -> 0 | Q12: =$G$12*Q6 -> 0 | R12: =$G$12*R6 -> 0 | S12: =$G$12*S6 -> 0 | ... X12: =$G$12*X6 -> 0
B13: 5 | C13: Variador de frecuencia para 300 KW/375 KVA. | D13: Día | E13: 0 | F13: 227.38 | G13: =F13*E13 -> 0 | H13: =F13*$I$23 -> 4547.6 | I13: =E13*H13 -> 0 | K13: 0 | L13: =$G$13*L6 -> 0 | M13: =$G$13*M6 -> 0 | N13: =$G$13*N6 -> 0 | O13: =$G$13*O6 -> 0 | P13: =$G$13*P6 -> 0 | Q13: =$G$13*Q6 -> 0 | R13: =$G$13*R6 -> 0 | S13: =$G$13*S6 -> 0 | ... X13: =$G$13*X6 -> 0
B14: 6 | E14: 0 | F14: 0 | G14: =F14*E14 -> 0 | H14: =F14*$I$23 -> 0 | I14: =E14*H14 -> 0 | K14: 0 | L14: 0 | M14: 0 | N14: 0 | O14: 0 | P14: 0 | Q14: 0 | R14: 0 | S14: 0 | T14: 0 | U14: 0 | V14: 0 | W14: 0 | X14: 0
B15: 7 | K15: 0 | L15: =$G$15*L6 -> 0 | M15: =$G$15*M6 -> 0 | N15: =$G$15*N6 -> 0 | O15: =$G$15*O6 -> 0 | P15: =$G$15*P6 -> 0 | Q15: =$G$15*Q6 -> 0 | R15: =$G$15*R6 -> 0 | S15: =$G$15*S6 -> 0 | ... X15: =$G$15*X6 -> 0
H17: TOTAL MENSUAL [USD] | K17: =SUM(K9:K15) -> 0 | L17: =SUM(L9:L15) -> 206127.68 | M17: =SUM(M9:M15) -> 186179.84 | N17: =SUM(N9:N15) -> 206127.68 | O17: =SUM(O9:O15) -> 199478.4 | P17: =SUM(P9:P15) -> 206127.68 | Q17: =SUM(Q9:Q15) -> 199478.4 | R17: =SUM(R9:R15) -> 206127.68 | ... X17: =SUM(X9:X15) -> 206127.68
H18: TOTAL MENSUAL [MN] | K18: =K17/$I$23 -> 0 | L18: =L17*$I$23 -> 4122553.6 | M18: =M17*$I$23 -> 3723596.8 | N18: =N17*$I$23 -> 4122553.6 | O18: =O17*$I$23 -> 3989568 | P18: =P17*$I$23 -> 4122553.6 | Q18: =Q17*$I$23 -> 3989568 | R18: =R17*$I$23 -> 4122553.6 | S18: =S17*$I$23 -> 4122553.6 | ... X18: =X17*$I$23 -> 4122553.6
H19: TOTAL [USD] | K19: =SUM(K17:X17) -> 2633114.9
H20: TOTAL [MN] | K20: =SUM(K18:X18) -> 52662298
H22: PREMISAS
H23: PARIDAD | I23: 20
H24: MES | I24: 30.4
H25: CRÉDITO | I25: 45
H26: GAS LP | I26: 10.5
H27: GASOLINA | I27: 22
H28: DIESEL | I28: 23
H29: https://www.google.com/search?client=firefox-b-d&q=precio+del+dolar+hoy
H31: Descuento MB2
B115: 64373.77

Sheet F08 INGRESOS
B2: INGRESOS
B4: RESUMEN | C4: PARTIDA | D4: CONCEPTO | E4: UNIDAD | F4: CANTIDAD | G4: PU [USD] | H4: TOTAL [USD] | I4: PU [MN] | J4: TOTAL [MN] | K4: TOTAL [MN] | M4: Instalación | N4: M1 | O4: M2 | P4: M3 | Q4: M4 | R4: M5 | S4: M6 | T4: M7 | U4: M8 | V4: M9 | W4: M10 | X4: M11 | Y4: M12 | Z4: M13
H5: TOTAL [USD] | I5: PU [MN] | J5: TOTAL [MN] | M5: - | N5: ENE | O5: FEB | P5: MAR | Q5: ABR | R5: MAY | S5: JUN | T5: JUL | U5: AGO | V5: SEP | W5: OCT | X5: NOV | Y5: DIC | Z5: ENE
H6: [USD] | I6: [MN] | J6: [MN] | K6: C / IVA | M6: - | N6: 31 | O6: 28 | P6: 31 | Q6: 30 | R6: 31 | S6: 30 | T6: 31 | U6: 31 | V6: 30 | W6: 31 | X6: 30 | Y6: 31 | Z6: 31
B7: FACTURACION | C7: 1 | D7: =PREMISAS!C9 -> Patín con bomba electrocentrifuga horizontal con gasto de 10,000-20,000 BPD incluye la operación continua. | E7: =PREMISAS!D9 -> Día | F7: =PREMISAS!E9 -> 0 | G7: =PREMISAS!F9 -> 602.496 | H7: =PREMISAS!G9 -> 0 | I7: =PREMISAS!H9 -> 12049.92 | J7: =PREMISAS!I9 -> 0 | K7: =J7*1.16 -> 0 | M7: =PREMISAS!K9 -> 0 | N7: =PREMISAS!L9 -> 0 | O7: =PREMISAS!M9 -> 0 | P7: =PREMISAS!N9 -> 0 | Q7: =PREMISAS!O9 -> 0 | R7: =PREMISAS!P9 -> 0 | S7: =PREMISAS!Q9 -> 0 | T7: =PREMISAS!R9 -> 0 | ... Z7: =PREMISAS!X9 -> 0
B8: FACTURACION | C8: 2 | D8: =PREMISAS!C10 -> Patín con bomba electrocentrifuga horizontal con gasto de 20,000-30,000 BPD incluye la operación continua. | E8: =PREMISAS!D10 -> Día | F8: =PREMISAS!E10 -> 0 | G8: =PREMISAS!F10 -> 470.01 | H8: =PREMISAS!G10 -> 0 | I8: =PREMISAS!H10 -> 9400.2 | J8: =PREMISAS!I10 -> 0 | K8: =J8*1.16 -> 0 | M8: =PREMISAS!K10 -> 0 | N8: =PREMISAS!L10 -> 0 | O8: =PREMISAS!M10 -> 0 | P8: =PREMISAS!N10 -> 0 | Q8: =PREMISAS!O10 -> 0 | R8: =PREMISAS!P10 -> 0 | S8: =PREMISAS!Q10 -> 0 | T8: =PREMISAS!R10 -> 0 | ... Z8: =PREMISAS!X10 -> 0
B9: FACTURACION | C9: 3 | D9: =PREMISAS!C11 -> Generador de energía a gas de 300 KW/375 KVA. | E9: =PREMISAS!D11 -> Día | F9: =PREMISAS!E11 -> 4 | G9: =PREMISAS!F11 -> 1662.32 | H9: =PREMISAS!G11 -> 6649.28 | I9: =PREMISAS!H11 -> 33246.4 | J9: =PREMISAS!I11 -> 132985.6 | K9: =J9*1.16 -> 154263.3 | M9: =PREMISAS!K11 -> 0 | N9: =PREMISAS!L11 -> 206127.68 | O9: =PREMISAS!M11 -> 186179.84 | P9: =PREMISAS!N11 -> 206127.68 | Q9: =PREMISAS!O11 -> 199478.4 | R9: =PREMISAS!P11 -> 206127.68 | S9: =PREMISAS!Q11 -> 199478.4 | T9: =PREMISAS!R11 -> 206127.68 | ... Z9: =PREMISAS!X11 -> 206127.68
B10: FACTURACION | C10: 4 | D10: =PREMISAS!C12 -> Generador de energía a gas de 300 KW/375 KVA a disposición. | E10: =PREMISAS!D12 -> Día | F10: =PREMISAS!E12 -> 0 | G10: =PREMISAS!F12 -> 1079.64 | H10: =PREMISAS!G12 -> 0 | I10: =PREMISAS!H12 -> 21592.8 | J10: =PREMISAS!I12 -> 0 | K10: =J10*1.16 -> 0 | M10: =PREMISAS!K12 -> 0 | N10: =PREMISAS!L12 -> 0 | O10: =PREMISAS!M12 -> 0 | P10: =PREMISAS!N12 -> 0 | Q10: =PREMISAS!O12 -> 0 | R10: =PREMISAS!P12 -> 0 | S10: =PREMISAS!Q12 -> 0 | T10: =PREMISAS!R12 -> 0 | ... Z10: =PREMISAS!X12 -> 0
B11: FACTURACION | C11: 5 | D11: =PREMISAS!C13 -> Variador de frecuencia para 300 KW/375 KVA. | E11: =PREMISAS!D13 -> Día | F11: =PREMISAS!E13 -> 0 | G11: =PREMISAS!F13 -> 227.38 | H11: =PREMISAS!G13 -> 0 | I11: =PREMISAS!H13 -> 4547.6 | J11: =PREMISAS!I13 -> 0 | K11: =J11*1.16 -> 0 | M11: =PREMISAS!K13 -> 0 | N11: =PREMISAS!L13 -> 0 | O11: =PREMISAS!M13 -> 0 | P11: =PREMISAS!N13 -> 0 | Q11: =PREMISAS!O13 -> 0 | R11: =PREMISAS!P13 -> 0 | S11: =PREMISAS!Q13 -> 0 | T11: =PREMISAS!R13 -> 0 | ... Z11: =PREMISAS!X13 -> 0
B12: FACTURACION | C12: 6 | E12: =PREMISAS!D14 -> 0 | F12: =PREMISAS!E14 -> 0 | G12: =PREMISAS!F14 -> 0 | H12: =PREMISAS!G14 -> 0 | I12: =PREMISAS!H14 -> 0 | J12: =PREMISAS!I14 -> 0 | K12: =J12*1.16 -> 0 | M12: =PREMISAS!K14 -> 0 | N12: =PREMISAS!L14 -> 0 | O12: =PREMISAS!M14 -> 0 | P12: =PREMISAS!N14 -> 0 | Q12: =PREMISAS!O14 -> 0 | R12: =PREMISAS!P14 -> 0 | S12: =PREMISAS!Q14 -> 0 | T12: =PREMISAS!R14 -> 0 | ... Z12: =PREMISAS!X14 -> 0
B13: FACTURACION | C13: 7
J15: TOTAL MENSUAL [USD] | M15: =SUM(M7:M13) -> 0 | N15: =SUM(N7:N13) -> 206127.68 | O15: =SUM(O7:O13) -> 186179.84 | P15: =SUM(P7:P13) -> 206127.68 | Q15: =SUM(Q7:Q13) -> 199478.4 | R15: =SUM(R7:R13) -> 206127.68 | S15: =SUM(S7:S13) -> 199478.4 | T15: =SUM(T7:T13) -> 206127.68 | ... Z15: =SUM(Z7:Z13) -> 206127.68
J16: TOTAL MENSUAL [MN] | M16: =M15/$K$21 -> 0 | N16: =N15*$K$21 -> 4122553.6 | O16: =O15*$K$21 -> 3723596.8 | P16: =P15*$K$21 -> 4122553.6 | Q16: =Q15*$K$21 -> 3989568 | R16: =R15*$K$21 -> 4122553.6 | S16: =S15*$K$21 -> 3989568 | T16: =T15*$K$21 -> 4122553.6 | U16: =U15*$K$21 -> 4122553.6 | ... Z16: =Z15*$K$21 -> 4122553.6
J17: TOTAL [USD] | M17: =SUM(M15:Z15) -> 2633114.9
J18: TOTAL [MN] | M18: =SUM(M16:Z16) -> 52662298
J20: =PREMISAS!H22 -> PREMISAS
J21: =PREMISAS!H23 -> PARIDAD | K21: =PREMISAS!I23 -> 20
J22: =PREMISAS!H24 -> MES | K22: =PREMISAS!I24 -> 30.4
J23: =PREMISAS!H25 -> CRÉDITO | K23: =PREMISAS!I25 -> 45
J24: =PREMISAS!H26 -> GAS LP | K24: =PREMISAS!I26 -> 10.5
J25: =PREMISAS!H27 -> GASOLINA | K25: =PREMISAS!I27 -> 22
J26: =PREMISAS!H28 -> DIESEL | K26: =PREMISAS!I28 -> 23
J27: https://www.google.com/search?client=firefox-b-d&q=precio+del+dolar+hoy

Sheet F00 INVERSIÓN
B2: INVERSIÓN
B4: RESUMEN | C4: DESCRIPCIÓN 1 | D4: UNIDAD | E4: CANTIDAD | F4: PU [USD] | G4: TOTAL [USD] | H4: PU [MN] | I4: TOTAL [MN] | J4: TOTAL [MN] | L4: Instalación | M4: M1 | N4: M2 | O4: M3 | P4: M4 | Q4: M5 | R4: M6 | S4: M7 | T4: M8 | U4: M9 | V4: M10 | W4: M11 | X4: M12 | Y4: M13
G5: TOTAL [USD] | H5: PU [MN] | I5: TOTAL [MN] | L5: - | M5: ENE | N5: FEB | O5: MAR | P5: ABR | Q5: MAY | R5: JUN | S5: JUL | T5: AGO | U5: SEP | V5: OCT | W5: NOV | X5: DIC | Y5: ENE
G6: [USD] | H6: [MN] | I6: [MN] | J6: C / IVA | L6: - | M6: 31 | N6: 28 | O6: 31 | P6: 30 | Q6: 31 | R6: 30 | S6: 31 | T6: 31 | U6: 30 | V6: 31 | W6: 30 | X6: 31 | Y6: 31
B7: EQUIPO DE TRANSPORTE | C7: Repuesto unidad 31 | E7: 1 | F7: 31800 | G7: =E7*F7 -> 31800 | H7: =F7*$J$46 -> 636000 | I7: =E7*H7 -> 636000 | J7: =I7*1.16 -> 737760 | L7: 0 | M7: 0 | N7: =G7 -> 31800 | O7: 0 | P7: 0 | Q7: =K7 -> 0 | R7: 0 | S7: 0 | T7: 0 | U7: 0 | V7: 0 | W7: 0 | X7: 0 | Y7: 0
B8: EQUIPO DE TRANSPORTE | E8: 0 | F8: 0 | G8: =E8*F8 -> 0 | H8: =F8*$J$46 -> 0 | I8: =E8*H8 -> 0 | J8: =I8*1.16 -> 0 | L8: 0 | M8: 0 | N8: =H8 -> 0 | O8: 0 | P8: 0 | Q8: 0 | R8: =L8 -> 0 | S8: 0 | T8: 0 | U8: 0 | V8: 0 | W8: 0 | X8: 0 | Y8: 0
B9: EQUIPO DE TRANSPORTE | E9: 0 | F9: 0 | G9: =E9*F9 -> 0 | H9: =F9*$J$46 -> 0 | I9: =E9*H9 -> 0 | J9: =I9*1.16 -> 0 | L9: 0 | M9: 0 | N9: 0 | O9: =H9 -> 0 | P9: 0 | Q9: 0 | R9: 0 | S9: =L9 -> 0 | T9: 0 | U9: 0 | V9: 0 | W9: 0 | X9: 0 | Y9: 0
B10: EQUIPO DE TRANSPORTE | E10: 0 | F10: 0 | G10: =E10*F10 -> 0 | H10: =F10*$J$46 -> 0 | I10: =E10*H10 -> 0 | J10: =I10*1.16 -> 0 | L10: 0 | M10: 0 | N10: 0 | O10: 0 | P10: =H10 -> 0 | Q10: 0 | R10: 0 | S10: 0 | T10: =L10 -> 0 | U10: 0 | V10: 0 | W10: 0 | X10: 0 | Y10: 0
L11: =SUM(L7:L10) -> 0 | M11: =SUM(M7:M10) -> 0 | N11: =SUM(N7:N10) -> 31800 | O11: =SUM(O7:O10) -> 0 | P11: =SUM(P7:P10) -> 0 | Q11: =SUM(Q7:Q10) -> 0 | R11: =SUM(R7:R10) -> 0 | S11: =SUM(S7:S10) -> 0 | ... Y11: =SUM(Y7:Y10) -> 0
B13: EQUIPO DE MOBILIARIO | E13: 1 | F13: 0 | G13: =E13*F13 -> 0 | H13: =F13*$J$46 -> 0 | I13: =E13*H13 -> 0 | J13: =I13*1.16 -> 0 | L13: 0 | M13: =G13 -> 0 | N13: 0 | O13: 0 | P13: 0 | Q13: =K13 -> 0 | R13: 0 | S13: 0 | T13: 0 | U13: 0 | V13: 0 | W13: 0 | X13: 0 | Y13: 0
B14: EQUIPO DE MOBILIARIO | E14: 2 | F14: 0 | G14: =E14*F14 -> 0 | H14: =F14*$J$46 -> 0 | I14: =E14*H14 -> 0 | J14: =I14*1.16 -> 0 | L14: 0 | M14: 0 | N14: =H14 -> 0 | O14: 0 | P14: 0 | Q14: 0 | R14: =L14 -> 0 | S14: 0 | T14: 0 | U14: 0 | V14: 0 | W14: 0 | X14: 0 | Y14: 0
B15: EQUIPO DE MOBILIARIO | E15: 3 | F15: 0 | G15: =E15*F15 -> 0 | H15: =F15*$J$46 -> 0 | I15: =E15*H15 -> 0 | J15: =I15*1.16 -> 0 | L15: 0 | M15: 0 | N15: 0 | O15: =H15 -> 0 | P15: 0 | Q15: 0 | R15: 0 | S15: =L15 -> 0 | T15: 0 | U15: 0 | V15: 0 | W15: 0 | X15: 0 | Y15: 0
B16: EQUIPO DE MOBILIARIO | E16: 4 | F16: 0 | G16: =E16*F16 -> 0 | H16: =F16*$J$46 -> 0 | I16: =E16*H16 -> 0 | J16: =I16*1.16 -> 0 | L16: 0 | M16: 0 | N16: 0 | O16: 0 | P16: =H16 -> 0 | Q16: 0 | R16: 0 | S16: 0 | T16: =L16 -> 0 | U16: 0 | V16: 0 | W16: 0 | X16: 0 | Y16: 0
L17: =SUM(L13:L16) -> 0 | M17: =SUM(M13:M16) -> 0 | N17: =SUM(N13:N16) -> 0 | O17: =SUM(O13:O16) -> 0 | P17: =SUM(P13:P16) -> 0 | Q17: =SUM(Q13:Q16) -> 0 | R17: =SUM(R13:R16) -> 0 | S17: =SUM(S13:S16) -> 0 | ... Y17: =SUM(Y13:Y16) -> 0
B19: MAQUINARIA Y EQUIPO 1 | E19: 1 | F19: 0 | G19: =E19*F19 -> 0 | H19: =F19*$J$46 -> 0 | I19: =E19*H19 -> 0 | J19: =I19*1.16 -> 0 | L19: 0 | M19: =G19 -> 0 | N19: 0 | O19: 0 | P19: 0 | Q19: 0 | R19: 0 | S19: 0 | T19: 0 | U19: 0 | V19: 0 | W19: 0 | X19: 0 | Y19: 0
B20: MAQUINARIA Y EQUIPO 2 | E20: 2 | F20: 0 | G20: =E20*F20 -> 0 | H20: =F20*$J$46 -> 0 | I20: =E20*H20 -> 0 | J20: =I20*1.16 -> 0 | L20: 0 | M20: 0 | N20: =H20 -> 0 | O20: 0 | P20: 0 | Q20: 0 | R20: 0 | S20: 0 | T20: 0 | U20: 0 | V20: 0 | W20: 0 | X20: 0 | Y20: 0
B21: MAQUINARIA Y EQUIPO 3 | E21: 3 | F21: 0 | G21: =E21*F21 -> 0 | H21: =F21*$J$46 -> 0 | I21: =E21*H21 -> 0 | J21: =I21*1.16 -> 0 | L21: 0 | M21: 0 | N21: 0 | O21: =H21 -> 0 | P21: 0 | Q21: 0 | R21: 0 | S21: 0 | T21: 0 | U21: 0 | V21: 0 | W21: 0 | X21: 0 | Y21: 0
B22: MAQUINARIA Y EQUIPO 4 | E22: 4 | F22: 0 | G22: =E22*F22 -> 0 | H22: =F22*$J$46 -> 0 | I22: =E22*H22 -> 0 | J22: =I22*1.16 -> 0 | L22: 0 | M22: 0 | N22: 0 | O22: 0 | P22: =H22 -> 0 | Q22: 0 | R22: 0 | S22: 0 | T22: 0 | U22: 0 | V22: 0 | W22: 0 | X22: 0 | Y22: 0
B23: MAQUINARIA Y EQUIPO 5 | E23: 5 | F23: 0 | G23: =E23*F23 -> 0 | H23: =F23*$J$46 -> 0 | I23: =E23*H23 -> 0 | J23: =I23*1.16 -> 0 | L23: 0 | M23: 0 | N23: 0 | O23: 0 | P23: 0 | Q23: =H23 -> 0 | R23: 0 | S23: 0 | T23: 0 | U23: 0 | V23: 0 | W23: 0 | X23: 0 | Y23: 0
B24: MAQUINARIA Y EQUIPO 6 | E24: 6 | F24: 0 | G24: =E24*F24 -> 0 | H24: =F24*$J$46 -> 0 | I24: =E24*H24 -> 0 | J24: =I24*1.16 -> 0 | L24: 0 | M24: 0 | N24: 0 | O24: 0 | P24: 0 | Q24: 0 | R24: =H24 -> 0 | S24: 0 | T24: 0 | U24: 0 | V24: 0 | W24: 0 | X24: 0 | Y24: 0
B25: MAQUINARIA Y EQUIPO 8 | E25: 7 | F25: 0 | G25: =E25*F25 -> 0 | H25: =F25*$J$46 -> 0 | I25: =E25*H25 -> 0 | J25: =I25*1.16 -> 0 | L25: 0 | M25: 0 | N25: 0 | O25: 0 | P25: 0 | Q25: 0 | R25: 0 | S25: =H25 -> 0 | T25: 0 | U25: 0 | V25: 0 | W25: 0 | X25: 0 | Y25: 0
L26: =SUM(L19:L25) -> 0 | M26: =SUM(M19:M25) -> 0 | N26: =SUM(N19:N25) -> 0 | O26: =SUM(O19:O25) -> 0 | P26: =SUM(P19:P25) -> 0 | Q26: =SUM(Q19:Q25) -> 0 | R26: =SUM(R19:R25) -> 0 | S26: =SUM(S19:S25) -> 0 | ... Y26: =SUM(Y19:Y25) -> 0
B28: OTROS ACTIVOS | E28: 1 | F28: 0 | G28: =E28*F28 -> 0 | H28: =F28*$J$46 -> 0 | I28: =E28*H28 -> 0 | J28: =I28*1.16 -> 0 | L28: 0 | M28: =G28 -> 0 | N28: 0 | O28: 0 | P28: 0 | Q28: 0 | R28: 0 | S28: 0 | T28: 0 | U28: 0 | V28: 0 | W28: 0 | X28: 0 | Y28: 0
B29: OTROS ACTIVOS | E29: 2 | F29: 0 | G29: =E29*F29 -> 0 | H29: =F29*$J$46 -> 0 | I29: =E29*H29 -> 0 | J29: =I29*1.16 -> 0 | L29: 0 | M29: 0 | N29: =H29 -> 0 | O29: 0 | P29: 0 | Q29: 0 | R29: 0 | S29: 0 | T29: 0 | U29: 0 | V29: 0 | W29: 0 | X29: 0 | Y29: 0
B30: OTROS ACTIVOS | E30: 3 | F30: 0 | G30: =E30*F30 -> 0 | H30: =F30*$J$46 -> 0 | I30: =E30*H30 -> 0 | J30: =I30*1.16 -> 0 | L30: 0 | M30: 0 | N30: 0 | O30: =H30 -> 0 | P30: 0 | Q30: 0 | R30: 0 | S30: 0 | T30: 0 | U30: 0 | V30: 0 | W30: 0 | X30: 0 | Y30: 0
B31: OTROS ACTIVOS | E31: 4 | F31: 0 | G31: =E31*F31 -> 0 | H31: =F31*$J$46 -> 0 | I31: =E31*H31 -> 0 | J31: =I31*1.16 -> 0 | L31: 0 | M31: 0 | N31: 0 | O31: 0 | P31: =H31 -> 0 | Q31: 0 | R31: 0 | S31: 0 | T31: 0 | U31: 0 | V31: 0 | W31: 0 | X31: 0 | Y31: 0
L32: =SUM(L28:L31) -> 0 | M32: =SUM(M28:M31) -> 0 | N32: =SUM(N28:N31) -> 0 | O32: =SUM(O28:O31) -> 0 | P32: =SUM(P28:P31) -> 0 | Q32: =SUM(Q28:Q31) -> 0 | R32: =SUM(R28:R31) -> 0 | S32: =SUM(S28:S31) -> 0 | ... Y32: =SUM(Y28:Y31) -> 0
B34: SOFTWARE Y LICICENCIAS | E34: 1 | F34: 0 | G34: =E34*F34 -> 0 | H34: =F34*$J$46 -> 0 | I34: =E34*H34 -> 0 | J34: =I34*1.16 -> 0 | L34: 0 | M34: =G34 -> 0 | N34: 0 | O34: 0 | P34: 0 | Q34: 0 | R34: 0 | S34: 0 | T34: 0 | U34: 0 | V34: 0 | W34: 0 | X34: 0 | Y34: 0
B35: SOFTWARE Y LICICENCIAS | E35: 2 | F35: 0 | G35: =E35*F35 -> 0 | H35: =F35*$J$46 -> 0 | I35: =E35*H35 -> 0 | J35: =I35*1.16 -> 0 | L35: 0 | M35: 0 | N35: =H35 -> 0 | O35: 0 | P35: 0 | Q35: 0 | R35: 0 | S35: 0 | T35: 0 | U35: 0 | V35: 0 | W35: 0 | X35: 0 | Y35: 0
B36: SOFTWARE Y LICICENCIAS | E36: 3 | F36: 0 | G36: =E36*F36 -> 0 | H36: =F36*$J$46 -> 0 | I36: =E36*H36 -> 0 | J36: =I36*1.16 -> 0 | L36: 0 | M36: 0 | N36: 0 | O36: =H36 -> 0 | P36: 0 | Q36: 0 | R36: 0 | S36: 0 | T36: 0 | U36: 0 | V36: 0 | W36: 0 | X36: 0 | Y36: 0
B37: SOFTWARE Y LICICENCIAS | E37: 4 | F37: 0 | G37: =E37*F37 -> 0 | H37: =F37*$J$46 -> 0 | I37: =E37*H37 -> 0 | J37: =I37*1.16 -> 0 | L37: 0 | M37: 0 | N37: 0 | O37: 0 | P37: =H37 -> 0 | Q37: 0 | R37: 0 | S37: 0 | T37: 0 | U37: 0 | V37: 0 | W37: 0 | X37: 0 | Y37: 0
L38: =SUM(L34:L37) -> 0 | M38: =SUM(M34:M37) -> 0 | N38: =SUM(N34:N37) -> 0 | O38: =SUM(O34:O37) -> 0 | P38: =SUM(P34:P37) -> 0 | Q38: =SUM(Q34:Q37) -> 0 | R38: =SUM(R34:R37) -> 0 | S38: =SUM(S34:S37) -> 0 | ... Y38: =SUM(Y34:Y37) -> 0
I40: TOTAL MENSUAL [USD] | L40: =SUM(L34:L38) -> 0 | M40: =+M38+M32+M26+M17+M11 -> 0 | N40: =+N38+N32+N26+N17+N11 -> 31800 | O40: =+O38+O32+O26+O17+O11 -> 0 | P40: =+P38+P32+P26+P17+P11 -> 0 | Q40: =+Q38+Q32+Q26+Q17+Q11 -> 0 | R40: =+R38+R32+R26+R17+R11 -> 0 | S40: =+S38+S32+S26+S17+S11 -> 0 | T40: =+T38+T32+T26+T17+T11 -> 0 | ... Y40: =+Y38+Y32+Y26+Y17+Y11 -> 0
I41: TOTAL MENSUAL [MN] | L41: =L40*$K$19 -> 0 | M41: =M40*$J$46 -> 0 | N41: =N40*$J$46 -> 636000 | O41: =O40*$J$46 -> 0 | P41: =P40*$J$46 -> 0 | Q41: =Q40*$J$46 -> 0 | R41: =R40*$J$46 -> 0 | S41: =S40*$J$46 -> 0 | T41: =T40*$J$46 -> 0 | ... Y41: =Y40*$J$46 -> 0
I42: TOTAL [USD] | L42: =SUM(L40:Y40) -> 31800
I43: TOTAL [MN] | L43: =SUM(L41:Y41) -> 636000
I45: ='F08 INGRESOS'!J20 -> PREMISAS
I46: ='F08 INGRESOS'!J21 -> PARIDAD | J46: ='F08 INGRESOS'!K21 -> 20
I47: ='F08 INGRESOS'!J22 -> MES | J47: ='F08 INGRESOS'!K22 -> 30.4
I48: ='F08 INGRESOS'!J23 -> CRÉDITO | J48: ='F08 INGRESOS'!K23 -> 45
...

Sheet NOMINA
B2: NÓMINA
B4: RESUMEN | C4: NOMBRE | D4: PUESTO | E4: UNIDAD | F4: CANTIDAD | G4: SALARIO | H4: IMPUESTOS | I4: COSTO REAL C/IMP. | K4: AGUINALDO | L4: FONDO DE AHORRO | M4: UTILIDADES | N4: APOYOS | O4: VACACIONES | P4: PU [USD] | Q4: TOTAL [USD] | R4: PU [MN] | S4: TOTAL [MN] | T4: TOTAL [MN] | V4: Instalación | W4: M1 | X4: M2 | Y4: M3 | Z4: M4 | AA4: M5 | AB4: M6 | AC4: M7 | AD4: M8 | AE4: M9 | AF4: M10 | AG4: M11 | AH4: M12 | AI4: M13
Q5: TOTAL [USD] | R5: PU [MN] | S5: TOTAL [MN] | V5: - | W5: ENE | X5: FEB | Y5: MAR | Z5: ABR | AA5: MAY | AB5: JUN | AC5: JUL | AD5: AGO | AE5: SEP | AF5: OCT | AG5: NOV | AH5: DIC | AI5: ENE
Q6: [USD] | R6: [MN] | S6: [MN] | T6: C / IVA | V6: - | W6: 31 | X6: 28 | Y6: 31 | Z6: 30 | AA6: 31 | AB6: 30 | AC6: 31 | AD6: 31 | AE6: 30 | AF6: 31 | AG6: 30 | AH6: 31 | AI6: 31
B7: NOMINA Y ADICIONALES | C7: HUMBERTO LECHUGA | D7: SUPERVISOR PROY. | F7: 1 | G7: 33000 | H7: =$T$33 -> 0.8 | I7: =G7*(1+H7) -> 59400 | K7: =G7 -> 33000 | L7: =K7/4 -> 8250 | M7: =G7/2 -> 16500 | N7: 0 | O7: =(G7/30.4)*12 -> 13026.316 | P7: =S7/$T$25 -> 3024.2763 | Q7: =P7*F7 -> 3024.2763 | R7: =I7+N7+(O7/12) -> 60485.526 | S7: =R7*F7 -> 60485.526 | T7: =S7*1.16 -> 70163.211 | V7: 0 | W7: =$Q$7 -> 3024.2763 | X7: =$Q$7 -> 3024.2763 | Y7: =$Q$7 -> 3024.2763 | Z7: =$Q$7 -> 3024.2763 | AA7: =$Q$7+(M7/$T$25) -> 3849.2763 | AB7: =$Q$7 -> 3024.2763 | AC7: =$Q$7 -> 3024.2763 | AD7: =$Q$7 -> 3024.2763 | AE7: =$Q$7 -> 3024.2763 | AF7: =$Q$7 -> 3024.2763 | AG7: =$Q$7 -> 3024.2763 | AH7: =$Q$7+((K7+L7)/$T$25) -> 5086.7763 | AI7: =$Q$7 -> 3024.2763
B8: NOMINA Y ADICIONALES | C8: ROCIO RODRIGUEZ | F8: 1 | G8: 30000 | H8: =$T$33 -> 0.8 | I8: =G8*(1+H8) -> 54000 | K8: =G8 -> 30000 | L8: =K8/4 -> 7500 | M8: =G8/2 -> 15000 | N8: 0 | O8: =(G8/30.4)*12 -> 11842.105 | P8: =S8/$T$25 -> 2749.3421 | Q8: =P8*F8 -> 2749.3421 | R8: =I8+N8+(O8/12) -> 54986.842 | S8: =R8*F8 -> 54986.842 | T8: =S8*1.16 -> 63784.737 | V8: 0 | W8: =$Q$8 -> 2749.3421 | X8: =$Q$8 -> 2749.3421 | Y8: =$Q$8 -> 2749.3421 | Z8: =$Q$8 -> 2749.3421 | AA8: =$Q$8+(M8/$T$25) -> 3499.3421 | AB8: =$Q$8 -> 2749.3421 | AC8: =$Q$8 -> 2749.3421 | AD8: =$Q$8 -> 2749.3421 | AE8: =$Q$8 -> 2749.3421 | AF8: =$Q$8 -> 2749.3421 | AG8: =$Q$8 -> 2749.3421 | AH8: =$Q$8+((K8+L8)/$T$25) -> 4624.3421 | AI8: =$Q$8 -> 2749.3421
