Workbook
Name Departamentos: '[1]BD Competencias'!$F$14:$F$41
Name Departamentos: '[2]BD Competencias'!$F$14:$F$41
Name Display_Week: [3]ProjectSchedule!$I$3
Name Project_Start: [3]ProjectSchedule!$I$2

Sheet SERVICIO
A1: GEOLIS SA DE CV
A2: Proyecto: Cambio de servicio Perdiz - Papan
A3: INGRESOS 2022 MXN | E3: M 1 | F3: M 2 | G3: M 3 | H3: M 4 | I3: M 5 | J3: M 6 | K3: M 7 | L3: M 8 | M3: M 9 | N3: M 10 | O3: M 11 | P3: M 12
A4: Descripcion | B4: Total Presupuestado | C4: Instalación | D4: Instalación | E4: Enero | F4: Febrero | G4: Marzo | H4: Abril | I4: Mayo | J4: Junio | K4: Julio | L4: Agosto | M4: Septiembre | N4: Octubre | O4: Noviembre | P4: Diciembre | Q4: Meses
A5: FACTURACION | B5: =SUM(C5:P5) -> 75320045 | C5: ='F08 INGRESOS'!M16 -> 17783233 | D5: ='F08 INGRESOS'!N16 -> 57536812 | E5: ='F08 INGRESOS'!O16 -> 0 | F5: ='F08 INGRESOS'!P16 -> 0 | G5: ='F08 INGRESOS'!Q16 -> 0 | H5: ='F08 INGRESOS'!R16 -> 0 | I5: ='F08 INGRESOS'!S16 -> 0 | J5: ='F08 INGRESOS'!T16 -> 0 | ... P5: ='F08 INGRESOS'!Z16 -> 0 | Q5: =COUNTA(E4:P4) -> 12
A6: EGRESOS 2024
A7: Descripcion | B7: Total Presupuestado | C7: - | D7: - | E7: Enero | F7: Febrero | G7: Marzo | H7: Abril | I7: Mayo | J7: Junio | K7: Julio | L7: Agosto | M7: Septiembre | N7: Octubre | O7: Noviembre | P7: Diciembre
A8: EQUIPO DE TRANSPORTE | B8: =SUM(C8:P8) -> 0 | C8: ='F00 INVERSIÓN'!L12 -> 0 | D8: ='F00 INVERSIÓN'!M12 -> 0 | E8: ='F00 INVERSIÓN'!N12 -> 0 | F8: ='F00 INVERSIÓN'!O12 -> 0 | G8: ='F00 INVERSIÓN'!P12 -> 0 | H8: ='F00 INVERSIÓN'!Q12 -> 0 | I8: ='F00 INVERSIÓN'!R12 -> 0 | J8: ='F00 INVERSIÓN'!S12 -> 0 | ... P8: ='F00 INVERSIÓN'!Y12 -> 0 | Q8: =B8/$B$162 -> 0
A9: EQUIPO DE MOBILIARIO | B9: =SUM(C9:P9) -> 0 | C9: ='F00 INVERSIÓN'!L18 -> 0 | D9: ='F00 INVERSIÓN'!M18 -> 0 | E9: ='F00 INVERSIÓN'!N18 -> 0 | F9: ='F00 INVERSIÓN'!O18 -> 0 | G9: ='F00 INVERSIÓN'!P18 -> 0 | H9: ='F00 INVERSIÓN'!Q18 -> 0 | I9: ='F00 INVERSIÓN'!R18 -> 0 | J9: ='F00 INVERSIÓN'!S18 -> 0 | ... P9: ='F00 INVERSIÓN'!Y18 -> 0 | Q9: =B9/$B$162 -> 0
A10: MAQUINARIA Y EQUIPO | B10: =SUM(C10:P10) -> 0 | C10: ='F00 INVERSIÓN'!L28 -> 0 | D10: ='F00 INVERSIÓN'!M28 -> 0 | E10: ='F00 INVERSIÓN'!N28 -> 0 | F10: ='F00 INVERSIÓN'!O28 -> 0 | G10: ='F00 INVERSIÓN'!P28 -> 0 | H10: ='F00 INVERSIÓN'!Q28 -> 0 | I10: ='F00 INVERSIÓN'!R28 -> 0 | J10: ='F00 INVERSIÓN'!S28 -> 0 | ... P10: ='F00 INVERSIÓN'!Y28 -> 0 | Q10: =B10/$B$162 -> 0
A11: OTROS ACTIVOS | B11: =SUM(C11:P11) -> 16714398 | C11: ='F00 INVERSIÓN'!L35 -> 16714398 | D11: ='F00 INVERSIÓN'!M35 -> 0 | E11: ='F00 INVERSIÓN'!N35 -> 0 | F11: ='F00 INVERSIÓN'!O35 -> 0 | G11: ='F00 INVERSIÓN'!P35 -> 0 | H11: ='F00 INVERSIÓN'!Q35 -> 0 | I11: ='F00 INVERSIÓN'!R35 -> 0 | J11: ='F00 INVERSIÓN'!S35 -> 0 | ... P11: ='F00 INVERSIÓN'!Y35 -> 0 | Q11: =B11/$B$162 -> 0.71848475
A12: SOFTWARE Y LICICENCIAS | B12: =SUM(C12:P12) -> 0 | C12: ='F00 INVERSIÓN'!L41 -> 0 | D12: ='F00 INVERSIÓN'!M41 -> 0 | E12: ='F00 INVERSIÓN'!N41 -> 0 | F12: ='F00 INVERSIÓN'!O41 -> 0 | G12: ='F00 INVERSIÓN'!P41 -> 0 | H12: ='F00 INVERSIÓN'!Q41 -> 0 | I12: ='F00 INVERSIÓN'!R41 -> 0 | J12: ='F00 INVERSIÓN'!S41 -> 0 | ... P12: ='F00 INVERSIÓN'!Y41 -> 0 | Q12: =B12/$B$162 -> 0
A13: ACTIVOS | B13: =SUM(B8:B12) -> 16714398 | C13: =SUM(C8:C12) -> 16714398 | D13: =SUM(D8:D12) -> 0 | E13: =SUM(E8:E12) -> 0 | F13: =SUM(F8:F12) -> 0 | G13: =SUM(G8:G12) -> 0 | H13: =SUM(H8:H12) -> 0 | I13: =SUM(I8:I12) -> 0 | ... P13: =SUM(P8:P12) -> 0 | Q13: =B13/$B$162 -> 0.71848475
A14: ARRENDAMIENTO DE INMUEBLES | B14: =SUM(C14:P14) -> 0 | C14: ='F02 INMUEBLES Y S'!N8 -> 0 | D14: ='F02 INMUEBLES Y S'!O8 -> 0 | E14: ='F02 INMUEBLES Y S'!P8 -> 0 | F14: ='F02 INMUEBLES Y S'!Q8 -> 0 | G14: ='F02 INMUEBLES Y S'!R8 -> 0 | H14: ='F02 INMUEBLES Y S'!S8 -> 0 | I14: ='F02 INMUEBLES Y S'!T8 -> 0 | J14: ='F02 INMUEBLES Y S'!U8 -> 0 | ... P14: ='F02 INMUEBLES Y S'!AA8 -> 0 | Q14: =B14/$B$162 -> 0
A15: ENERGIA ELECTRICA | B15: =SUM(C15:P15) -> 0 | C15: ='F02 INMUEBLES Y S'!N9 -> 0 | D15: ='F02 INMUEBLES Y S'!O9 -> 0 | E15: ='F02 INMUEBLES Y S'!P9 -> 0 | F15: ='F02 INMUEBLES Y S'!Q9 -> 0 | G15: ='F02 INMUEBLES Y S'!R9 -> 0 | H15: ='F02 INMUEBLES Y S'!S9 -> 0 | I15: ='F02 INMUEBLES Y S'!T9 -> 0 | J15: ='F02 INMUEBLES Y S'!U9 -> 0 | ... P15: ='F02 INMUEBLES Y S'!AA9 -> 0 | Q15: =B15/$B$162 -> 0
A16: RENTA DE CASAS NO DEDUCIBLE | B16: =SUM(C16:P16) -> 0 | C16: ='F02 INMUEBLES Y S'!N10 -> 0 | D16: ='F02 INMUEBLES Y S'!O10 -> 0 | E16: ='F02 INMUEBLES Y S'!P10 -> 0 | F16: ='F02 INMUEBLES Y S'!Q10 -> 0 | G16: ='F02 INMUEBLES Y S'!R10 -> 0 | H16: ='F02 INMUEBLES Y S'!S10 -> 0 | I16: ='F02 INMUEBLES Y S'!T10 -> 0 | J16: ='F02 INMUEBLES Y S'!U10 -> 0 | ... P16: ='F02 INMUEBLES Y S'!AA10 -> 0 | Q16: =B16/$B$162 -> 0
A17: SERVICIOS DE LIMPIEZA | B17: =SUM(C17:P17) -> 0 | C17: ='F02 INMUEBLES Y S'!N11 -> 0 | D17: ='F02 INMUEBLES Y S'!O11 -> 0 | E17: ='F02 INMUEBLES Y S'!P11 -> 0 | F17: ='F02 INMUEBLES Y S'!Q11 -> 0 | G17: ='F02 INMUEBLES Y S'!R11 -> 0 | H17: ='F02 INMUEBLES Y S'!S11 -> 0 | I17: ='F02 INMUEBLES Y S'!T11 -> 0 | J17: ='F02 INMUEBLES Y S'!U11 -> 0 | ... P17: ='F02 INMUEBLES Y S'!AA11 -> 0 | Q17: =B17/$B$162 -> 0
A18: SERVICIOS DE VIGILANCIA | B18: =SUM(C18:P18) -> 0 | C18: ='F02 INMUEBLES Y S'!N12 -> 0 | D18: ='F02 INMUEBLES Y S'!O12 -> 0 | E18: ='F02 INMUEBLES Y S'!P12 -> 0 | F18: ='F02 INMUEBLES Y S'!Q12 -> 0 | G18: ='F02 INMUEBLES Y S'!R12 -> 0 | H18: ='F02 INMUEBLES Y S'!S12 -> 0 | I18: ='F02 INMUEBLES Y S'!T12 -> 0 | J18: ='F02 INMUEBLES Y S'!U12 -> 0 | ... P18: ='F02 INMUEBLES Y S'!AA12 -> 0 | Q18: =B18/$B$162 -> 0
A19: SERVICIOS DE FUMIGACION | B19: =SUM(C19:P19) -> 0 | C19: ='F02 INMUEBLES Y S'!N13 -> 0 | D19: ='F02 INMUEBLES Y S'!O13 -> 0 | E19: ='F02 INMUEBLES Y S'!P13 -> 0 | F19: ='F02 INMUEBLES Y S'!Q13 -> 0 | G19: ='F02 INMUEBLES Y S'!R13 -> 0 | H19: ='F02 INMUEBLES Y S'!S13 -> 0 | I19: ='F02 INMUEBLES Y S'!T13 -> 0 | J19: ='F02 INMUEBLES Y S'!U13 -> 0 | ... P19: ='F02 INMUEBLES Y S'!AA13 -> 0 | Q19: =B19/$B$162 -> 0
A20: TELEFONIA FIJA | B20: =SUM(C20:P20) -> 0 | C20: ='F02 INMUEBLES Y S'!N14 -> 0 | D20: ='F02 INMUEBLES Y S'!O14 -> 0 | E20: ='F02 INMUEBLES Y S'!P14 -> 0 | F20: ='F02 INMUEBLES Y S'!Q14 -> 0 | G20: ='F02 INMUEBLES Y S'!R14 -> 0 | H20: ='F02 INMUEBLES Y S'!S14 -> 0 | I20: ='F02 INMUEBLES Y S'!T14 -> 0 | J20: ='F02 INMUEBLES Y S'!U14 -> 0 | ... P20: ='F02 INMUEBLES Y S'!AA14 -> 0 | Q20: =B20/$B$162 -> 0
A21: AGUA Y ALCANTARILLADO | B21: =SUM(C21:P21) -> 0 | C21: ='F02 INMUEBLES Y S'!N15 -> 0 | D21: ='F02 INMUEBLES Y S'!O15 -> 0 | E21: ='F02 INMUEBLES Y S'!P15 -> 0 | F21: ='F02 INMUEBLES Y S'!Q15 -> 0 | G21: ='F02 INMUEBLES Y S'!R15 -> 0 | H21: ='F02 INMUEBLES Y S'!S15 -> 0 | I21: ='F02 INMUEBLES Y S'!T15 -> 0 | J21: ='F02 INMUEBLES Y S'!U15 -> 0 | ... P21: ='F02 INMUEBLES Y S'!AA15 -> 0 | Q21: =B21/$B$162 -> 0
A22: ARRENDAMIENTO DE OF. MOVILES | B22: =SUM(C22:P22) -> 0 | C22: ='F02 INMUEBLES Y S'!N16 -> 0 | D22: ='F02 INMUEBLES Y S'!O16 -> 0 | E22: ='F02 INMUEBLES Y S'!P16 -> 0 | F22: ='F02 INMUEBLES Y S'!Q16 -> 0 | G22: ='F02 INMUEBLES Y S'!R16 -> 0 | H22: ='F02 INMUEBLES Y S'!S16 -> 0 | I22: ='F02 INMUEBLES Y S'!T16 -> 0 | J22: ='F02 INMUEBLES Y S'!U16 -> 0 | ... P22: ='F02 INMUEBLES Y S'!AA16 -> 0 | Q22: =B22/$B$162 -> 0
A23: ARRENDA DE INMUEBLES Y SERV | B23: =SUM(B14:B22) -> 0 | C23: =SUM(C14:C22) -> 0 | D23: =SUM(D14:D22) -> 0 | E23: =SUM(E14:E22) -> 0 | F23: =SUM(F14:F22) -> 0 | G23: =SUM(G14:G22) -> 0 | H23: =SUM(H14:H22) -> 0 | I23: =SUM(I14:I22) -> 0 | ... P23: =SUM(P14:P22) -> 0 | Q23: =B23/$B$162 -> 0
A24: ROPA Y ARTICULOS DE PROTECCION | B24: =SUM(C24:P24) -> 233794.18 | C24: ='F01 EPP'!M19 -> 233794.18 | D24: ='F01 EPP'!N19 -> 0 | E24: ='F01 EPP'!O19 -> 0 | F24: ='F01 EPP'!P19 -> 0 | G24: ='F01 EPP'!Q19 -> 0 | H24: ='F01 EPP'!R19 -> 0 | I24: ='F01 EPP'!S19 -> 0 | J24: ='F01 EPP'!T19 -> 0 | ... P24: ='F01 EPP'!Z19 -> 0 | Q24: =B24/$B$162 -> 0.010049872
A25: ARTICULOS DE SEGURIDAD | B25: =B24 -> 233794.18 | C25: =C24 -> 233794.18 | D25: =D24 -> 0 | E25: =E24 -> 0 | F25: =F24 -> 0 | G25: =G24 -> 0 | H25: =H24 -> 0 | I25: =I24 -> 0 | ... P25: =P24 -> 0 | Q25: =B25/$B$162 -> 0.010049872
A26: EQUIPO DE COMPUTO (Adquisición) | B26: =SUM(C26:P26) -> 32526 | C26: ='F03 COM Y EQ COM'!L45 -> 0 | D26: ='F03 COM Y EQ COM'!M45 -> 32526 | E26: ='F03 COM Y EQ COM'!N45 -> 0 | F26: ='F03 COM Y EQ COM'!O45 -> 0 | G26: ='F03 COM Y EQ COM'!P45 -> 0 | H26: ='F03 COM Y EQ COM'!Q45 -> 0 | I26: ='F03 COM Y EQ COM'!R45 -> 0 | J26: ='F03 COM Y EQ COM'!S45 -> 0 | ... P26: ='F03 COM Y EQ COM'!Y45 -> 0 | Q26: =B26/$B$162 -> 0.001398162
A27: ARRENDAMIENTO DE EQ. COMPUTO | B27: =SUM(C27:P27) -> 0 | C27: ='F03 COM Y EQ COM'!L46 -> 0 | D27: ='F03 COM Y EQ COM'!M46 -> 0 | E27: ='F03 COM Y EQ COM'!N46 -> 0 | F27: ='F03 COM Y EQ COM'!O46 -> 0 | G27: ='F03 COM Y EQ COM'!P46 -> 0 | H27: ='F03 COM Y EQ COM'!Q46 -> 0 | I27: ='F03 COM Y EQ COM'!R46 -> 0 | J27: ='F03 COM Y EQ COM'!S46 -> 0 | ... P27: ='F03 COM Y EQ COM'!Y46 -> 0 | Q27: =B27/$B$162 -> 0
A28: EQUIPO DE COMPUTO | B28: =SUM(B26:B27) -> 32526 | C28: =SUM(C26:C27) -> 0 | D28: =SUM(D26:D27) -> 32526 | E28: =SUM(E26:E27) -> 0 | F28: =SUM(F26:F27) -> 0 | G28: =SUM(G26:G27) -> 0 | H28: =SUM(H26:H27) -> 0 | I28: =SUM(I26:I27) -> 0 | ... P28: =SUM(P26:P27) -> 0 | Q28: =B28/$B$162 -> 0.001398162
A29: ENSERES MENORES DIVERSOS (Acondicionamiento de casas) | B29: =SUM(C29:P29) -> 10057.52 | C29: ='F07 OPERAC. (MAT,SERV & EQUIPO)'!L17 -> 5028.76 | D29: ='F07 OPERAC. (MAT,SERV & EQUIPO)'!M17 -> 5028.76 | E29: ='F07 OPERAC. (MAT,SERV & EQUIPO)'!N17 -> 0 | F29: ='F07 OPERAC. (MAT,SERV & EQUIPO)'!O17 -> 0 | G29: ='F07 OPERAC. (MAT,SERV & EQUIPO)'!P17 -> 0 | H29: ='F07 OPERAC. (MAT,SERV & EQUIPO)'!Q17 -> 0 | I29: ='F07 OPERAC. (MAT,SERV & EQUIPO)'!R17 -> 0 | J29: ='F07 OPERAC. (MAT,SERV & EQUIPO)'!S17 -> 0 | ... P29: ='F07 OPERAC. (MAT,SERV & EQUIPO)'!Y17 -> 0 | Q29: =B29/$B$162 -> 0.00043233235
A30: EQUIPOS Y ENSERES | B30: =B29 -> 10057.52 | C30: =C29 -> 5028.76 | D30: =D29 -> 5028.76 | E30: =E29 -> 0 | F30: =F29 -> 0 | G30: =G29 -> 0 | H30: =H29 -> 0 | I30: =I29 -> 0 | ... P30: =P29 -> 0 | Q30: =B30/$B$162 -> 0.00043233235
A31: INSUMOS AGRICOLAS | B31: =SUM(C31:P31) -> 0 | C31: ='F07 OPERAC. (MAT,SERV & EQUIPO)'!L39 -> 0 | D31: ='F07 OPERAC. (MAT,SERV & EQUIPO)'!M39 -> 0 | E31: ='F07 OPERAC. (MAT,SERV & EQUIPO)'!N39 -> 0 | F31: ='F07 OPERAC. (MAT,SERV & EQUIPO)'!O39 -> 0 | G31: ='F07 OPERAC. (MAT,SERV & EQUIPO)'!P39 -> 0 | H31: ='F07 OPERAC. (MAT,SERV & EQUIPO)'!Q39 -> 0 | I31: ='F07 OPERAC. (MAT,SERV & EQUIPO)'!R39 -> 0 | J31: ='F07 OPERAC. (MAT,SERV & EQUIPO)'!S39 -> 0 | ... P31: ='F07 OPERAC. (MAT,SERV & EQUIPO)'!Y39 -> 0 | Q31: =B31/$B$162 -> 0
A32: PAPELERIA Y UTILES DE OFICINA | B32: =SUM(C32:P32) -> 0 | C32: ='F07 OPERAC. (MAT,SERV & EQUIPO)'!L126 -> 0 | D32: ='F07 OPERAC. (MAT,SERV & EQUIPO)'!M126 -> 0 | E32: ='F07 OPERAC. (MAT,SERV & EQUIPO)'!N126 -> 0 | F32: ='F07 OPERAC. (MAT,SERV & EQUIPO)'!O126 -> 0 | G32: ='F07 OPERAC. (MAT,SERV & EQUIPO)'!P126 -> 0 | H32: ='F07 OPERAC. (MAT,SERV & EQUIPO)'!Q126 -> 0 | I32: ='F07 OPERAC. (MAT,SERV & EQUIPO)'!R126 -> 0 | J32: ='F07 OPERAC. (MAT,SERV & EQUIPO)'!S126 -> 0 | ... P32: ='F07 OPERAC. (MAT,SERV & EQUIPO)'!Y126 -> 0 | Q32: =B32/$B$162 -> 0
A33: ARTICULOS DE ASEO Y SANITARIOS | B33: =SUM(C33:P33) -> 0 | C33: ='F07 OPERAC. (MAT,SERV & EQUIPO)'!L127 -> 0 | D33: ='F07 OPERAC. (MAT,SERV & EQUIPO)'!M127 -> 0 | E33: ='F07 OPERAC. (MAT,SERV & EQUIPO)'!N127 -> 0 | F33: ='F07 OPERAC. (MAT,SERV & EQUIPO)'!O127 -> 0 | G33: ='F07 OPERAC. (MAT,SERV & EQUIPO)'!P127 -> 0 | H33: ='F07 OPERAC. (MAT,SERV & EQUIPO)'!Q127 -> 0 | I33: ='F07 OPERAC. (MAT,SERV & EQUIPO)'!R127 -> 0 | J33: ='F07 OPERAC. (MAT,SERV & EQUIPO)'!S127 -> 0 | ... P33: ='F07 OPERAC. (MAT,SERV & EQUIPO)'!Y127 -> 0 | Q33: =B33/$B$162 -> 0
A34: ARTICULOS DE CAFETERIA | B34: =SUM(C34:P34) -> 0 | C34: ='F07 OPERAC. (MAT,SERV & EQUIPO)'!L128 -> 0 | D34: ='F07 OPERAC. (MAT,SERV & EQUIPO)'!M128 -> 0 | E34: ='F07 OPERAC. (MAT,SERV & EQUIPO)'!N128 -> 0 | F34: ='F07 OPERAC. (MAT,SERV & EQUIPO)'!O128 -> 0 | G34: ='F07 OPERAC. (MAT,SERV & EQUIPO)'!P128 -> 0 | H34: ='F07 OPERAC. (MAT,SERV & EQUIPO)'!Q128 -> 0 | I34: ='F07 OPERAC. (MAT,SERV & EQUIPO)'!R128 -> 0 | J34: ='F07 OPERAC. (MAT,SERV & EQUIPO)'!S128 -> 0 | ... P34: ='F07 OPERAC. (MAT,SERV & EQUIPO)'!Y128 -> 0 | Q34: =B34/$B$162 -> 0
A35: ARTICULOS DIGITALES Y DE COMPUTO | B35: =SUM(C35:P35) -> 0 | C35: ='F07 OPERAC. (MAT,SERV & EQUIPO)'!L129 -> 0 | D35: ='F07 OPERAC. (MAT,SERV & EQUIPO)'!M129 -> 0 | E35: ='F07 OPERAC. (MAT,SERV & EQUIPO)'!N129 -> 0 | F35: ='F07 OPERAC. (MAT,SERV & EQUIPO)'!O129 -> 0 | G35: ='F07 OPERAC. (MAT,SERV & EQUIPO)'!P129 -> 0 | H35: ='F07 OPERAC. (MAT,SERV & EQUIPO)'!Q129 -> 0 | I35: ='F07 OPERAC. (MAT,SERV & EQUIPO)'!R129 -> 0 | J35: ='F07 OPERAC. (MAT,SERV & EQUIPO)'!S129 -> 0 | ... P35: ='F07 OPERAC. (MAT,SERV & EQUIPO)'!Y129 -> 0 | Q35: =B35/$B$162 -> 0
A36: INSUMOS DE OFICINA | B36: =SUM(B32:B35) -> 0 | C36: =SUM(C32:C35) -> 0 | D36: =SUM(D32:D35) -> 0 | E36: =SUM(E32:E35) -> 0 | F36: =SUM(F32:F35) -> 0 | G36: =SUM(G32:G35) -> 0 | H36: =SUM(H32:H35) -> 0 | I36: =SUM(I32:I35) -> 0 | ... P36: =SUM(P32:P35) -> 0 | Q36: =B36/$B$162 -> 0
A37: SERVICIOS DE MERCADOTECNIA | B37: =SUM(C37:P37) -> 0 | C37: ='F07 OPERAC. (MAT,SERV & EQUIPO)'!L140 -> 0 | D37: ='F07 OPERAC. (MAT,SERV & EQUIPO)'!M140 -> 0 | E37: ='F07 OPERAC. (MAT,SERV & EQUIPO)'!N140 -> 0 | F37: ='F07 OPERAC. (MAT,SERV & EQUIPO)'!O140 -> 0 | G37: ='F07 OPERAC. (MAT,SERV & EQUIPO)'!P140 -> 0 | H37: ='F07 OPERAC. (MAT,SERV & EQUIPO)'!Q140 -> 0 | I37: ='F07 OPERAC. (MAT,SERV & EQUIPO)'!R140 -> 0 | J37: ='F07 OPERAC. (MAT,SERV & EQUIPO)'!S140 -> 0 | ... P37: ='F07 OPERAC. (MAT,SERV & EQUIPO)'!Y140 -> 0 | Q37: =B37/$B$162 -> 0
A38: PUBLICIDAD Y PROPAGANDA | B38: =SUM(C38:P38) -> 0 | C38: ='F07 OPERAC. (MAT,SERV & EQUIPO)'!L141 -> 0 | D38: ='F07 OPERAC. (MAT,SERV & EQUIPO)'!M141 -> 0 | E38: ='F07 OPERAC. (MAT,SERV & EQUIPO)'!N141 -> 0 | F38: ='F07 OPERAC. (MAT,SERV & EQUIPO)'!O141 -> 0 | G38: ='F07 OPERAC. (MAT,SERV & EQUIPO)'!P141 -> 0 | H38: ='F07 OPERAC. (MAT,SERV & EQUIPO)'!Q141 -> 0 | I38: ='F07 OPERAC. (MAT,SERV & EQUIPO)'!R141 -> 0 | J38: ='F07 OPERAC. (MAT,SERV & EQUIPO)'!S141 -> 0 | ... P38: ='F07 OPERAC. (MAT,SERV & EQUIPO)'!Y141 -> 0 | Q38: =B38/$B$162 -> 0
A39: MARKETING | B39: =SUM(B37:B38) -> 0 | C39: =SUM(C37:C38) -> 0 | D39: =SUM(D37:D38) -> 0 | E39: =SUM(E37:E38) -> 0 | F39: =SUM(F37:F38) -> 0 | G39: =SUM(G37:G38) -> 0 | H39: =SUM(H37:H38) -> 0 | I39: =SUM(I37:I38) -> 0 | ... P39: =SUM(P37:P38) -> 0 | Q39: =B39/$B$162 -> 0
A40: ABRASIVOS | B40: =SUM(C40:P40) -> 20997.34 | C40: ='F06 (MAT,SERV & EQUIPO)'!M8 -> 10498.67 | D40: ='F06 (MAT,SERV & EQUIPO)'!N8 -> 10498.67 | E40: ='F06 (MAT,SERV & EQUIPO)'!O8 -> 0 | F40: ='F06 (MAT,SERV & EQUIPO)'!P8 -> 0 | G40: ='F06 (MAT,SERV & EQUIPO)'!Q8 -> 0 | H40: ='F06 (MAT,SERV & EQUIPO)'!R8 -> 0 | I40: ='F06 (MAT,SERV & EQUIPO)'!S8 -> 0 | J40: ='F06 (MAT,SERV & EQUIPO)'!T8 -> 0 | ... P40: ='F06 (MAT,SERV & EQUIPO)'!Z8 -> 0 | Q40: =B40/$B$162 -> 0.00090259122
...

Sheet Comparativa Anexo C
B2: RESUMEN ORDINARIAS
B3: No. | C3: DISCIPLINA | D3: MONTO [USD] | E3: GEOLIS
B4: 9 | C4: OBRA CIVIL | D4: 104077.7 | E4: =D4*0.7 -> 72854.39
B5: 2 | C5: OBRA ELÉCTRICA | D5: 1149249 | E5: =D5*0.7 -> 804474.31
B6: 83 | C6: OBRA MECÁNICA | D6: 880052.49 | E6: =D6*0.7 -> 616036.74
B8: TOTAL | D8: =SUM(D4:D7) -> 2133379.2 | E8: =D8*0.7 -> 1493365.4
B10: RESUMEN
B11: No. | C11: DISCIPLINA | D11: MONTO [USD] | E11: GEOLIS
B12: 49 | C12: INTERCONEXIÓN DE TBBA-04 (SUCCIÓN, DESCARGA, DRENAJE Y GAS COMBUSTIBLE) | D12: 228790.08 | E12: =D12*0.7 -> 160153.06
B13: 37 | C13: OBRA ELÉCTRICA | D13: 1790079 | E13: =D13*0.7 -> 1253055.3
B14: 2 | C14: INGENIERIA | D14: 15988.8 | E14: =D14*0.7 -> 11192.16
E15: =D15*0.7 -> 0
E16: =D16*0.7 -> 0
B17: TOTAL | D17: =SUM(D12:D16) -> 2034857.9 | E17: =D17*0.7 -> 1424400.5

Sheet GRÁFICA

Sheet GRÁFICA II
B32: OPEX | C32: Mes 0 | D32: Instalación | E32: Mes 2 | F32: Mes 3 | G32: Mes 4 | H32: Mes 5 | I32: Mes 6 | J32: Mes 7 | K32: Mes 8 | L32: Mes 9 | M32: Mes 10 | N32: Mes 11 | O32: Mes 12 | P32: Mes 13 | Q32: Mes 14 | R32: Total
A33: 1 | B33: =SERVICIO!A23 -> ARRENDA DE INMUEBLES Y SERV | C33: =SERVICIO!C23 -> 0 | D33: =SERVICIO!D23 -> 0 | E33: =SERVICIO!E23 -> 0 | F33: =SERVICIO!F23 -> 0 | G33: =SERVICIO!G23 -> 0 | H33: =SERVICIO!H23 -> 0 | I33: =SERVICIO!I23 -> 0 | J33: =SERVICIO!J23 -> 0 | ... P33: =SERVICIO!P23 -> 0 | Q33: =SERVICIO!#REF! -> #REF! | R33: =SERVICIO!B23 -> 0
A34: 2 | B34: =SERVICIO!A25 -> ARTICULOS DE SEGURIDAD | C34: =SERVICIO!C25 -> 233794.18 | D34: =SERVICIO!D25 -> 0 | E34: =SERVICIO!E25 -> 0 | F34: =SERVICIO!F25 -> 0 | G34: =SERVICIO!G25 -> 0 | H34: =SERVICIO!H25 -> 0 | I34: =SERVICIO!I25 -> 0 | J34: =SERVICIO!J25 -> 0 | ... P34: =SERVICIO!P25 -> 0 | Q34: =SERVICIO!#REF! -> #REF! | R34: =SERVICIO!B25 -> 233794.18
A35: 3 | B35: =SERVICIO!A28 -> EQUIPO DE COMPUTO | C35: =SERVICIO!C28 -> 0 | D35: =SERVICIO!D28 -> 32526 | E35: =SERVICIO!E28 -> 0 | F35: =SERVICIO!F28 -> 0 | G35: =SERVICIO!G28 -> 0 | H35: =SERVICIO!H28 -> 0 | I35: =SERVICIO!I28 -> 0 | J35: =SERVICIO!J28 -> 0 | ... P35: =SERVICIO!P28 -> 0 | Q35: =SERVICIO!#REF! -> #REF! | R35: =SERVICIO!B28 -> 32526
A36: 4 | B36: =SERVICIO!A30 -> EQUIPOS Y ENSERES | C36: =SERVICIO!C30 -> 5028.76 | D36: =SERVICIO!D30 -> 5028.76 | E36: =SERVICIO!E30 -> 0 | F36: =SERVICIO!F30 -> 0 | G36: =SERVICIO!G30 -> 0 | H36: =SERVICIO!H30 -> 0 | I36: =SERVICIO!I30 -> 0 | J36: =SERVICIO!J30 -> 0 | ... P36: =SERVICIO!P30 -> 0 | Q36: =SERVICIO!#REF! -> #REF! | R36: =SERVICIO!B30 -> 10057.52
A37: 5 | B37: =SERVICIO!A31 -> INSUMOS AGRICOLAS | C37: =SERVICIO!C31 -> 0 | D37: =SERVICIO!D31 -> 0 | E37: =SERVICIO!E31 -> 0 | F37: =SERVICIO!F31 -> 0 | G37: =SERVICIO!G31 -> 0 | H37: =SERVICIO!H31 -> 0 | I37: =SERVICIO!I31 -> 0 | J37: =SERVICIO!J31 -> 0 | ... P37: =SERVICIO!P31 -> 0 | Q37: =SERVICIO!#REF! -> #REF! | R37: =SERVICIO!B31 -> 0
A38: 6 | B38: =SERVICIO!A36 -> INSUMOS DE OFICINA | C38: =SERVICIO!C36 -> 0 | D38: =SERVICIO!D36 -> 0 | E38: =SERVICIO!E36 -> 0 | F38: =SERVICIO!F36 -> 0 | G38: =SERVICIO!G36 -> 0 | H38: =SERVICIO!H36 -> 0 | I38: =SERVICIO!I36 -> 0 | J38: =SERVICIO!J36 -> 0 | ... P38: =SERVICIO!P36 -> 0 | Q38: =SERVICIO!#REF! -> #REF! | R38: =SERVICIO!B36 -> 0
A39: 7 | B39: =SERVICIO!A39 -> MARKETING | C39: =SERVICIO!C39 -> 0 | D39: =SERVICIO!D39 -> 0 | E39: =SERVICIO!E39 -> 0 | F39: =SERVICIO!F39 -> 0 | G39: =SERVICIO!G39 -> 0 | H39: =SERVICIO!H39 -> 0 | I39: =SERVICIO!I39 -> 0 | J39: =SERVICIO!J39 -> 0 | ... P39: =SERVICIO!P39 -> 0 | Q39: =SERVICIO!#REF! -> #REF! | R39: =SERVICIO!B39 -> 0
A40: 8 | B40: =SERVICIO!A75 -> MATERIALES | C40: =SERVICIO!C75 -> 10498.67 | D40: =SERVICIO!D75 -> 10498.67 | E40: =SERVICIO!E75 -> 0 | F40: =SERVICIO!F75 -> 0 | G40: =SERVICIO!G75 -> 0 | H40: =SERVICIO!H75 -> 0 | I40: =SERVICIO!I75 -> 0 | J40: =SERVICIO!J75 -> 0 | ... P40: =SERVICIO!P75 -> 0 | Q40: =SERVICIO!#REF! -> #REF! | R40: =SERVICIO!B75 -> 20997.34
A41: 9 | B41: =SERVICIO!A77 -> MATERIALES DE SALUD | C41: =SERVICIO!C77 -> 0 | D41: =SERVICIO!D77 -> 0 | E41: =SERVICIO!E77 -> 0 | F41: =SERVICIO!F77 -> 0 | G41: =SERVICIO!G77 -> 0 | H41: =SERVICIO!H77 -> 0 | I41: =SERVICIO!I77 -> 0 | J41: =SERVICIO!J77 -> 0 | ... P41: =SERVICIO!P77 -> 0 | Q41: =SERVICIO!#REF! -> #REF! | R41: =SERVICIO!B77 -> 0
A42: 10 | B42: =SERVICIO!A78 -> NOMINA Y ADICIONALES | C42: =SERVICIO!C78 -> 417404.61 | D42: =SERVICIO!D78 -> 678534.54 | E42: =SERVICIO!E78 -> 0 | F42: =SERVICIO!F78 -> 0 | G42: =SERVICIO!G78 -> 0 | H42: =SERVICIO!H78 -> 0 | I42: =SERVICIO!I78 -> 0 | J42: =SERVICIO!J78 -> 0 | ... P42: =SERVICIO!P78 -> 0 | Q42: =SERVICIO!#REF! -> #REF! | R42: =SERVICIO!B78 -> 1095939.1
A43: 11 | B43: =SERVICIO!A82 -> SERV TELEFONIA CELULAR Y RADIO | C43: =SERVICIO!C82 -> 0 | D43: =SERVICIO!D82 -> 0 | E43: =SERVICIO!E82 -> 0 | F43: =SERVICIO!F82 -> 0 | G43: =SERVICIO!G82 -> 0 | H43: =SERVICIO!H82 -> 0 | I43: =SERVICIO!I82 -> 0 | J43: =SERVICIO!J82 -> 0 | ... P43: =SERVICIO!P82 -> 0 | Q43: =SERVICIO!#REF! -> #REF! | R43: =SERVICIO!B82 -> 0
A44: 12 | B44: =SERVICIO!A146 -> SERVICIOS | C44: =SERVICIO!C146 -> 1959720.8 | D44: =SERVICIO!D146 -> 1281872.5 | E44: =SERVICIO!E146 -> 0 | F44: =SERVICIO!F146 -> 0 | G44: =SERVICIO!G146 -> 0 | H44: =SERVICIO!H146 -> 0 | I44: =SERVICIO!I146 -> 0 | J44: =SERVICIO!J146 -> 0 | ... P44: =SERVICIO!P146 -> 0 | Q44: =SERVICIO!#REF! -> #REF! | R44: =SERVICIO!B146 -> 3241593.3
A45: 13 | B45: =SERVICIO!A147 -> SERVICIOS DE CAPACITACION | C45: =SERVICIO!C147 -> 0 | D45: =SERVICIO!D147 -> 0 | E45: =SERVICIO!E147 -> 0 | F45: =SERVICIO!F147 -> 0 | G45: =SERVICIO!G147 -> 0 | H45: =SERVICIO!H147 -> 0 | I45: =SERVICIO!I147 -> 0 | J45: =SERVICIO!J147 -> 0 | ... P45: =SERVICIO!P147 -> 0 | Q45: =SERVICIO!#REF! -> #REF! | R45: =SERVICIO!B147 -> 0
A46: 14 | B46: =SERVICIO!A149 -> SERVICIOS DE SALUD | C46: =SERVICIO!C149 -> 0 | D46: =SERVICIO!D149 -> 0 | E46: =SERVICIO!E149 -> 0 | F46: =SERVICIO!F149 -> 0 | G46: =SERVICIO!G149 -> 0 | H46: =SERVICIO!H149 -> 0 | I46: =SERVICIO!I149 -> 0 | J46: =SERVICIO!J149 -> 0 | ... P46: =SERVICIO!P149 -> 0 | Q46: =SERVICIO!#REF! -> #REF! | R46: =SERVICIO!B149 -> 0
A47: 15 | B47: =SERVICIO!A150 -> UNIFORMES | C47: =SERVICIO!C150 -> 0 | D47: =SERVICIO!D150 -> 0 | E47: =SERVICIO!E150 -> 0 | F47: =SERVICIO!F150 -> 0 | G47: =SERVICIO!G150 -> 0 | H47: =SERVICIO!H150 -> 0 | I47: =SERVICIO!I150 -> 0 | J47: =SERVICIO!J150 -> 0 | ... P47: =SERVICIO!P150 -> 0 | Q47: =SERVICIO!#REF! -> #REF! | R47: =SERVICIO!B150 -> 0
A48: 16 | B48: =SERVICIO!A153 -> VEHICULOS Y COMBUSTIBLE | C48: =SERVICIO!C153 -> 150400 | D48: =SERVICIO!D153 -> 150400 | E48: =SERVICIO!E153 -> 0 | F48: =SERVICIO!F153 -> 0 | G48: =SERVICIO!G153 -> 0 | H48: =SERVICIO!H153 -> 0 | I48: =SERVICIO!I153 -> 0 | J48: =SERVICIO!J153 -> 0 | ... P48: =SERVICIO!P153 -> 0 | Q48: =SERVICIO!#REF! -> #REF! | R48: =SERVICIO!B153 -> 300800
A49: 17 | B49: =SERVICIO!A161 -> VIATICOS | C49: =SERVICIO!C161 -> 806647.15 | D49: =SERVICIO!D161 -> 806647.15 | E49: =SERVICIO!E161 -> 0 | F49: =SERVICIO!F161 -> 0 | G49: =SERVICIO!G161 -> 0 | H49: =SERVICIO!H161 -> 0 | I49: =SERVICIO!I161 -> 0 | J49: =SERVICIO!J161 -> 0 | ... P49: =SERVICIO!P161 -> 0 | Q49: =SERVICIO!#REF! -> #REF! | R49: =SERVICIO!B161 -> 1613294.3
R50: =SUM(R33:R49) -> 6549001.8

Sheet PREMISAS
M3: Instalación | N3: Instalación | O3: Mes 1 | P3: Mes 2 | Q3: Mes 3 | R3: Mes 4 | S3: Mes 5 | T3: Mes 6 | U3: Mes 7 | V3: Mes 8 | W3: Mes 9 | X3: Mes 10 | Y3: Mes 11 | Z3: Mes 12
O4: ENE | P4: FEB | Q4: MAR | R4: ABR | S4: MAY | T4: JUN | U4: JUL | V4: AGO | W4: SEP | X4: OCT | Y4: NOV | Z4: DIC
B5: PARTIDAS | C5: DESCRIPCIÓN | F5: UNIDAD | G5: CANTIDAD | H5: PU [USD] | I5: PU [MN] | J5: TOTAL [USD] | K5: TOTAL [MN] | O5: 31 | P5: 29 | Q5: 31 | R5: 30 | S5: 30 | T5: 31 | U5: 31 | V5: 31 | W5: 30 | X5: 31 | Y5: 30 | Z5: 31
B6: BEH
B7: 1 | C7: ='Comparativa Anexo C'!C4 -> OBRA CIVIL | F7: Servicio | G7: 1 | H7: ='Comparativa Anexo C'!D4 -> 104077.7 | I7: =H7*$D$18 -> 1880684 | J7: =H7*G7 -> 104077.7 | K7: =G7*I7 -> 1880684 | M7: =K7 -> 1880684 | N7: 0 | O7: 0 | P7: 0 | Q7: 0 | R7: 0 | S7: 0 | T7: 0 | U7: 0 | V7: 0 | W7: 0 | X7: 0 | Y7: 0 | Z7: 0
B8: 2 | C8: ='Comparativa Anexo C'!C5 -> OBRA ELÉCTRICA | F8: Día | G8: 1 | H8: ='Comparativa Anexo C'!D5 -> 1149249 | I8: =H8*$D$18 -> 20766930 | J8: =H8*G8 -> 1149249 | K8: =G8*I8 -> 20766930 | N8: =K8 -> 20766930 | O8: 0 | P8: 0 | Q8: 0 | R8: 0 | S8: 0 | T8: 0 | U8: 0 | V8: 0 | W8: 0 | X8: 0 | Y8: 0 | Z8: 0
B9: 3 | C9: ='Comparativa Anexo C'!C6 -> OBRA MECÁNICA | F9: Día | G9: 1 | H9: ='Comparativa Anexo C'!D6 -> 880052.49 | I9: =H9*$D$18 -> 15902548 | J9: =H9*G9 -> 880052.49 | K9: =G9*I9 -> 15902548 | M9: =K9 -> 15902548 | O9: 0 | P9: 0 | Q9: 0 | R9: 0 | S9: 0 | T9: 0 | U9: 0 | V9: 0 | W9: 0 | X9: 0 | Y9: 0 | Z9: 0
B10: 4 | C10: - | F10: Día | G10: 1 | H10: ='Comparativa Anexo C'!E7 -> 0 | I10: =H10*$D$18 -> 0 | J10: =H10*G10 -> 0 | K10: =G10*I10 -> 0 | M10: =K10 -> 0 | N10: 0 | O10: 0 | P10: 0 | Q10: 0 | R10: 0 | S10: 0 | T10: 0 | U10: 0 | V10: 0 | W10: 0 | X10: 0 | Y10: 0 | Z10: 0
B11: 5 | C11: - | F11: Día | G11: 0 | H11: 0 | I11: =H11*$D$18 -> 0 | J11: =H11*G11 -> 0 | K11: =G11*I11 -> 0 | M11: 0 | N11: 0 | O11: 0 | P11: 0 | Q11: 0 | R11: 0 | S11: 0 | T11: 0 | U11: 0 | V11: 0 | W11: 0 | X11: 0 | Y11: 0 | Z11: 0
B12: 6 | C12: Conceptos extraordinarios | F12: Día | G12: 1 | H12: ='Comparativa Anexo C'!D17 -> 2034857.9 | I12: =H12*$D$18 -> 36769882 | J12: =H12*G12 -> 2034857.9 | K12: =G12*I12 -> 36769882 | M12: 0 | N12: =K12 -> 36769882 | O12: 0 | P12: 0 | Q12: 0 | R12: 0 | S12: 0 | T12: 0 | U12: 0 | V12: 0 | W12: 0 | X12: 0 | Y12: 0 | Z12: 0
B14: Costo día Gen Op. + Resp. | D14: 4540.18 | E14: =D14*D18 -> 82041.053 | J14: Total Mensual [MN] | M14: =SUM(M7:M12) -> 17783233 | N14: =SUM(N7:N12) -> 57536812 | O14: =SUM(O7:O12) -> 0 | P14: =SUM(P7:P12) -> 0 | Q14: =SUM(Q7:Q12) -> 0 | R14: =SUM(R7:R12) -> 0 | S14: =SUM(S7:S12) -> 0 | T14: =SUM(T7:T12) -> 0 | ... Z14: =SUM(Z7:Z12) -> 0
B15: Costo día 2 Gen Op. | D15: 5141.2 | E15: =D15*D18 -> 92901.484 | J15: Total Mensual [USD] | M15: =M14/$D$18 -> 984130.19 | N15: =N14/$D$18 -> 3184106.9 | O15: =O14/$D$18 -> 0 | P15: =P14/$D$18 -> 0 | Q15: =Q14/$D$18 -> 0 | R15: =R14/$D$18 -> 0 | S15: =S14/$D$18 -> 0 | T15: =T14/$D$18 -> 0 | ... Z15: =Z14/$D$18 -> 0
J16: Total [MN] | M16: =SUM(M14:Z14) -> 75320045
C17: Premisas | J17: Total [USD] | M17: =SUM(M15:Z15) -> 4168237.1
C18: Paridad | D18: 18.07
C19: Mes | D19: 30.4 | I19: Ingresos sin IVA (MXN) | K19: =M16 -> 75320045
C20: Periodo Pago (días) | D20: 30 | I20: Ingresos IVA (MXN) | K20: =K19*1.16 -> 87371252
C21: Gas lp | D21: 0 | I21: Ingresos IVA (USD) | K21: =M17 -> 4168237.1
C22: Gasolina Magna | D22: 22 | I22: Ingresos sin IVA (USD) | K22: =K21*1.16 -> 4835155.1
C23: Diesel | D23: 23
C24: https://www.google.com/search?client=firefox-b-d&q=precio+del+dolar+hoy
B81: 64373.77
O124: ENE | P124: FEB
C125: ='F08 INGRESOS'!M17 -> 984130.19 | D125: ='F08 INGRESOS'!N17 -> 3184106.9 | E125: ='F08 INGRESOS'!O17 -> 0 | F125: ='F08 INGRESOS'!P17 -> 0 | G125: ='F08 INGRESOS'!Q17 -> 0 | H125: ='F08 INGRESOS'!R17 -> 0 | I125: ='F08 INGRESOS'!S17 -> 0 | J125: ='F08 INGRESOS'!T17 -> 0 | ... P125: ='F08 INGRESOS'!Z17 -> 0
B129: =SUM(C129:P129) -> #DIV/0! | D129: =D13/$B$152 -> #DIV/0!
B130: =SUM(C130:P130) -> #DIV/0! | D130: =D23/$B$152 -> #DIV/0!
B131: =SUM(C131:P131) -> 0
B132: =SUM(C132:P132) -> 0
B133: =SUM(C133:P133) -> #REF! | D133: =#REF!/$B$152 -> #REF!
B134: =SUM(C134:P134) -> 0
B135: =SUM(C135:P135) -> 0
B136: =SUM(C136:P136) -> 0
B137: =SUM(C137:P137) -> 0
B138: =SUM(C138:P138) -> 0
B139: =SUM(C139:P139) -> 0
B140: =SUM(C140:P140) -> 0
B141: =SUM(C141:P141) -> #DIV/0! | G141: =G102/$B$152 -> #DIV/0!
B142: =SUM(C142:P142) -> 0
B143: =SUM(C143:P143) -> 0
B144: =SUM(C144:P144) -> 0
...

Sheet FLUJO
D1: 0 | E1: 1 | F1: 2 | G1: 3 | H1: 4 | I1: 5 | J1: 6 | K1: 7 | L1: 8 | M1: 9 | N1: 10 | O1: 11 | P1: 12
C3: Instalación | D3: Instalación | E3: Mes 1 | F3: Mes 2 | G3: Mes 3 | H3: Mes 4 | I3: Mes 5 | J3: Mes 6 | K3: Mes 7 | L3: Mes 8 | M3: Mes 9 | N3: Mes 10 | O3: Mes 11 | P3: Mes 12 | R3: =SUM(R6:R10) -> 38550162 | T3: =R3*1.16 -> 44718188 | V3: =+R3/$E$38 -> 2133379.2 | X3: =V3*1.16 -> 2474719.9
E4: ENE | F4: FEB | G4: MAR | H4: ABR | I4: MAY | J4: JUN | K4: JUL | L4: AGO | M4: SEP | N4: OCT | O4: NOV | P4: DIC | R4: TOTAL PROYECTO (MN) | T4: TOTAL PROYECTO IVA (MN) | V4: TOTAL PROYECTO (USD) | X4: TOTAL PROYECTO IVA (USD)
A5: Ingresos (MN) | E5: 31 | F5: 29 | G5: 31 | H5: 30 | I5: 30 | J5: 31 | K5: 31 | L5: 31 | M5: 30 | N5: 31 | O5: 30 | P5: 31
A6: =PREMISAS!C7 -> OBRA CIVIL | C6: ='F08 INGRESOS'!M8 -> 1880684 | D6: ='F08 INGRESOS'!N8 -> 0 | E6: ='F08 INGRESOS'!O8 -> 0 | F6: ='F08 INGRESOS'!P8 -> 0 | G6: ='F08 INGRESOS'!Q8 -> 0 | H6: ='F08 INGRESOS'!R8 -> 0 | I6: ='F08 INGRESOS'!S8 -> 0 | J6: ='F08 INGRESOS'!T8 -> 0 | ... P6: ='F08 INGRESOS'!Z8 -> 0 | R6: =SUM(C6:P6) -> 1880684 | T6: =R6*1.16 -> 2181593.5 | V6: =+R6/$E$38 -> 104077.7 | X6: =V6*1.16 -> 120730.13
A7: =PREMISAS!#REF! -> #REF! | C7: ='F08 INGRESOS'!M9 -> 0 | D7: ='F08 INGRESOS'!N9 -> 20766930 | E7: ='F08 INGRESOS'!O9 -> 0 | F7: ='F08 INGRESOS'!P9 -> 0 | G7: ='F08 INGRESOS'!Q9 -> 0 | H7: ='F08 INGRESOS'!R9 -> 0 | I7: ='F08 INGRESOS'!S9 -> 0 | J7: ='F08 INGRESOS'!T9 -> 0 | ... P7: ='F08 INGRESOS'!Z9 -> 0 | R7: =SUM(C7:P7) -> 20766930 | T7: =R7*1.16 -> 24089639 | V7: =+R7/$E$38 -> 1149249 | X7: =V7*1.16 -> 1333128.9
A8: =PREMISAS!C8 -> OBRA ELÉCTRICA | C8: ='F08 INGRESOS'!M10 -> 15902548 | D8: ='F08 INGRESOS'!N10 -> 0 | E8: ='F08 INGRESOS'!O10 -> 0 | F8: ='F08 INGRESOS'!P10 -> 0 | G8: ='F08 INGRESOS'!Q10 -> 0 | H8: ='F08 INGRESOS'!R10 -> 0 | I8: ='F08 INGRESOS'!S10 -> 0 | J8: ='F08 INGRESOS'!T10 -> 0 | ... P8: ='F08 INGRESOS'!Z10 -> 0 | R8: =SUM(C8:P8) -> 15902548 | T8: =R8*1.16 -> 18446956 | V8: =+R8/$E$38 -> 880052.49 | X8: =V8*1.16 -> 1020860.9
A9: =PREMISAS!C9 -> OBRA MECÁNICA | C9: ='F08 INGRESOS'!M11 -> 0 | D9: ='F08 INGRESOS'!N11 -> 0 | E9: ='F08 INGRESOS'!O11 -> 0 | F9: ='F08 INGRESOS'!P11 -> 0 | G9: ='F08 INGRESOS'!Q11 -> 0 | H9: ='F08 INGRESOS'!R11 -> 0 | I9: ='F08 INGRESOS'!S11 -> 0 | J9: ='F08 INGRESOS'!T11 -> 0 | ... P9: ='F08 INGRESOS'!Z11 -> 0 | R9: =SUM(C9:P9) -> 0 | T9: =R9*1.16 -> 0 | V9: =+R9/$E$38 -> 0 | X9: =V9*1.16 -> 0
A10: =PREMISAS!C11 -> - | C10: ='F08 INGRESOS'!M12 -> 0 | D10: ='F08 INGRESOS'!N12 -> 0 | E10: ='F08 INGRESOS'!O12 -> 0 | F10: ='F08 INGRESOS'!P12 -> 0 | G10: ='F08 INGRESOS'!Q12 -> 0 | H10: ='F08 INGRESOS'!R12 -> 0 | I10: ='F08 INGRESOS'!S12 -> 0 | J10: ='F08 INGRESOS'!T12 -> 0 | ... P10: ='F08 INGRESOS'!Z12 -> 0 | R10: =SUM(C10:P10) -> 0 | T10: =R10*1.16 -> 0 | V10: =+R10/$E$38 -> 0 | X10: =V10*1.16 -> 0
A11: =PREMISAS!C12 -> Conceptos extraordinarios | E11: ='F08 INGRESOS'!O13 -> 0 | F11: ='F08 INGRESOS'!P13 -> 0 | G11: ='F08 INGRESOS'!Q13 -> 0 | H11: ='F08 INGRESOS'!R13 -> 0 | I11: ='F08 INGRESOS'!S13 -> 0 | J11: ='F08 INGRESOS'!T13 -> 0 | K11: ='F08 INGRESOS'!U13 -> 0 | L11: ='F08 INGRESOS'!V13 -> 0 | ... P11: ='F08 INGRESOS'!Z13 -> 0 | R11: =SUM(C11:P11) -> 0 | T11: =R11*1.16 -> 0 | V11: =+R11/$E$38 -> 0 | X11: =V11*1.16 -> 0
A12: Ingresos Totales (MN) | C12: =SUM(C6:C11) -> 17783233 | D12: =SUM(D6:D11) -> 20766930 | E12: =SUM(E6:E11) -> 0 | F12: =SUM(F6:F11) -> 0 | G12: =SUM(G6:G11) -> 0 | H12: =SUM(H6:H11) -> 0 | I12: =SUM(I6:I11) -> 0 | J12: =SUM(J6:J11) -> 0 | ... P12: =SUM(P6:P11) -> 0 | R12: =SUM(C12:P12) -> 38550162
A14: Ingresos Totales (MN) IVA | C14: =+C12*1.16 -> 20628550 | D14: =+D12*1.16 -> 24089639 | E14: =+E12*1.16 -> 0 | F14: =+F12*1.16 -> 0 | G14: =+G12*1.16 -> 0 | H14: =+H12*1.16 -> 0 | I14: =+I12*1.16 -> 0 | J14: =+J12*1.16 -> 0 | ... P14: =+P12*1.16 -> 0 | R14: =SUM(C14:P14) -> 44718188
A16: Egresos (MX)
A17: OPEX | C17: =EGRESOS!D37 -> 3583494.2 | D17: =EGRESOS!E37 -> 2965507.6 | E17: =EGRESOS!F37 -> 0 | F17: =EGRESOS!G37 -> 0 | G17: =EGRESOS!H37 -> 0 | H17: =EGRESOS!I37 -> 0 | I17: =EGRESOS!J37 -> 0 | J17: =EGRESOS!K37 -> 0 | ... P17: =EGRESOS!Q37 -> 0 | R17: =SUM(C17:P17) -> 6549001.8 | V17: =+R17/$E$38 -> 362424 | X17: =+V17*1.16 -> 420411.85
A18: FINANCIAMIENTO
A19: CAPEX | C19: =EGRESOS!D35 -> 16714398 | D19: =EGRESOS!E35 -> 0 | E19: =EGRESOS!F35 -> 0 | F19: =EGRESOS!G35 -> 0 | G19: =EGRESOS!H35 -> 0 | H19: =EGRESOS!I35 -> 0 | I19: =EGRESOS!J35 -> 0 | J19: =EGRESOS!K35 -> 0 | ... P19: =EGRESOS!Q35 -> 0 | R19: =SUM(C19:P19) -> 16714398 | V19: =+R19/$E$38 -> 924980.5 | X19: =+V19*1.16 -> 1072977.4
A21: Egresos Totales (MN) | C21: =SUM(C17:C20) -> 20297892 | D21: =SUM(D17:D20) -> 2965507.6 | E21: =SUM(E17:E20) -> 0 | F21: =SUM(F17:F20) -> 0 | G21: =SUM(G17:G20) -> 0 | H21: =SUM(H17:H20) -> 0 | I21: =SUM(I17:I20) -> 0 | J21: =SUM(J17:J20) -> 0 | ... P21: =SUM(P17:P20) -> 0 | R21: =SUM(C21:P21) -> 23263399 | T21: =+R21*1.16 -> 26985543 | V21: =+R21/$E$38 -> 1287404.5 | X21: =+V21*1.16 -> 1493389.2
A23: Egresos Totales (MN) IVA | C23: =+C21*1.16 -> 23545554 | D23: =+D21*1.16 -> 3439988.8 | E23: =+E21*1.16 -> 0 | F23: =+F21*1.16 -> 0 | G23: =+G21*1.16 -> 0 | H23: =+H21*1.16 -> 0 | I23: =+I21*1.16 -> 0 | J23: =+J21*1.16 -> 0 | ... P23: =+P21*1.16 -> 0 | R23: =SUM(C23:P23) -> 26985543 | T23: =+R23*1.16 -> 31303230 | V23: =+R23/$E$38 -> 1493389.2 | X23: =+V23*1.16 -> 1732331.5
A25: FLUJO EFECTIVO | C25: =C12-C21 -> -2514659.2 | D25: =D12-D21 -> 17801422 | E25: =E12-E21 -> 0 | F25: =F12-F21 -> 0 | G25: =G12-G21 -> 0 | H25: =H12-H21 -> 0 | I25: =I12-I21 -> 0 | J25: =J12-J21 -> 0 | ... P25: =P12-P21 -> 0
A27: FLUJO EFECTIVO IVA | C27: =+C25*1.16 -> -2917004.7 | D27: =+D25*1.16 -> 20649650 | E27: =+E25*1.16 -> 0 | F27: =+F25*1.16 -> 0 | G27: =+G25*1.16 -> 0 | H27: =+H25*1.16 -> 0 | I27: =+I25*1.16 -> 0 | J27: =+J25*1.16 -> 0 | ... P27: =+P25*1.16 -> 0
A29: FLUJO ACUMULADO | C29: =+C25 -> -2514659.2 | D29: =+D25+C29 -> 15286763 | E29: =+E25+D29 -> 15286763 | F29: =+F25+E29 -> 15286763 | G29: =+G25+F29 -> 15286763 | H29: =+H25+G29 -> 15286763 | I29: =+I25+H29 -> 15286763 | J29: =+J25+I29 -> 15286763 | K29: =+K25+J29 -> 15286763 | ... P29: =+P25+O29 -> 15286763
A31: FLUJO ACUMULADO IVA | C31: =+C29*1.16 -> -2917004.7 | D31: =+D29*1.16 -> 17732645 | E31: =+E29*1.16 -> 17732645 | F31: =+F29*1.16 -> 17732645 | G31: =+G29*1.16 -> 17732645 | H31: =+H29*1.16 -> 17732645 | I31: =+I29*1.16 -> 17732645 | J31: =+J29*1.16 -> 17732645 | ... P31: =+P29*1.16 -> 17732645
C33: OPEX Promedio | D33: =AVERAGE(C17:P17) -> 467785.84
C34: CAPEX | D34: =SUM(C19:G19) -> 16714398
C35: Opex Total | D35: =SUM(C17:P17) -> 6549001.8
C37: FACTORES DE SENSIBILIDAD | G37: RESULTADOS (MMMN)
C38: Tipo de Cambio | E38: =PREMISAS!D18 -> 18.07 | I38: Total Ingresos | J38: =SUM(R12)/1000000 -> 38.550162
F39: USD | I39: Total Egresos | J39: =SUM(R21)/1000000 -> 23.263399
F40: USD
C41: Equipo sup. | F41: USD
C42: Instalación | F42: USD
C43: Gas lp | F43: (USD/L)
C44: Desinstalación | F44: USD
C45: Telemetría | F45: USD
C47: Préstamo | F47: USD | G47: EBTDA Acumulado | H47: =(R12-R21)/1000000 -> 15.286763 | I47: EBTDA Anual | J47: =H47/E51 -> 10.191175
C48: Capital de trabajo | E48: =MIN(C31:P31) -> -2917004.7 | G48: VPN | H48: =(NPV(E49/18,D25:P25))/1000000 -> 17.683532 | I48: VPN Anual | J48: =H48/E51 -> 11.789021
C49: Tasa de VPN y VPI Anual | E49: 0.12 | G49: VPI | H49: =(NPV(E49/18,D19:P19))/1000000 -> 0
C50: Meses de Préstamo | G50: Punto de Equilibrio | I50: meses
C51: Años del proyecto | E51: 1.5 | G51: TIR | H51: =XIRR(D25:P25,D4:P4) -> #VALUE! | I51: %
G52: Utilidades | H52: =+H47/J38 -> 0.39654212
...

Sheet EGRESOS
A2: REFERENCIA EGRESO - JD EDWARDS
D4: Instalación | E4: Instalación | F4: Mes 1 | G4: Mes 2 | H4: Mes 3 | I4: Mes 4 | J4: Mes 5 | K4: Mes 6 | L4: Mes 7 | M4: Mes 8 | N4: Mes 9 | O4: Mes 10 | P4: Mes 11 | Q4: Mes 12
D5: ABR | E5: MAY | F5: JUN | G5: JUL | H5: AGO | I5: SEP | J5: OCT | K5: NOV | L5: DIC | M5: ENE | N5: FEB | O5: MAR | P5: ABR | Q5: MAY | R5: TOTAL PROYECTO (MXN) | T5: TOTAL PROYECTO (USD)
D6: 30 | E6: 31 | F6: 20 | G6: 31 | H6: 31 | I6: 30 | J6: 31 | K6: 30 | L6: 31 | M6: 30 | N6: 31 | O6: 30 | P6: 31 | Q6: 31
A8: INVERSIÓN | D8: ='F00 INVERSIÓN'!L43 -> 16714398 | E8: ='F00 INVERSIÓN'!M43 -> 0 | F8: ='F00 INVERSIÓN'!N43 -> 0 | G8: ='F00 INVERSIÓN'!O43 -> 0 | H8: ='F00 INVERSIÓN'!P43 -> 0 | I8: ='F00 INVERSIÓN'!Q43 -> 0 | J8: ='F00 INVERSIÓN'!R43 -> 0 | K8: ='F00 INVERSIÓN'!S43 -> 0 | ... Q8: ='F00 INVERSIÓN'!Y43 -> 0 | R8: =SUM(D8:Q8) -> 16714398 | T8: =R8/$E$42 -> 924980.5 | V8: ='F00 INVERSIÓN'!L45 -> 16714398 | W8: =SERVICIO!B13 -> 16714398 | X8: =V8-R8 -> 0 | Y8: =V8-W8 -> 0
B9: ACTIVOS
A10: NOMINA Y ADICIONALES | D10: ='F01 NÓMINA'!X20+'F01 EPP'!M19+'F01 UNIFORMES'!M15 -> 651198.78 | E10: ='F01 NÓMINA'!Y20+'F01 EPP'!N19+'F01 UNIFORMES'!N15 -> 678534.54 | F10: ='F01 NÓMINA'!Z20+'F01 EPP'!O19+'F01 UNIFORMES'!O15 -> 0 | G10: ='F01 NÓMINA'!AA20+'F01 EPP'!P19+'F01 UNIFORMES'!P15 -> 0 | H10: ='F01 NÓMINA'!AB20+'F01 EPP'!Q19+'F01 UNIFORMES'!Q15 -> 0 | I10: ='F01 NÓMINA'!AC20+'F01 EPP'!R19+'F01 UNIFORMES'!R15 -> 0 | J10: ='F01 NÓMINA'!AD20+'F01 EPP'!S19+'F01 UNIFORMES'!S15 -> 0 | K10: ='F01 NÓMINA'!AE20+'F01 EPP'!T19+'F01 UNIFORMES'!T15 -> 0 | ... Q10: ='F01 NÓMINA'!AK20+'F01 EPP'!Z19+'F01 UNIFORMES'!Z15 -> 0 | R10: =SUM(D10:Q10) -> 1329733.3 | T10: =R10/$E$42 -> 73587.898 | V10: ='F01 NÓMINA'!X22+'F01 EPP'!M21+'F01 UNIFORMES'!M17 -> 1329733.3 | W10: ='F01 NÓMINA'!X22+'F01 EPP'!M21+'F01 UNIFORMES'!M17 -> 1329733.3 | X10: =V10-R10 -> 0 | Y10: =V10-W10 -> 0
B11: NÓMINA + EPP + UNIFORMES
A12: INMUEBLES Y SERVICIOS | D12: ='F02 INMUEBLES Y S'!N18 -> 0 | E12: ='F02 INMUEBLES Y S'!O18 -> 0 | F12: ='F02 INMUEBLES Y S'!P18 -> 0 | G12: ='F02 INMUEBLES Y S'!Q18 -> 0 | H12: ='F02 INMUEBLES Y S'!R18 -> 0 | I12: ='F02 INMUEBLES Y S'!S18 -> 0 | J12: ='F02 INMUEBLES Y S'!T18 -> 0 | K12: ='F02 INMUEBLES Y S'!U18 -> 0 | ... Q12: ='F02 INMUEBLES Y S'!AA18 -> 0 | R12: =SUM(D12:Q12) -> 0 | T12: =R12/$E$42 -> 0 | V12: ='F02 INMUEBLES Y S'!N20 -> 0 | W12: =SERVICIO!B23 -> 0 | X12: =V12-R12 -> 0 | Y12: =V12-W12 -> 0
B13: INMUEBLES
A14: TELEFONIA Y COMUNICACIÓN | D14: ='F03 COM Y EQ COM'!L36 -> 0 | E14: ='F03 COM Y EQ COM'!M36 -> 0 | F14: ='F03 COM Y EQ COM'!N36 -> 0 | G14: ='F03 COM Y EQ COM'!O36 -> 0 | H14: ='F03 COM Y EQ COM'!P36 -> 0 | I14: ='F03 COM Y EQ COM'!Q36 -> 0 | J14: ='F03 COM Y EQ COM'!R36 -> 0 | K14: ='F03 COM Y EQ COM'!S36 -> 0 | ... Q14: ='F03 COM Y EQ COM'!Y36 -> 0 | R14: =SUM(D14:Q14) -> 0 | T14: =R14/$E$42 -> 0 | V14: ='F03 COM Y EQ COM'!L38 -> 0 | W14: =SERVICIO!B82 -> 0 | X14: =V14-R14 -> 0 | Y14: =V14-W14 -> 0
B15: COM Y EQ COM
A16: VEHICULOS Y COMBUSTIBLE | D16: ='F04 VEHÍCULOS Y COMB. '!V25 -> 150400 | E16: ='F04 VEHÍCULOS Y COMB. '!W25 -> 150400 | F16: ='F04 VEHÍCULOS Y COMB. '!X25 -> 0 | G16: ='F04 VEHÍCULOS Y COMB. '!Y25 -> 0 | H16: ='F04 VEHÍCULOS Y COMB. '!Z25 -> 0 | I16: ='F04 VEHÍCULOS Y COMB. '!AA25 -> 0 | J16: ='F04 VEHÍCULOS Y COMB. '!AB25 -> 0 | K16: ='F04 VEHÍCULOS Y COMB. '!AC25 -> 0 | ... Q16: ='F04 VEHÍCULOS Y COMB. '!AI25 -> 0 | R16: =SUM(D16:Q16) -> 300800 | T16: =R16/$E$42 -> 16646.375 | V16: ='F04 VEHÍCULOS Y COMB. '!V27 -> 300800 | W16: =SERVICIO!B153 -> 300800 | X16: =V16-R16 -> 0 | Y16: =V16-W16 -> 0
B17: VEHÍCULOS Y COMB
A18: VIATICOS | D18: ='F05 VIÁTICOS'!K28 -> 806647.15 | E18: ='F05 VIÁTICOS'!L28 -> 806647.15 | F18: ='F05 VIÁTICOS'!M28 -> 0 | G18: ='F05 VIÁTICOS'!N28 -> 0 | H18: ='F05 VIÁTICOS'!O28 -> 0 | I18: ='F05 VIÁTICOS'!P28 -> 0 | J18: ='F05 VIÁTICOS'!Q28 -> 0 | K18: ='F05 VIÁTICOS'!R28 -> 0 | ... Q18: ='F05 VIÁTICOS'!X28 -> 0 | R18: =SUM(D18:Q18) -> 1613294.3 | T18: =R18/$E$42 -> 89280.26 | V18: ='F05 VIÁTICOS'!K30 -> 1613294.3 | W18: =SERVICIO!B161 -> 1613294.3 | X18: =V18-R18 -> 0 | Y18: =V18-W18 -> 0
B19: VIATICOS CAJA CHICA Y REEMBOLSO
A20: MAT, SERV & EQUIPO | D20: ='F06 (MAT,SERV & EQUIPO)'!M44 -> 10498.67 | E20: ='F06 (MAT,SERV & EQUIPO)'!N44 -> 10498.67 | F20: ='F06 (MAT,SERV & EQUIPO)'!O44 -> 0 | G20: ='F06 (MAT,SERV & EQUIPO)'!P44 -> 0 | H20: ='F06 (MAT,SERV & EQUIPO)'!Q44 -> 0 | I20: ='F06 (MAT,SERV & EQUIPO)'!R44 -> 0 | J20: ='F06 (MAT,SERV & EQUIPO)'!S44 -> 0 | K20: ='F06 (MAT,SERV & EQUIPO)'!T44 -> 0 | ... Q20: ='F06 (MAT,SERV & EQUIPO)'!Z44 -> 0 | R20: =SUM(D20:Q20) -> 20997.34 | T20: =R20/$E$42 -> 1162 | V20: ='F06 (MAT,SERV & EQUIPO)'!M46 -> 20997.34 | W20: =SERVICIO!B75 -> 20997.34 | X20: =V20-R20 -> 0 | Y20: =V20-W20 -> 0
B21: MAT,SERV & EQUIPO
A22: SERVICIOS | D22: ='F07 OPERAC. (MAT,SERV & EQUIPO)'!L117 -> 1959720.8 | E22: ='F07 OPERAC. (MAT,SERV & EQUIPO)'!M117 -> 1281872.5 | F22: ='F07 OPERAC. (MAT,SERV & EQUIPO)'!N117 -> 0 | G22: ='F07 OPERAC. (MAT,SERV & EQUIPO)'!O117 -> 0 | H22: ='F07 OPERAC. (MAT,SERV & EQUIPO)'!P117 -> 0 | I22: ='F07 OPERAC. (MAT,SERV & EQUIPO)'!Q117 -> 0 | J22: ='F07 OPERAC. (MAT,SERV & EQUIPO)'!R117 -> 0 | K22: ='F07 OPERAC. (MAT,SERV & EQUIPO)'!S117 -> 0 | ... Q22: ='F07 OPERAC. (MAT,SERV & EQUIPO)'!Y117 -> 0 | R22: =SUM(D22:Q22) -> 3241593.3 | T22: =R22/$E$42 -> 179390.88 | V22: ='F07 OPERAC. (MAT,SERV & EQUIPO)'!L119 -> 3241593.3 | W22: =SERVICIO!B146 -> 3241593.3 | X22: =V22-R22 -> 0 | Y22: =V22-W22 -> 0
B23: MAT,SERV & EQUIPO
A24: ACTIVOS (CONSTRUCCION) | R24: =SUM(D24:Q24) -> 0 | X24: =V24-R24 -> 0 | Y24: =V24-W24 -> 0
A26: MATERIALES (OPERACION) | D26: ='F07 OPERAC. (MAT,SERV & EQUIPO)'!L44 -> 5028.76 | E26: ='F07 OPERAC. (MAT,SERV & EQUIPO)'!M44 -> 5028.76 | F26: ='F07 OPERAC. (MAT,SERV & EQUIPO)'!N44 -> 0 | G26: ='F07 OPERAC. (MAT,SERV & EQUIPO)'!O44 -> 0 | H26: ='F07 OPERAC. (MAT,SERV & EQUIPO)'!P44 -> 0 | I26: ='F07 OPERAC. (MAT,SERV & EQUIPO)'!Q44 -> 0 | J26: ='F07 OPERAC. (MAT,SERV & EQUIPO)'!R44 -> 0 | K26: ='F07 OPERAC. (MAT,SERV & EQUIPO)'!S44 -> 0 | ... Q26: ='F07 OPERAC. (MAT,SERV & EQUIPO)'!Y44 -> 0 | R26: =SUM(D26:Q26) -> 10057.52 | T26: =R26/$E$42 -> 556.58661 | V26: ='F07 OPERAC. (MAT,SERV & EQUIPO)'!L46 -> 10057.52 | W26: =SERVICIO!B30+SERVICIO!B31 -> 10057.52 | X26: =V26-R26 -> 0 | Y26: =V26-W26 -> 0
B27: SERVICIOS AGRICOLAS Y ENSERES MENORES
A28: SERVICIOS (OPERACION) | D28: ='F07 OPERAC. (MAT,SERV & EQUIPO)'!L195 -> 0 | E28: ='F07 OPERAC. (MAT,SERV & EQUIPO)'!M195 -> 0 | F28: ='F07 OPERAC. (MAT,SERV & EQUIPO)'!N195 -> 0 | G28: ='F07 OPERAC. (MAT,SERV & EQUIPO)'!O195 -> 0 | H28: ='F07 OPERAC. (MAT,SERV & EQUIPO)'!P195 -> 0 | I28: ='F07 OPERAC. (MAT,SERV & EQUIPO)'!Q195 -> 0 | J28: ='F07 OPERAC. (MAT,SERV & EQUIPO)'!R195 -> 0 | K28: ='F07 OPERAC. (MAT,SERV & EQUIPO)'!S195 -> 0 | ... Q28: ='F07 OPERAC. (MAT,SERV & EQUIPO)'!Y195 -> 0 | R28: =SUM(D28:Q28) -> 0 | T28: =R28/$E$42 -> 0 | V28: ='F07 OPERAC. (MAT,SERV & EQUIPO)'!L197 -> 0 | W28: =SERVICIO!B36+SERVICIO!B39+SERVICIO!B77+SERVICIO!B147+SERVICIO!B149 -> 0 | X28: =V28-R28 -> 0 | Y28: =V28-W28 -> 0
B29: ENSERES MENORES DIVERSOS, INSUMOS AGRICOLAS
A30: ACTIVOS (OPERACION) (Computadoras) | D30: ='F03 COM Y EQ COM'!L49 -> 0 | E30: ='F03 COM Y EQ COM'!M49 -> 32526 | F30: ='F03 COM Y EQ COM'!N49 -> 0 | G30: ='F03 COM Y EQ COM'!O49 -> 0 | H30: ='F03 COM Y EQ COM'!P49 -> 0 | I30: ='F03 COM Y EQ COM'!Q49 -> 0 | J30: ='F03 COM Y EQ COM'!R49 -> 0 | K30: ='F03 COM Y EQ COM'!S49 -> 0 | ... Q30: ='F03 COM Y EQ COM'!Y49 -> 0 | R30: =SUM(D30:Q30) -> 32526 | T30: =R30/$E$42 -> 1800 | V30: ='F03 COM Y EQ COM'!L51 -> 32526 | W30: =SERVICIO!B28 -> 32526 | X30: =V30-R30 -> 0 | Y30: =V30-W30 -> 0
B31: EQUIPO DE COMPUTO Y ARRENDAMIENTO DE EQ. COMPUTO
A33: EGRESO TOTAL MENSUAL | D33: =SUM(D8:D30) -> 20297892 | E33: =SUM(E8:E30) -> 2965507.6 | F33: =SUM(F8:F30) -> 0 | G33: =SUM(G8:G30) -> 0 | H33: =SUM(H8:H30) -> 0 | I33: =SUM(I8:I30) -> 0 | J33: =SUM(J8:J30) -> 0 | K33: =SUM(K8:K30) -> 0 | ... Q33: =SUM(Q8:Q30) -> 0 | R33: =SUM(D33:Q33) -> 23263399 | T33: =R33/$E$42 -> 1287404.5 | V33: =SERVICIO!B162 -> 23263399 | X33: =V33-R33 -> 0
A35: CAPEX TOTAL MENSUAL | D35: =D8 -> 16714398 | E35: =E8 -> 0 | F35: =F8 -> 0 | G35: =G8 -> 0 | H35: =H8 -> 0 | I35: =I8 -> 0 | J35: =J8 -> 0 | K35: =K8 -> 0 | ... Q35: =Q8 -> 0 | R35: =SUM(D35:Q35) -> 16714398 | T35: =R35/$E$42 -> 924980.5
A37: OPEX TOTAL MENSUAL | D37: =+D33-D35 -> 3583494.2 | E37: =+E33-E35 -> 2965507.6 | F37: =+F33-F35 -> 0 | G37: =+G33-G35 -> 0 | H37: =+H33-H35 -> 0 | I37: =+I33-I35 -> 0 | J37: =+J33-J35 -> 0 | K37: =+K33-K35 -> 0 | ... Q37: =+Q33-Q35 -> 0 | R37: =SUM(D37:Q37) -> 6549001.8 | T37: =R37/$E$42 -> 362424
A39: OPEX TOTAL MENSUAL REAL | R39: =SUM(D39:Q39) -> 0 | T39: =+R39*PREMISAS!$D$18 -> 0
D41: =SERVICIO!A195 -> Premisas
D42: =SERVICIO!A196 -> Paridad | E42: =SERVICIO!B196 -> 18.07
D43: =SERVICIO!A197 -> Mes | E43: =SERVICIO!B197 -> 30.4
D44: =SERVICIO!A198 -> Periodo Pago (días) | E44: =SERVICIO!B198 -> 30
D45: =SERVICIO!A199 -> Gas lp | E45: =SERVICIO!B199 -> 0
D46: =SERVICIO!A200 -> Gasolina Magna | E46: =SERVICIO!B200 -> 22
D47: =SERVICIO!A201 -> Diesel | E47: =SERVICIO!B201 -> 23

Sheet F08 INGRESOS
B2: INGRESOS
B5: RESUMEN | C5: PARTIDA | D5: CONCEPTO | E5: UNIDAD | F5: CANTIDAD | G5: IMPORTE SERVICIO Y DIA | H5: IMPORTE TOTAL | I5: IMPORTE | J5: IMPORTE TOTAL | K5: TOTAL C/IVA | M5: Instalación | N5: Instalación | O5: Mes 1 | P5: Mes 2 | Q5: Mes 3 | R5: Mes 4 | S5: Mes 5 | T5: Mes 6 | U5: Mes 7 | V5: Mes 8 | W5: Mes 9 | X5: Mes 10 | Y5: Mes 11 | Z5: Mes 12
O6: ENE | P6: FEB | Q6: MAR | R6: ABR | S6: MAY | T6: JUN | U6: JUL | V6: AGO | W6: SEP | X6: OCT | Y6: NOV | Z6: DIC
G7: [USD] | H7: [USD] | I7: [MN] | J7: [MN] | K7: [MN] | O7: 31 | P7: 29 | Q7: 31 | R7: 30 | S7: 30 | T7: 31 | U7: 31 | V7: 31 | W7: 30 | X7: 31 | Y7: 30 | Z7: 31
B8: FACTURACION | C8: 1.2 | D8: Servicio de diseño, interconexión eléctrica, pruebas y puesta en operación de equipos de bombeo electrocentrífugo horizontal de 10,000-20,000 BPD. | E8: Servicio | F8: =PREMISAS!G7 -> 1 | G8: =PREMISAS!H7 -> 104077.7 | H8: =G8*F8 -> 104077.7 | I8: =PREMISAS!I7 -> 1880684 | J8: =F8*I8 -> 1880684 | K8: =J8*1.16 -> 2181593.5 | M8: =PREMISAS!M7 -> 1880684 | N8: =PREMISAS!N7 -> 0 | O8: =PREMISAS!O7 -> 0 | P8: =PREMISAS!P7 -> 0 | Q8: =PREMISAS!Q7 -> 0 | R8: =PREMISAS!R7 -> 0 | S8: =PREMISAS!S7 -> 0 | T8: =PREMISAS!T7 -> 0 | ... Z8: =PREMISAS!Z7 -> 0
B9: FACTURACION | C9: 2.2 | D9: Variador de frecuencia para 300 KW/375 KVA. | E9: Día | F9: =PREMISAS!G8 -> 1 | G9: =PREMISAS!H8 -> 1149249 | H9: =G9*F9 -> 1149249 | I9: =PREMISAS!I8 -> 20766930 | J9: =F9*I9 -> 20766930 | K9: =J9*1.16 -> 24089639 | M9: =PREMISAS!M8 -> 0 | N9: =PREMISAS!N8 -> 20766930 | O9: =PREMISAS!O8 -> 0 | P9: =PREMISAS!P8 -> 0 | Q9: =PREMISAS!Q8 -> 0 | R9: =PREMISAS!R8 -> 0 | S9: =PREMISAS!S8 -> 0 | T9: =PREMISAS!T8 -> 0 | ... Z9: =PREMISAS!Z8 -> 0
B10: FACTURACION | C10: 2.6 | D10: Generador de energía a gas de 300 KW/375 KVA | E10: Día | F10: =PREMISAS!G9 -> 1 | G10: =PREMISAS!H9 -> 880052.49 | H10: =G10*F10 -> 880052.49 | I10: =PREMISAS!I9 -> 15902548 | J10: =F10*I10 -> 15902548 | K10: =J10*1.16 -> 18446956 | M10: =PREMISAS!M9 -> 15902548 | N10: =PREMISAS!N9 -> 0 | O10: =PREMISAS!O9 -> 0 | P10: =PREMISAS!P9 -> 0 | Q10: =PREMISAS!Q9 -> 0 | R10: =PREMISAS!R9 -> 0 | S10: =PREMISAS!S9 -> 0 | T10: =PREMISAS!T9 -> 0 | ... Z10: =PREMISAS!Z9 -> 0
B11: FACTURACION | C11: 2.6 | D11: Generador de energía a gas de 300 KW/375 KVA a disposición. | E11: Día | F11: =PREMISAS!G10 -> 1 | G11: =PREMISAS!H10 -> 0 | H11: =G11*F11 -> 0 | I11: =PREMISAS!I10 -> 0 | J11: =F11*I11 -> 0 | K11: =J11*1.16 -> 0 | M11: =PREMISAS!M10 -> 0 | N11: =PREMISAS!N10 -> 0 | O11: =PREMISAS!O10 -> 0 | P11: =PREMISAS!P10 -> 0 | Q11: =PREMISAS!Q10 -> 0 | R11: =PREMISAS!R10 -> 0 | S11: =PREMISAS!S10 -> 0 | T11: =PREMISAS!T10 -> 0 | ... Z11: =PREMISAS!Z10 -> 0
B12: FACTURACION | C12: 2.7 | D12: Patín con bomba electrocentrífuga horizontal con gasto de 10,000-20,000 BPD incluye la operación continua. | E12: Día | F12: =PREMISAS!G11 -> 0 | G12: =PREMISAS!H11 -> 0 | H12: =G12*F12 -> 0 | I12: =PREMISAS!I11 -> 0 | J12: =F12*I12 -> 0 | K12: =J12*1.16 -> 0 | M12: =PREMISAS!M11 -> 0 | N12: =PREMISAS!N11 -> 0 | O12: =PREMISAS!O11 -> 0 | P12: =PREMISAS!P11 -> 0 | Q12: =PREMISAS!Q11 -> 0 | R12: =PREMISAS!R11 -> 0 | S12: =PREMISAS!S11 -> 0 | T12: =PREMISAS!T11 -> 0 | ... Z12: =PREMISAS!Z11 -> 0
B13: FACTURACION | C13: 2.7 | D13: Patín con bomba electrocentrífuga horizontal con gasto de 20,000-30,000 BPD incluye la operación continua. | E13: Día | F13: =PREMISAS!G12 -> 1 | G13: =PREMISAS!H12 -> 2034857.9 | H13: =G13*F13 -> 2034857.9 | I13: =PREMISAS!I12 -> 36769882 | J13: =F13*I13 -> 36769882 | K13: =J13*1.16 -> 42653064 | M13: =PREMISAS!M12 -> 0 | N13: =PREMISAS!N12 -> 36769882 | O13: =PREMISAS!O12 -> 0 | P13: =PREMISAS!P12 -> 0 | Q13: =PREMISAS!Q12 -> 0 | R13: =PREMISAS!R12 -> 0 | S13: =PREMISAS!S12 -> 0 | T13: =PREMISAS!T12 -> 0 | ... Z13: =PREMISAS!Z12 -> 0
B16: =PREMISAS!C17 -> Premisas | K16: Total Mensual [MN] | M16: =SUM(M8:M14) -> 17783233 | N16: =SUM(N8:N14) -> 57536812 | O16: =SUM(O8:O14) -> 0 | P16: =SUM(P8:P14) -> 0 | Q16: =SUM(Q8:Q14) -> 0 | R16: =SUM(R8:R14) -> 0 | S16: =SUM(S8:S14) -> 0 | T16: =SUM(T8:T14) -> 0 | ... Z16: =SUM(Z8:Z14) -> 0
B17: =PREMISAS!C18 -> Paridad | C17: =PREMISAS!D18 -> 18.07 | K17: Total Mensual [USD] | M17: =M16/$C$17 -> 984130.19 | N17: =N16/$C$17 -> 3184106.9 | O17: =O16/$C$17 -> 0 | P17: =P16/$C$17 -> 0 | Q17: =Q16/$C$17 -> 0 | R17: =R16/$C$17 -> 0 | S17: =S16/$C$17 -> 0 | T17: =T16/$C$17 -> 0 | ... Z17: =Z16/$C$17 -> 0
B18: =PREMISAS!C19 -> Mes | C18: =PREMISAS!D19 -> 30.4 | K18: Total [MN] | M18: =SUM(M16:Z16) -> 75320045
B19: =PREMISAS!C20 -> Periodo Pago (días) | C19: =PREMISAS!D20 -> 30 | K19: Total [USD] | M19: =M18/C17 -> 4168237.1
B20: =PREMISAS!C21 -> Gas lp | C20: =PREMISAS!D21 -> 0
B21: =PREMISAS!C22 -> Gasolina Magna | C21: =PREMISAS!D22 -> 22
B22: =PREMISAS!C23 -> Diesel | C22: =PREMISAS!D23 -> 23

Sheet F00 INVERSIÓN
B2: INVERSIÓN
B5: RESUMEN | C5: DESCRIPCIÓN 1 | D5: UNIDAD | E5: CANTIDAD | F5: IMPORTE SERVICIO Y DIA | G5: IMPORTE TOTAL | H5: IMPORTE | I5: IMPORTE TOTAL | J5: TOTAL C/IVA | L5: Instalación | M5: Instalación | N5: Mes 1 | O5: Mes 2 | P5: Mes 3 | Q5: Mes 4 | R5: Mes 5 | S5: Mes 6 | T5: Mes 7 | U5: Mes 8 | V5: Mes 9 | W5: Mes 10 | X5: Mes 11 | Y5: Mes 12
N6: ENE | O6: FEB | P6: MAR | Q6: ABR | R6: MAY | S6: JUN | T6: JUL | U6: AGO | V6: SEP | W6: OCT | X6: NOV | Y6: DIC
F7: [USD] | G7: [USD] | H7: [MN] | I7: [MN] | J7: [MN] | N7: 31 | O7: 29 | P7: 31 | Q7: 30 | R7: 30 | S7: 31 | T7: 31 | U7: 31 | V7: 30 | W7: 31 | X7: 30 | Y7: 31
B8: EQUIPO DE TRANSPORTE | E8: 0 | F8: 0 | G8: =E8*F8 -> 0 | H8: =F8*$C$44 -> 0 | I8: =E8*H8 -> 0 | J8: =I8*1.16 -> 0 | L8: 0 | M8: =I8 -> 0 | N8: 0 | O8: 0 | P8: 0 | Q8: 0 | R8: 0 | S8: 0 | T8: 0 | U8: 0 | V8: 0 | W8: 0 | X8: 0 | Y8: 0
B9: EQUIPO DE TRANSPORTE | C9: Camionetas | E9: 0 | F9: 32025.45 | G9: =E9*F9 -> 0 | H9: =F9*$C$44 -> 578699.88 | I9: =E9*H9 -> 0 | J9: =I9*1.16 -> 0 | L9: 0 | M9: =I9 -> 0 | N9: 0 | O9: 0 | P9: 0 | Q9: 0 | R9: 0 | T9: 0 | U9: 0 | V9: 0 | W9: 0 | X9: 0 | Y9: 0
B10: EQUIPO DE TRANSPORTE | E10: 0 | F10: 76812.4 | G10: =E10*F10 -> 0 | H10: =F10*$C$44 -> 1388000.1 | I10: =E10*H10 -> 0 | J10: =I10*1.16 -> 0 | L10: 0 | M10: 0 | N10: 0 | O10: 0 | Q10: 0 | R10: 0 | S10: 0 | T10: 0 | U10: 0 | V10: 0 | W10: 0 | X10: 0 | Y10: 0
B11: EQUIPO DE TRANSPORTE | E11: 0 | F11: 0 | G11: =E11*F11 -> 0 | H11: =F11*$C$44 -> 0 | I11: =E11*H11 -> 0 | J11: =I11*1.16 -> 0 | L11: 0 | M11: 0 | N11: =I11 -> 0 | O11: 0 | P11: 0 | Q11: 0 | R11: 0 | S11: 0 | T11: 0 | U11: 0 | V11: 0 | W11: 0 | X11: 0 | Y11: 0
L12: =SUM(L8:L11) -> 0 | M12: =SUM(M8:M11) -> 0 | N12: =SUM(N8:N11) -> 0 | O12: =SUM(O8:O11) -> 0 | P12: =SUM(P8:P11) -> 0 | Q12: =SUM(Q8:Q11) -> 0 | R12: =SUM(R8:R11) -> 0 | S12: =SUM(S8:S11) -> 0 | ... Y12: =SUM(Y8:Y11) -> 0
B14: EQUIPO DE MOBILIARIO | C14: Comisionamiento Gen | E14: 0 | F14: 6500 | G14: =E14*F14 -> 0 | H14: =F14*$C$44 -> 117455 | I14: =E14*H14 -> 0 | J14: =I14*1.16 -> 0 | L14: 0 | M14: =I14 -> 0 | N14: 0 | O14: 0 | P14: 0 | Q14: 0 | R14: 0 | S14: 0 | T14: 0 | U14: 0 | V14: 0 | W14: 0 | X14: 0 | Y14: 0
B15: EQUIPO DE MOBILIARIO | C15: Material de Seguridad | E15: 0 | F15: 3500 | G15: =E15*F15 -> 0 | H15: =F15*$C$44 -> 63245 | I15: =E15*H15 -> 0 | J15: =I15*1.16 -> 0 | L15: 0 | M15: 0 | N15: 0 | O15: 0 | P15: 0 | Q15: 0 | R15: 0 | S15: 0 | T15: 0 | U15: 0 | V15: 0 | W15: 0 | X15: 0 | Y15: 0
B16: EQUIPO DE MOBILIARIO | C16: Herramienta Manual | E16: 0 | F16: 11538.46 | G16: =E16*F16 -> 0 | H16: =F16*$C$44 -> 208499.97 | I16: =E16*H16 -> 0 | J16: =I16*1.16 -> 0 | L16: =I16 -> 0 | M16: 0 | N16: 0 | O16: 0 | P16: 0 | Q16: 0 | S16: 0 | T16: 0 | U16: 0 | V16: 0 | W16: 0 | X16: 0 | Y16: 0
B17: EQUIPO DE MOBILIARIO | C17: Comisionamiento HPS | E17: 0 | F17: 2000 | G17: =E17*F17 -> 0 | H17: =F17*$C$44 -> 36140 | I17: =E17*H17 -> 0 | J17: =I17*1.16 -> 0 | L17: 0 | M17: 0 | N17: =I17 -> 0 | O17: 0 | P17: 0 | Q17: 0 | R17: 0 | S17: 0 | T17: 0 | U17: 0 | V17: 0 | W17: 0 | X17: 0 | Y17: 0
L18: =SUM(L14:L17) -> 0 | M18: =SUM(M14:M17) -> 0 | N18: =SUM(N14:N17) -> 0 | O18: =SUM(O14:O17) -> 0 | P18: =SUM(P14:P17) -> 0 | Q18: =SUM(Q14:Q17) -> 0 | R18: =SUM(R14:R17) -> 0 | S18: =SUM(S14:S17) -> 0 | ... Y18: =SUM(Y14:Y17) -> 0
B20: MAQUINARIA Y EQUIPO 1 | E20: 0 | F20: 176089.03 | G20: =E20*F20 -> 0 | H20: =F20*$C$44 -> 3181928.8 | I20: =E20*H20 -> 0 | J20: =I20*1.16 -> 0 | L20: =I20 -> 0 | M20: 0 | N20: 0 | O20: 0 | P20: 0 | Q20: 0 | R20: 0 | S20: 0 | T20: 0 | U20: 0 | V20: 0 | W20: 0 | X20: 0 | Y20: 0
B21: MAQUINARIA Y EQUIPO 2 | E21: 0 | F21: 79961.3 | G21: =E21*F21 -> 0 | H21: =F21*$C$44 -> 1444900.7 | I21: =E21*H21 -> 0 | J21: =I21*1.16 -> 0 | L21: =I21 -> 0 | M21: 0 | N21: 0 | O21: 0 | P21: 0 | Q21: 0 | R21: 0 | S21: 0 | T21: 0 | U21: 0 | V21: 0 | W21: 0 | X21: 0 | Y21: 0
B22: MAQUINARIA Y EQUIPO 3 | E22: 0 | F22: 513000 | G22: =E22*F22 -> 0 | H22: =F22*$C$44 -> 9269910 | I22: =E22*H22 -> 0 | J22: =I22*1.16 -> 0 | L22: =I22 -> 0 | M22: 0 | N22: 0 | O22: 0 | P22: 0 | Q22: 0 | S22: 0 | T22: 0 | U22: 0 | V22: 0 | W22: 0 | X22: 0 | Y22: 0
B23: MAQUINARIA Y EQUIPO 4 | E23: 0 | F23: 49960 | G23: =E23*F23 -> 0 | H23: =F23*$C$44 -> 902777.2 | I23: =E23*H23 -> 0 | J23: =I23*1.16 -> 0 | L23: 0 | M23: =I23 -> 0 | N23: 0 | O23: 0 | P23: 0 | Q23: 0 | R23: 0 | S23: 0 | T23: 0 | U23: 0 | V23: 0 | W23: 0 | X23: 0 | Y23: 0
B24: MAQUINARIA Y EQUIPO 5 | E24: 0 | F24: 50000 | G24: =E24*F24 -> 0 | H24: =F24*$C$44 -> 903500 | I24: =E24*H24 -> 0 | J24: =I24*1.16 -> 0 | L24: 0 | M24: =I24 -> 0 | N24: 0 | O24: 0 | P24: 0 | Q24: 0 | R24: 0 | S24: 0 | T24: 0 | U24: 0 | V24: 0 | W24: 0 | X24: 0 | Y24: 0
B25: MAQUINARIA Y EQUIPO 6 | E25: 0 | F25: 160487 | G25: =E25*F25 -> 0 | H25: =F25*$C$44 -> 2900000 | I25: =E25*H25 -> 0 | J25: =I25*1.16 -> 0 | L25: =I25*0.5 -> 0 | M25: =L25 -> 0 | N25: 0 | O25: 0 | P25: 0 | Q25: 0 | R25: 0 | S25: 0 | T25: 0 | U25: 0 | V25: 0 | W25: 0 | X25: 0 | Y25: 0
B26: MAQUINARIA Y EQUIPO 7 | C26: Servicios | D26: RICCSSA | E26: 0 | F26: 49255.23 | G26: =E26*F26 -> 0 | H26: =F26*$C$44 -> 890042.01 | I26: =E26*H26 -> 0 | J26: =I26*1.16 -> 0 | L26: =I26 -> 0 | M26: 0 | N26: 0 | O26: 0 | P26: 0 | Q26: 0 | R26: 0 | S26: 0 | T26: 0 | U26: 0 | V26: 0 | W26: 0 | X26: 0 | Y26: 0
B27: MAQUINARIA Y EQUIPO 11 | C27: Servicio de obra | D27: RICCSSA | E27: 0 | F27: 26563.36 | G27: =E27*F27 -> 0 | H27: =F27*$C$44 -> 479999.92 | I27: =E27*H27 -> 0 | J27: =I27*1.16 -> 0 | L27: =I27 -> 0 | M27: 0 | N27: 0 | O27: 0 | P27: 0 | Q27: 0 | R27: 0 | S27: 0 | T27: 0 | U27: 0 | V27: 0 | W27: 0 | X27: 0 | Y27: 0
L28: =SUM(L20:L27) -> 0 | M28: =SUM(M20:M27) -> 0 | N28: =SUM(N20:N27) -> 0 | O28: =SUM(O20:O27) -> 0 | P28: =SUM(P20:P27) -> 0 | Q28: =SUM(Q20:Q27) -> 0 | R28: =SUM(R20:R27) -> 0 | S28: =SUM(S20:S27) -> 0 | ... Y28: =SUM(Y20:Y27) -> 0
B30: OTROS ACTIVOS | C30: Obra mecanica | D30: Geolis | E30: 1 | F30: 130261.96 | G30: =E30*F30 -> 130261.96 | H30: =F30*$C$44 -> 2353833.7 | I30: =E30*H30 -> 2353833.7 | J30: =I30*1.16 -> 2730447.1 | L30: =I30 -> 2353833.7 | M30: 0 | N30: 0 | O30: 0 | P30: 0 | Q30: 0 | R30: 0 | S30: 0 | T30: 0 | U30: 0 | V30: 0 | W30: 0 | X30: 0 | Y30: 0
B31: OTROS ACTIVOS | C31: Obra electrica | D31: Geolis | E31: 1 | F31: 214720.53 | G31: =E31*F31 -> 214720.53 | H31: =F31*$C$44 -> 3880000 | I31: =E31*H31 -> 3880000 | J31: =I31*1.16 -> 4500800 | L31: =I31 -> 3880000 | M31: 0 | N31: 0 | O31: 0 | P31: 0 | Q31: 0 | R31: 0 | S31: 0 | T31: 0 | U31: 0 | V31: 0 | W31: 0 | X31: 0 | Y31: 0
B32: OTROS ACTIVOS | C32: Servicios | D32: Geolis | E32: 0 | F32: 88695.55 | G32: =E32*F32 -> 0 | H32: =F32*$C$44 -> 1602728.6 | I32: =E32*H32 -> 0 | J32: =I32*1.16 -> 0 | L32: =I32 -> 0 | M32: 0 | N32: 0 | O32: 0 | P32: 0 | Q32: 0 | R32: 0 | S32: 0 | T32: 0 | U32: 0 | V32: 0 | W32: 0 | X32: 0 | Y32: 0
B33: OTROS ACTIVOS | C33: Generador | D33: Geolis | E33: 1 | F33: 579998 | G33: =E33*F33 -> 579998 | H33: =F33*$C$44 -> 10480564 | I33: =E33*H33 -> 10480564 | J33: =I33*1.16 -> 12157454 | L33: =I33 -> 10480564
B34: OTROS ACTIVOS | C34: Refaccionamiento | D34: Geolis | E34: 0 | F34: 87242.9 | G34: =E34*F34 -> 0 | H34: =F34*$C$44 -> 1576479.2 | I34: =E34*H34 -> 0 | J34: =I34*1.16 -> 0 | L34: =I34 -> 0 | M34: 0 | N34: 0 | O34: 0 | P34: 0 | Q34: 0 | R34: 0 | S34: 0 | T34: 0 | U34: 0 | V34: 0 | W34: 0 | X34: 0 | Y34: 0
L35: =SUM(L30:L34) -> 16714398 | M35: =SUM(M30:M34) -> 0 | N35: =SUM(N30:N34) -> 0 | O35: =SUM(O30:O34) -> 0 | P35: =SUM(P30:P34) -> 0 | Q35: =SUM(Q30:Q34) -> 0 | R35: =SUM(R30:R34) -> 0 | S35: =SUM(S30:S34) -> 0 | ... Y35: =SUM(Y30:Y34) -> 0
B37: SOFTWARE Y LICICENCIAS | E37: 0 | F37: 0 | G37: =E37*F37 -> 0 | H37: =F37*$C$44 -> 0 | I37: =E37*H37 -> 0 | J37: =I37*1.16 -> 0 | L37: 0 | M37: 0 | N37: 0 | O37: 0 | P37: 0 | Q37: 0 | R37: 0 | S37: 0 | T37: 0 | U37: 0 | V37: 0 | W37: 0 | X37: 0 | Y37: 0
B38: SOFTWARE Y LICICENCIAS | E38: 0 | F38: 0 | G38: =E38*F38 -> 0 | H38: =F38*$C$44 -> 0 | I38: =E38*H38 -> 0 | J38: =I38*1.16 -> 0 | L38: 0 | M38: 0 | N38: 0 | O38: 0 | P38: 0 | Q38: 0 | R38: 0 | S38: 0 | T38: 0 | U38: 0 | V38: 0 | W38: 0 | X38: 0 | Y38: 0
B39: SOFTWARE Y LICICENCIAS | E39: 0 | F39: 0 | G39: =E39*F39 -> 0 | H39: =F39*$C$44 -> 0 | I39: =E39*H39 -> 0 | J39: =I39*1.16 -> 0 | L39: 0 | M39: 0 | N39: 0 | O39: 0 | P39: 0 | Q39: 0 | R39: 0 | S39: 0 | T39: 0 | U39: 0 | V39: 0 | W39: 0 | X39: 0 | Y39: 0
B40: SOFTWARE Y LICICENCIAS | E40: 0 | F40: 0 | G40: =E40*F40 -> 0 | H40: =F40*$C$44 -> 0 | I40: =E40*H40 -> 0 | J40: =I40*1.16 -> 0 | L40: 0 | M40: 0 | N40: 0 | O40: 0 | P40: 0 | Q40: 0 | R40: 0 | S40: 0 | T40: 0 | U40: 0 | V40: 0 | W40: 0 | X40: 0 | Y40: 0
L41: =SUM(L37:L40) -> 0 | M41: =SUM(M37:M40) -> 0 | N41: =SUM(N37:N40) -> 0 | O41: =SUM(O37:O40) -> 0 | P41: =SUM(P37:P40) -> 0 | Q41: =SUM(Q37:Q40) -> 0 | R41: =SUM(R37:R40) -> 0 | S41: =SUM(S37:S40) -> 0 | ... Y41: =SUM(Y37:Y40) -> 0
B43: ='F08 INGRESOS'!B16 -> Premisas | J43: Total Mensual [MN] | L43: =L41+L35+L28+L18+L12 -> 16714398 | M43: =M41+M35+M28+M18+M12 -> 0 | N43: =N41+N35+N28+N18+N12 -> 0 | O43: =O41+O35+O28+O18+O12 -> 0 | P43: =P41+P35+P28+P18+P12 -> 0 | Q43: =Q41+Q35+Q28+Q18+Q12 -> 0 | R43: =R41+R35+R28+R18+R12 -> 0 | S43: =S41+S35+S28+S18+S12 -> 0 | ... Y43: =Y41+Y35+Y28+Y18+Y12 -> 0
B44: ='F08 INGRESOS'!B17 -> Paridad | C44: ='F08 INGRESOS'!C17 -> 18.07 | J44: Total Mensual [USD] | L44: =L43/$C$44 -> 924980.5 | M44: =M43/$C$44 -> 0 | N44: =N43/$C$44 -> 0 | O44: =O43/$C$44 -> 0 | P44: =P43/$C$44 -> 0 | Q44: =Q43/$C$44 -> 0 | R44: =R43/$C$44 -> 0 | S44: =S43/$C$44 -> 0 | ... Y44: =Y43/$C$44 -> 0
B45: ='F08 INGRESOS'!B18 -> Mes | C45: ='F08 INGRESOS'!C18 -> 30.4 | J45: Total [MN] | L45: =SUM(L43:Y43) -> 16714398
B46: ='F08 INGRESOS'!B19 -> Periodo Pago (días) | C46: ='F08 INGRESOS'!C19 -> 30 | J46: Total [USD] | L46: =L45/$C$44 -> 924980.5
B47: ='F08 INGRESOS'!B20 -> Gas lp | C47: ='F08 INGRESOS'!C20 -> 0
B48: ='F08 INGRESOS'!B21 -> Gasolina Magna | C48: ='F08 INGRESOS'!C21 -> 22
...

Sheet F01 NÓMINA
B2: NÓMINA
B5: RESUMEN | C5: NOMBRE | D5: PUESTO | E5: UNIDAD | F5: CANTIDAD | G5: SALARIO | H5: IMPUESTOS | I5: COSTO REAL C/IMP. | K5: AGUINALDO | L5: FONDO DE AHORRO | M5: UTILIDADES | N5: DESPENSA | O5: VIVIENDA | P5: ISR | Q5: VACACIONES | R5: IMPORTE | S5: IMPORTE TOTAL | T5: IMPORTE | U5: IMPORTE TOTAL | V5: TOTAL C/IVA | X5: Instalación | Y5: Instalación | Z5: Mes 1 | AA5: Mes 2 | AB5: Mes 3 | AC5: Mes 4 | AD5: Mes 5 | AE5: Mes 6 | AF5: Mes 7 | AG5: Mes 8 | AH5: Mes 9 | AI5: Mes 10 | AJ5: Mes 11 | AK5: Mes 12
Z6: ENE | AA6: FEB | AB6: MAR | AC6: ABR | AD6: MAY | AE6: JUN | AF6: JUL | AG6: AGO | AH6: SEP | AI6: OCT | AJ6: NOV | AK6: DIC
R7: [USD] | S7: [USD] | T7: [MN] | U7: [MN] | V7: [MN] | Z7: 31 | AA7: 29 | AB7: 31 | AC7: 30 | AD7: 30 | AE7: 31 | AF7: 31 | AG7: 31 | AH7: 30 | AI7: 31 | AJ7: 30 | AK7: 31
B8: NOMINA Y ADICIONALES | D8: SUPERVISOR DE OBRA | F8: 1 | G8: 24000 | H8: 1 | I8: =G8*(1+H8) -> 48000 | K8: =G8 -> 24000 | L8: =G8/4 -> 6000 | M8: =G8/2 -> 12000 | N8: 0 | O8: 0 | Q8: =(G8/30.4)*6 -> 4736.8421 | R8: =T8/$C$21 -> 2678.1813 | S8: =R8*F8 -> 2678.1813 | T8: =I8+O8+(Q8/12) -> 48394.737 | U8: =T8*F8 -> 48394.737 | V8: =U8*1.16 -> 56137.895 | X8: =$U$8 -> 48394.737 | Y8: =$U$8 -> 48394.737 | Z8: 0 | AA8: 0 | AB8: 0 | AC8: 0 | AD8: 0 | AE8: 0 | AF8: 0 | AG8: 0 | AH8: 0 | AI8: 0 | AJ8: 0 | AK8: 0
