Workbook

Sheet USD
A1: GEOLIS SA DE CV
A2: Proyecto: colocar unidad de negocio
A3: INGRESOS 2025
A4: Descripcion | B4: Total Presupuestado | C4: Enero Pre | D4: Febrero Pre | E4: Marzo Pre | F4: Abril Pre | G4: Mayo Pre | H4: Junio Pre | I4: Julio Pre | J4: Agosto Pre | K4: Septiembre Pre | L4: Octubre Pre | M4: Noviembre Pre | N4: Diciembre Pre
A5: FACTURACION | B5: =SUM(C5:N5) -> 46339701 | C5: 4113505.5 | D5: 3839271.8 | E5: 4113505.5 | F5: 3980811.8 | G5: 4113505.5 | H5: 3980811.8 | I5: 4113505.5 | J5: 4113505.5 | K5: 3980811.8 | L5: 4113505.5 | M5: 3163455.9 | N5: 2713505.5
A7: EGRESOS 2025
A8: Descripcion | B8: Total Presupuestado | C8: Enero Pre | D8: Febrero Pre | E8: Marzo Pre | F8: Abril Pre | G8: Mayo Pre | H8: Junio Pre | I8: Julio Pre | J8: Agosto Pre | K8: Septiembre Pre | L8: Octubre Pre | M8: Noviembre Pre | N8: Diciembre Pre
A9: EQUIPO DE TRANSPORTE | B9: =SUM(C9:N9) -> 94000 | C9: =+'[1]F00 INV'!Q33+'[1]F00 INV'!Q16 -> 22800 | D9: =+'[1]F00 INV'!R33+'[1]F00 INV'!R16 -> 22800 | E9: =+'[1]F00 INV'!S33+'[1]F00 INV'!S16 -> 48400 | F9: =+'[1]F00 INV'!T46+'[1]F00 INV'!T47 -> 0 | G9: =+'[1]F00 INV'!U46+'[1]F00 INV'!U47 -> 0 | H9: =+'[1]F00 INV'!V46+'[1]F00 INV'!V47 -> 0 | I9: =+'[1]F00 INV'!W46+'[1]F00 INV'!W47 -> 0 | J9: =+'[1]F00 INV'!X46+'[1]F00 INV'!X47 -> 0 | K9: =+'[1]F00 INV'!Y46+'[1]F00 INV'!Y47 -> 0 | L9: =+'[1]F00 INV'!Z46+'[1]F00 INV'!Z47 -> 0 | M9: =+'[1]F00 INV'!AA46+'[1]F00 INV'!AA47 -> 0 | N9: =+'[1]F00 INV'!AB46+'[1]F00 INV'!AB47 -> 0
A10: EQUIPO DE MOBILIARIO | B10: =SUM(C10:N10) -> 416000 | C10: ='[1]F00 INV'!Q10+'[1]F00 INV'!Q11+'[1]F00 INV'!Q55+'[1]F00 INV'!Q35 -> 129000 | D10: ='[1]F00 INV'!R10+'[1]F00 INV'!R11+'[1]F00 INV'!R55+'[1]F00 INV'!R35 -> 139000 | E10: ='[1]F00 INV'!S10+'[1]F00 INV'!S11+'[1]F00 INV'!S55+'[1]F00 INV'!S35 -> 142000 | F10: ='[1]F00 INV'!T10+'[1]F00 INV'!T11+'[1]F00 INV'!T55+'[1]F00 INV'!T35 -> 3000 | G10: ='[1]F00 INV'!U10+'[1]F00 INV'!U11+'[1]F00 INV'!U55+'[1]F00 INV'!U35 -> 3000 | H10: ='[1]F00 INV'!V10+'[1]F00 INV'!V11+'[1]F00 INV'!V55+'[1]F00 INV'!V35 -> 0 | I10: ='[1]F00 INV'!W10+'[1]F00 INV'!W11+'[1]F00 INV'!W55+'[1]F00 INV'!W35 -> 0 | J10: ='[1]F00 INV'!X10+'[1]F00 INV'!X11+'[1]F00 INV'!X55+'[1]F00 INV'!X35 -> 0 | ... N10: ='[1]F00 INV'!AB10+'[1]F00 INV'!AB11+'[1]F00 INV'!AB55+'[1]F00 INV'!AB35 -> 0
A11: MAQUINARIA Y EQUIPO | B11: =SUM(C11:N11) -> 2094000 | C11: =+'[1]F00 INV'!Q54+'[1]F00 INV'!Q50+'[1]F00 INV'!Q49+'[1]F00 INV'!Q39+'[1]F00 INV'!Q30+'[1]F00 INV'!Q31+'[1]F00 INV'!Q32+'[1]F00 INV'!Q33+'[1]F00 INV'!Q29+'[1]F00 INV'!Q27+'[1]F00 INV'!Q25+'[1]F00 INV'!Q19+'[1]F00 INV'!Q18+'[1]F00 INV'!Q17+'[1]F00 INV'!Q16+'[1]F00 INV'!Q9 -> 580300 | D11: =+'[1]F00 INV'!R54+'[1]F00 INV'!R50+'[1]F00 INV'!R49+'[1]F00 INV'!R39+'[1]F00 INV'!R30+'[1]F00 INV'!R31+'[1]F00 INV'!R32+'[1]F00 INV'!R33+'[1]F00 INV'!R29+'[1]F00 INV'!R27+'[1]F00 INV'!R25+'[1]F00 INV'!R19+'[1]F00 INV'!R18+'[1]F00 INV'!R17+'[1]F00 INV'!R16+'[1]F00 INV'!R9 -> 637800 | E11: =+'[1]F00 INV'!S54+'[1]F00 INV'!S50+'[1]F00 INV'!S49+'[1]F00 INV'!S39+'[1]F00 INV'!S30+'[1]F00 INV'!S31+'[1]F00 INV'!S32+'[1]F00 INV'!S33+'[1]F00 INV'!S29+'[1]F00 INV'!S27+'[1]F00 INV'!S25+'[1]F00 INV'!S19+'[1]F00 INV'!S18+'[1]F00 INV'!S17+'[1]F00 INV'!S16+'[1]F00 INV'!S9 -> 530900 | F11: =+'[1]F00 INV'!T54+'[1]F00 INV'!T50+'[1]F00 INV'!T49+'[1]F00 INV'!T39+'[1]F00 INV'!T30+'[1]F00 INV'!T31+'[1]F00 INV'!T32+'[1]F00 INV'!T33+'[1]F00 INV'!T29+'[1]F00 INV'!T27+'[1]F00 INV'!T25+'[1]F00 INV'!T19+'[1]F00 INV'!T18+'[1]F00 INV'!T17+'[1]F00 INV'!T16+'[1]F00 INV'!T9 -> 315000 | G11: =+'[1]F00 INV'!U54+'[1]F00 INV'!U50+'[1]F00 INV'!U49+'[1]F00 INV'!U39+'[1]F00 INV'!U30+'[1]F00 INV'!U31+'[1]F00 INV'!U32+'[1]F00 INV'!U33+'[1]F00 INV'!U29+'[1]F00 INV'!U27+'[1]F00 INV'!U25+'[1]F00 INV'!U19+'[1]F00 INV'!U18+'[1]F00 INV'!U17+'[1]F00 INV'!U16+'[1]F00 INV'!U9 -> 15000 | H11: =+'[1]F00 INV'!V54+'[1]F00 INV'!V50+'[1]F00 INV'!V49+'[1]F00 INV'!V39+'[1]F00 INV'!V30+'[1]F00 INV'!V31+'[1]F00 INV'!V32+'[1]F00 INV'!V33+'[1]F00 INV'!V29+'[1]F00 INV'!V27+'[1]F00 INV'!V25+'[1]F00 INV'!V19+'[1]F00 INV'!V18+'[1]F00 INV'!V17+'[1]F00 INV'!V16+'[1]F00 INV'!V9 -> 15000 | I11: =+'[1]F00 INV'!W54+'[1]F00 INV'!W50+'[1]F00 INV'!W49+'[1]F00 INV'!W39+'[1]F00 INV'!W30+'[1]F00 INV'!W31+'[1]F00 INV'!W32+'[1]F00 INV'!W33+'[1]F00 INV'!W29+'[1]F00 INV'!W27+'[1]F00 INV'!W25+'[1]F00 INV'!W19+'[1]F00 INV'!W18+'[1]F00 INV'!W17+'[1]F00 INV'!W16+'[1]F00 INV'!W9 -> 0 | J11: =+'[1]F00 INV'!X54+'[1]F00 INV'!X50+'[1]F00 INV'!X49+'[1]F00 INV'!X39+'[1]F00 INV'!X30+'[1]F00 INV'!X31+'[1]F00 INV'!X32+'[1]F00 INV'!X33+'[1]F00 INV'!X29+'[1]F00 INV'!X27+'[1]F00 INV'!X25+'[1]F00 INV'!X19+'[1]F00 INV'!X18+'[1]F00 INV'!X17+'[1]F00 INV'!X16+'[1]F00 INV'!X9 -> 0 | ... N11: =+'[1]F00 INV'!AB54+'[1]F00 INV'!AB50+'[1]F00 INV'!AB49+'[1]F00 INV'!AB39+'[1]F00 INV'!AB30+'[1]F00 INV'!AB31+'[1]F00 INV'!AB32+'[1]F00 INV'!AB33+'[1]F00 INV'!AB29+'[1]F00 INV'!AB27+'[1]F00 INV'!AB25+'[1]F00 INV'!AB19+'[1]F00 INV'!AB18+'[1]F00 INV'!AB17+'[1]F00 INV'!AB16+'[1]F00 INV'!AB9 -> 0
A12: OTROS ACTIVOS | B12: =SUM(C12:N12) -> 2755000 | C12: =+'[1]F00 INV'!Q36+'[1]F00 INV'!Q40+'[1]F00 INV'!Q53 -> 450000 | D12: =+'[1]F00 INV'!R36+'[1]F00 INV'!R40+'[1]F00 INV'!R53 -> 455000 | E12: =+'[1]F00 INV'!S36+'[1]F00 INV'!S40+'[1]F00 INV'!S53 -> 500000 | F12: =+'[1]F00 INV'!T36+'[1]F00 INV'!T40+'[1]F00 INV'!T53 -> 450000 | G12: =+'[1]F00 INV'!U36+'[1]F00 INV'!U40+'[1]F00 INV'!U53 -> 450000 | H12: =+'[1]F00 INV'!V36+'[1]F00 INV'!V40+'[1]F00 INV'!V53 -> 450000 | I12: =+'[1]F00 INV'!W36+'[1]F00 INV'!W40+'[1]F00 INV'!W53 -> 0 | J12: =+'[1]F00 INV'!X36+'[1]F00 INV'!X40+'[1]F00 INV'!X53 -> 0 | ... N12: =+'[1]F00 INV'!AB36+'[1]F00 INV'!AB40+'[1]F00 INV'!AB53 -> 0
A13: SOFTWARE Y LICICENCIAS | B13: =SUM(C13:N13) -> 0
A14: ACTIVOS | B14: =SUM(B9:B13) -> 5359000 | C14: =SUM(C9:C13) -> 1182100 | D14: =SUM(D9:D13) -> 1254600 | E14: =SUM(E9:E13) -> 1221300 | F14: =SUM(F9:F13) -> 768000 | G14: =SUM(G9:G13) -> 468000 | H14: =SUM(H9:H13) -> 465000 | I14: =SUM(I9:I13) -> 0 | ... N14: =SUM(N9:N13) -> 0 | P14: Mobiliario de oficina
A15: ARRENDAMIENTO DE INMUEBLES | B15: =SUM(C15:N15) -> 80000 | C15: =('[1]F02 INM Y SERV'!F9+'[1]F02 INM Y SERV'!F10+'[1]F02 INM Y SERV'!F11)/[1]FLUJO!$E$43 -> 6666.6667 | D15: =+C15 -> 6666.6667 | E15: =+D15 -> 6666.6667 | F15: =+E15 -> 6666.6667 | G15: =+F15 -> 6666.6667 | H15: =+G15 -> 6666.6667 | I15: =+H15 -> 6666.6667 | J15: =+I15 -> 6666.6667 | K15: =+J15 -> 6666.6667 | ... N15: =+M15 -> 6666.6667
A16: ENERGIA ELECTRICA | B16: =SUM(C16:N16) -> 22295.082 | C16: =('[1]F02 INM Y SERV'!H9+'[1]F02 INM Y SERV'!H10+'[1]F02 INM Y SERV'!H11)/[1]FLUJO!$E$43 -> 1857.9235 | D16: =+C16 -> 1857.9235 | E16: =+D16 -> 1857.9235 | F16: =+E16 -> 1857.9235 | G16: =+F16 -> 1857.9235 | H16: =+G16 -> 1857.9235 | I16: =+H16 -> 1857.9235 | J16: =+I16 -> 1857.9235 | K16: =+J16 -> 1857.9235 | ... N16: =+M16 -> 1857.9235
A17: RENTA DE CASAS NO DEDUCIBLE | B17: =SUM(C17:N17) -> 0
A18: SERVICIOS DE LIMPIEZA | B18: =SUM(C18:N18) -> 17062.295 | C18: =('[1]F02 INM Y SERV'!P9+'[1]F02 INM Y SERV'!P10+'[1]F02 INM Y SERV'!P11)/[1]FLUJO!$E$43 -> 1421.8579 | D18: =+C18 -> 1421.8579 | E18: =+D18 -> 1421.8579 | F18: =+E18 -> 1421.8579 | G18: =+F18 -> 1421.8579 | H18: =+G18 -> 1421.8579 | I18: =+H18 -> 1421.8579 | J18: =+I18 -> 1421.8579 | K18: =+J18 -> 1421.8579 | ... N18: =+M18 -> 1421.8579
A19: SERVICIOS DE VIGILANCIA | B19: =SUM(C19:N19) -> 19672.131 | C19: =('[1]F02 INM Y SERV'!O9+'[1]F02 INM Y SERV'!O10+'[1]F02 INM Y SERV'!O11)/[1]FLUJO!$E$43 -> 1639.3443 | D19: =+C19 -> 1639.3443 | E19: =+D19 -> 1639.3443 | F19: =+E19 -> 1639.3443 | G19: =+F19 -> 1639.3443 | H19: =+G19 -> 1639.3443 | I19: =+H19 -> 1639.3443 | J19: =+I19 -> 1639.3443 | K19: =+J19 -> 1639.3443 | ... N19: =+M19 -> 1639.3443
A20: SERVICIOS DE FUMIGACION | B20: =SUM(C20:N20) -> 0
A21: TELEFONIA FIJA | B21: =SUM(C21:N21) -> 0
A22: AGUA Y ALCANTARILLADO | B22: =SUM(C22:N22) -> 0
A23: ARRENDAMIENTO DE OF. MOVILES | B23: =SUM(C23:N23) -> 0
A24: ARRENDA DE INMUEBLES Y SERV | B24: =SUM(B15:B23) -> 139029.51 | C24: =SUM(C15:C23) -> 11585.792 | D24: =SUM(D15:D23) -> 11585.792 | E24: =SUM(E15:E23) -> 11585.792 | F24: =SUM(F15:F23) -> 11585.792 | G24: =SUM(G15:G23) -> 11585.792 | H24: =SUM(H15:H23) -> 11585.792 | I24: =SUM(I15:I23) -> 11585.792 | ... N24: =SUM(N15:N23) -> 11585.792 | P24: renta casa staff villahermosa, servicio de limpieza
A25: ROPA Y ARTICULOS DE PROTECCION | B25: =SUM(C25:N25) -> 342013.26 | C25: =+'[1]F01 NÓM'!$O$137 -> 24423.099 | D25: =+C25 -> 24423.099 | E25: =+'[1]F01 NÓM'!$O$138 -> 29316.707 | F25: =+E25 -> 29316.707 | G25: =+F25 -> 29316.707 | H25: =+G25 -> 29316.707 | I25: =+H25 -> 29316.707 | J25: =+I25 -> 29316.707 | K25: =+J25 -> 29316.707 | L25: =+K25 -> 29316.707 | M25: =+L25 -> 29316.707 | N25: =+M25 -> 29316.707
A26: ARTICULOS DE SEGURIDAD | B26: =B25 -> 342013.26 | C26: =C25 -> 24423.099 | D26: =D25 -> 24423.099 | E26: =E25 -> 29316.707 | F26: =F25 -> 29316.707 | G26: =G25 -> 29316.707 | H26: =H25 -> 29316.707 | I26: =I25 -> 29316.707 | ... N26: =N25 -> 29316.707 | P26: overoles, botas, lentes, porta credencial
A27: EQUIPO DE COMPUTO (Adquisición) | B27: =SUM(C27:N27) -> 9180.6557 | C27: =+'[1]F03 COM Y EQ COM'!J51 -> 9180.6557 | D27: =+'[1]F03 COM Y EQ COM'!K51 -> 0 | E27: =+'[1]F03 COM Y EQ COM'!L51 -> 0 | F27: =+'[1]F03 COM Y EQ COM'!M51 -> 0 | G27: =+'[1]F03 COM Y EQ COM'!N51 -> 0 | H27: =+'[1]F03 COM Y EQ COM'!O51 -> 0 | I27: =+'[1]F03 COM Y EQ COM'!P51 -> 0 | J27: =+'[1]F03 COM Y EQ COM'!Q51 -> 0 | ... N27: =+'[1]F03 COM Y EQ COM'!U51 -> 0
A28: ARRENDAMIENTO DE EQ. COMPUTO | B28: =SUM(C28:N28) -> 0
A29: EQUIPO DE COMPUTO | B29: =SUM(B27:B28) -> 9180.6557 | C29: =SUM(C27:C28) -> 9180.6557 | D29: =SUM(D27:D28) -> 0 | E29: =SUM(E27:E28) -> 0 | F29: =SUM(F27:F28) -> 0 | G29: =SUM(G27:G28) -> 0 | H29: =SUM(H27:H28) -> 0 | I29: =SUM(I27:I28) -> 0 | ... N29: =SUM(N27:N28) -> 0
A30: ENSERES MENORES DIVERSOS (Acondicionamiento de casas) | B30: =SUM(C30:N30) -> 0
A31: EQUIPOS Y ENSERES | B31: =B30 -> 0 | C31: =C30 -> 0 | D31: =D30 -> 0 | E31: =E30 -> 0 | F31: =F30 -> 0 | G31: =G30 -> 0 | H31: =H30 -> 0 | I31: =I30 -> 0 | ... N31: =N30 -> 0
A32: INSUMOS AGRICOLAS | B32: =SUM(C32:N32) -> 0
A33: PAPELERIA Y UTILES DE OFICINA | B33: =SUM(C33:N33) -> 24000 | C33: =+'[1]F07 OPERAC'!M8+'[1]F07 OPERAC'!M9 -> 2000 | D33: =+'[1]F07 OPERAC'!N8+'[1]F07 OPERAC'!N9 -> 2000 | E33: =+'[1]F07 OPERAC'!O8+'[1]F07 OPERAC'!O9 -> 2000 | F33: =+'[1]F07 OPERAC'!P8+'[1]F07 OPERAC'!P9 -> 2000 | G33: =+'[1]F07 OPERAC'!Q8+'[1]F07 OPERAC'!Q9 -> 2000 | H33: =+'[1]F07 OPERAC'!R8+'[1]F07 OPERAC'!R9 -> 2000 | I33: =+'[1]F07 OPERAC'!S8+'[1]F07 OPERAC'!S9 -> 2000 | J33: =+'[1]F07 OPERAC'!T8+'[1]F07 OPERAC'!T9 -> 2000 | ... N33: =+'[1]F07 OPERAC'!X8+'[1]F07 OPERAC'!X9 -> 2000
A34: ARTICULOS DE ASEO Y SANITARIOS | B34: =SUM(C34:N34) -> 90000 | C34: =+'[1]F07 OPERAC'!M58+'[1]F07 OPERAC'!M59+'[1]F07 OPERAC'!M60 -> 7500 | D34: =+'[1]F07 OPERAC'!N58+'[1]F07 OPERAC'!N59+'[1]F07 OPERAC'!N60 -> 7500 | E34: =+'[1]F07 OPERAC'!O58+'[1]F07 OPERAC'!O59+'[1]F07 OPERAC'!O60 -> 7500 | F34: =+'[1]F07 OPERAC'!P58+'[1]F07 OPERAC'!P59+'[1]F07 OPERAC'!P60 -> 7500 | G34: =+'[1]F07 OPERAC'!Q58+'[1]F07 OPERAC'!Q59+'[1]F07 OPERAC'!Q60 -> 7500 | H34: =+'[1]F07 OPERAC'!R58+'[1]F07 OPERAC'!R59+'[1]F07 OPERAC'!R60 -> 7500 | I34: =+'[1]F07 OPERAC'!S58+'[1]F07 OPERAC'!S59+'[1]F07 OPERAC'!S60 -> 7500 | J34: =+'[1]F07 OPERAC'!T58+'[1]F07 OPERAC'!T59+'[1]F07 OPERAC'!T60 -> 7500 | ... N34: =+'[1]F07 OPERAC'!X58+'[1]F07 OPERAC'!X59+'[1]F07 OPERAC'!X60 -> 7500
A35: ARTICULOS DE CAFETERIA | B35: =SUM(C35:N35) -> 54000 | C35: =+'[1]F07 OPERAC'!M10 -> 9000 | D35: =+'[1]F07 OPERAC'!N10 -> 0 | E35: =+'[1]F07 OPERAC'!O10 -> 9000 | F35: =+'[1]F07 OPERAC'!P10 -> 0 | G35: =+'[1]F07 OPERAC'!Q10 -> 9000 | H35: =+'[1]F07 OPERAC'!R10 -> 0 | I35: =+'[1]F07 OPERAC'!S10 -> 9000 | J35: =+'[1]F07 OPERAC'!T10 -> 0 | ... N35: =+'[1]F07 OPERAC'!X10 -> 0
A36: ARTICULOS DIGITALES Y DE COMPUTO | B36: =SUM(C36:N36) -> 0
A37: INSUMOS DE OFICINA | B37: =SUM(B33:B36) -> 168000 | C37: =SUM(C33:C36) -> 18500 | D37: =SUM(D33:D36) -> 9500 | E37: =SUM(E33:E36) -> 18500 | F37: =SUM(F33:F36) -> 9500 | G37: =SUM(G33:G36) -> 18500 | H37: =SUM(H33:H36) -> 9500 | I37: =SUM(I33:I36) -> 18500 | ... N37: =SUM(N33:N36) -> 9500
A38: SERVICIOS DE MERCADOTECNIA | B38: =SUM(C38:N38) -> 0
A39: PUBLICIDAD Y PROPAGANDA | B39: =SUM(C39:N39) -> 0
A40: MARKETING | B40: =SUM(B38:B39) -> 0 | C40: =SUM(C38:C39) -> 0 | D40: =SUM(D38:D39) -> 0 | E40: =SUM(E38:E39) -> 0 | F40: =SUM(F38:F39) -> 0 | G40: =SUM(G38:G39) -> 0 | H40: =SUM(H38:H39) -> 0 | I40: =SUM(I38:I39) -> 0 | ... N40: =SUM(N38:N39) -> 0 | P40: Servicio mensual Jimena, publicación en periodico o revista digital, renovacion anual en el directorio de la industria enegetica y extras
A41: ABRASIVOS | B41: =SUM(C41:N41) -> 0
...

Sheet MN
A1: GEOLIS SA DE CV | C1: 18.3
A2: Proyecto: PRC LITORAL
A3: INGRESOS 2025
A4: Descripcion | B4: Total Presupuestado | C4: Enero Pre | D4: Febrero Pre | E4: Marzo Pre | F4: Abril Pre | G4: Mayo Pre | H4: Junio Pre | I4: Julio Pre | J4: Agosto Pre | K4: Septiembre Pre | L4: Octubre Pre | M4: Noviembre Pre | N4: Diciembre Pre
A5: FACTURACION | B5: =SUM(C5:N5) -> 848016537 | C5: =+USD!C5*MN!$C$1 -> 75277151 | D5: =+USD!D5*MN!$C$1 -> 70258674 | E5: =+USD!E5*MN!$C$1 -> 75277151 | F5: =+USD!F5*MN!$C$1 -> 72848855 | G5: =+USD!G5*MN!$C$1 -> 75277151 | H5: =+USD!H5*MN!$C$1 -> 72848855 | I5: =+USD!I5*MN!$C$1 -> 75277151 | J5: =+USD!J5*MN!$C$1 -> 75277151 | ... N5: =+USD!N5*MN!$C$1 -> 49657151
A7: EGRESOS 2025
A8: Descripcion | B8: Total Presupuestado | C8: Enero Pre | D8: Febrero Pre | E8: Marzo Pre | F8: Abril Pre | G8: Mayo Pre | H8: Junio Pre | I8: Julio Pre | J8: Agosto Pre | K8: Septiembre Pre | L8: Octubre Pre | M8: Noviembre Pre | N8: Diciembre Pre
A9: EQUIPO DE TRANSPORTE | B9: =SUM(C9:N9) -> 1720200 | C9: =+USD!C9*MN!$C$1 -> 417240 | D9: =+USD!D9*MN!$C$1 -> 417240 | E9: =+USD!E9*MN!$C$1 -> 885720 | F9: =+USD!F9*MN!$C$1 -> 0 | G9: =+USD!G9*MN!$C$1 -> 0 | H9: =+USD!H9*MN!$C$1 -> 0 | I9: =+USD!I9*MN!$C$1 -> 0 | J9: =+USD!J9*MN!$C$1 -> 0 | ... N9: =+USD!N9*MN!$C$1 -> 0
A10: EQUIPO DE MOBILIARIO | B10: =SUM(C10:N10) -> 1830000 | C10: =+USD!C9*MN!$C$1 -> 417240 | D10: =+USD!D9*MN!$C$1 -> 417240 | E10: =+USD!E9*MN!$C$1 -> 885720 | F10: =+USD!F10*MN!$C$1 -> 54900 | G10: =+USD!G10*MN!$C$1 -> 54900 | H10: =+USD!H10*MN!$C$1 -> 0 | I10: =+USD!I10*MN!$C$1 -> 0 | J10: =+USD!J10*MN!$C$1 -> 0 | K10: =+USD!K10*MN!$C$1 -> 0 | L10: =+USD!L10*MN!$C$1 -> 0 | M10: =+USD!M10*MN!$C$1 -> 0 | N10: =+USD!N10*MN!$C$1 -> 0
A11: MAQUINARIA Y EQUIPO | B11: =SUM(C11:N11) -> 38320200 | C11: =+USD!C11*MN!$C$1 -> 10619490 | D11: =+USD!D11*MN!$C$1 -> 11671740 | E11: =+USD!E11*MN!$C$1 -> 9715470 | F11: =+USD!F11*MN!$C$1 -> 5764500 | G11: =+USD!G11*MN!$C$1 -> 274500 | H11: =+USD!H11*MN!$C$1 -> 274500 | I11: =+USD!I11*MN!$C$1 -> 0 | J11: =+USD!J11*MN!$C$1 -> 0 | ... N11: =+USD!N11*MN!$C$1 -> 0
A12: OTROS ACTIVOS | B12: =SUM(C12:N12) -> 50416500 | C12: =+USD!C12*MN!$C$1 -> 8235000 | D12: =+USD!D12*MN!$C$1 -> 8326500 | E12: =+USD!E12*MN!$C$1 -> 9150000 | F12: =+USD!F12*MN!$C$1 -> 8235000 | G12: =+USD!G12*MN!$C$1 -> 8235000 | H12: =+USD!H12*MN!$C$1 -> 8235000 | I12: =+USD!I12*MN!$C$1 -> 0 | J12: =+USD!J12*MN!$C$1 -> 0 | ... N12: =+USD!N12*MN!$C$1 -> 0
A13: SOFTWARE Y LICICENCIAS | B13: =SUM(C13:N13) -> 0 | C13: =+USD!C13*MN!$C$1 -> 0 | D13: =+USD!D13*MN!$C$1 -> 0 | E13: =+USD!E13*MN!$C$1 -> 0 | F13: =+USD!F13*MN!$C$1 -> 0 | G13: =+USD!G13*MN!$C$1 -> 0 | H13: =+USD!H13*MN!$C$1 -> 0 | I13: =+USD!I13*MN!$C$1 -> 0 | J13: =+USD!J13*MN!$C$1 -> 0 | ... N13: =+USD!N13*MN!$C$1 -> 0
A14: ACTIVOS | B14: =SUM(B9:B13) -> 92286900 | C14: =SUM(C9:C13) -> 19688970 | D14: =SUM(D9:D13) -> 20832720 | E14: =SUM(E9:E13) -> 20636910 | F14: =SUM(F9:F13) -> 14054400 | G14: =SUM(G9:G13) -> 8564400 | H14: =SUM(H9:H13) -> 8509500 | I14: =SUM(I9:I13) -> 0 | ... N14: =SUM(N9:N13) -> 0 | P14: Mobiliario de oficina
A15: ARRENDAMIENTO DE INMUEBLES | B15: =SUM(C15:N15) -> 1464000 | C15: =+USD!C15*MN!$C$1 -> 122000 | D15: =+USD!D15*MN!$C$1 -> 122000 | E15: =+USD!E15*MN!$C$1 -> 122000 | F15: =+USD!F15*MN!$C$1 -> 122000 | G15: =+USD!G15*MN!$C$1 -> 122000 | H15: =+USD!H15*MN!$C$1 -> 122000 | I15: =+USD!I15*MN!$C$1 -> 122000 | J15: =+USD!J15*MN!$C$1 -> 122000 | ... N15: =+USD!N15*MN!$C$1 -> 122000
A16: ENERGIA ELECTRICA | B16: =SUM(C16:N16) -> 408000 | C16: =+USD!C16*MN!$C$1 -> 34000 | D16: =+USD!D16*MN!$C$1 -> 34000 | E16: =+USD!E16*MN!$C$1 -> 34000 | F16: =+USD!F16*MN!$C$1 -> 34000 | G16: =+USD!G16*MN!$C$1 -> 34000 | H16: =+USD!H16*MN!$C$1 -> 34000 | I16: =+USD!I16*MN!$C$1 -> 34000 | J16: =+USD!J16*MN!$C$1 -> 34000 | ... N16: =+USD!N16*MN!$C$1 -> 34000
A17: RENTA DE CASAS NO DEDUCIBLE | B17: =SUM(C17:N17) -> 0 | C17: =+USD!C17*MN!$C$1 -> 0 | D17: =+USD!D17*MN!$C$1 -> 0 | E17: =+USD!E17*MN!$C$1 -> 0 | F17: =+USD!F17*MN!$C$1 -> 0 | G17: =+USD!G17*MN!$C$1 -> 0 | H17: =+USD!H17*MN!$C$1 -> 0 | I17: =+USD!I17*MN!$C$1 -> 0 | J17: =+USD!J17*MN!$C$1 -> 0 | ... N17: =+USD!N17*MN!$C$1 -> 0
A18: SERVICIOS DE LIMPIEZA | B18: =SUM(C18:N18) -> 312240 | C18: =+USD!C18*MN!$C$1 -> 26020 | D18: =+USD!D18*MN!$C$1 -> 26020 | E18: =+USD!E18*MN!$C$1 -> 26020 | F18: =+USD!F18*MN!$C$1 -> 26020 | G18: =+USD!G18*MN!$C$1 -> 26020 | H18: =+USD!H18*MN!$C$1 -> 26020 | I18: =+USD!I18*MN!$C$1 -> 26020 | J18: =+USD!J18*MN!$C$1 -> 26020 | ... N18: =+USD!N18*MN!$C$1 -> 26020
A19: SERVICIOS DE VIGILANCIA | B19: =SUM(C19:N19) -> 360000 | C19: =+USD!C19*MN!$C$1 -> 30000 | D19: =+USD!D19*MN!$C$1 -> 30000 | E19: =+USD!E19*MN!$C$1 -> 30000 | F19: =+USD!F19*MN!$C$1 -> 30000 | G19: =+USD!G19*MN!$C$1 -> 30000 | H19: =+USD!H19*MN!$C$1 -> 30000 | I19: =+USD!I19*MN!$C$1 -> 30000 | J19: =+USD!J19*MN!$C$1 -> 30000 | ... N19: =+USD!N19*MN!$C$1 -> 30000
A20: SERVICIOS DE FUMIGACION | B20: =SUM(C20:N20) -> 0 | C20: =+USD!C20*MN!$C$1 -> 0 | D20: =+USD!D20*MN!$C$1 -> 0 | E20: =+USD!E20*MN!$C$1 -> 0 | F20: =+USD!F20*MN!$C$1 -> 0 | G20: =+USD!G20*MN!$C$1 -> 0 | H20: =+USD!H20*MN!$C$1 -> 0 | I20: =+USD!I20*MN!$C$1 -> 0 | J20: =+USD!J20*MN!$C$1 -> 0 | ... N20: =+USD!N20*MN!$C$1 -> 0
A21: TELEFONIA FIJA | B21: =SUM(C21:N21) -> 0 | C21: =+USD!C21*MN!$C$1 -> 0 | D21: =+USD!D21*MN!$C$1 -> 0 | E21: =+USD!E21*MN!$C$1 -> 0 | F21: =+USD!F21*MN!$C$1 -> 0 | G21: =+USD!G21*MN!$C$1 -> 0 | H21: =+USD!H21*MN!$C$1 -> 0 | I21: =+USD!I21*MN!$C$1 -> 0 | J21: =+USD!J21*MN!$C$1 -> 0 | ... N21: =+USD!N21*MN!$C$1 -> 0
A22: AGUA Y ALCANTARILLADO | B22: =SUM(C22:N22) -> 0 | C22: =+USD!C22*MN!$C$1 -> 0 | D22: =+USD!D22*MN!$C$1 -> 0 | E22: =+USD!E22*MN!$C$1 -> 0 | F22: =+USD!F22*MN!$C$1 -> 0 | G22: =+USD!G22*MN!$C$1 -> 0 | H22: =+USD!H22*MN!$C$1 -> 0 | I22: =+USD!I22*MN!$C$1 -> 0 | J22: =+USD!J22*MN!$C$1 -> 0 | ... N22: =+USD!N22*MN!$C$1 -> 0
A23: ARRENDAMIENTO DE OF. MOVILES | B23: =SUM(C23:N23) -> 0 | C23: =+USD!C23*MN!$C$1 -> 0 | D23: =+USD!D23*MN!$C$1 -> 0 | E23: =+USD!E23*MN!$C$1 -> 0 | F23: =+USD!F23*MN!$C$1 -> 0 | G23: =+USD!G23*MN!$C$1 -> 0 | H23: =+USD!H23*MN!$C$1 -> 0 | I23: =+USD!I23*MN!$C$1 -> 0 | J23: =+USD!J23*MN!$C$1 -> 0 | ... N23: =+USD!N23*MN!$C$1 -> 0
A24: ARRENDA DE INMUEBLES Y SERV | B24: =SUM(B15:B23) -> 2544240 | C24: =SUM(C15:C23) -> 212020 | D24: =SUM(D15:D23) -> 212020 | E24: =SUM(E15:E23) -> 212020 | F24: =SUM(F15:F23) -> 212020 | G24: =SUM(G15:G23) -> 212020 | H24: =SUM(H15:H23) -> 212020 | I24: =SUM(I15:I23) -> 212020 | ... N24: =SUM(N15:N23) -> 212020 | P24: renta casa staff villahermosa, servicio de limpieza
A25: ROPA Y ARTICULOS DE PROTECCION | B25: =SUM(C25:N25) -> 6258842.7 | C25: =+USD!C25*MN!$C$1 -> 446942.71 | D25: =+USD!D25*MN!$C$1 -> 446942.71 | E25: =+USD!E25*MN!$C$1 -> 536495.73 | F25: =+USD!F25*MN!$C$1 -> 536495.73 | G25: =+USD!G25*MN!$C$1 -> 536495.73 | H25: =+USD!H25*MN!$C$1 -> 536495.73 | I25: =+USD!I25*MN!$C$1 -> 536495.73 | J25: =+USD!J25*MN!$C$1 -> 536495.73 | ... N25: =+USD!N25*MN!$C$1 -> 536495.73
A26: ARTICULOS DE SEGURIDAD | B26: =B25 -> 6258842.7 | C26: =C25 -> 446942.71 | D26: =D25 -> 446942.71 | E26: =E25 -> 536495.73 | F26: =F25 -> 536495.73 | G26: =G25 -> 536495.73 | H26: =H25 -> 536495.73 | I26: =I25 -> 536495.73 | ... N26: =N25 -> 536495.73 | P26: overoles, botas, lentes, porta credencial
A27: EQUIPO DE COMPUTO (Adquisición) | B27: =SUM(C27:N27) -> 168006 | C27: =+USD!C27*MN!$C$1 -> 168006 | D27: =+USD!D27*MN!$C$1 -> 0 | E27: =+USD!E27*MN!$C$1 -> 0 | F27: =+USD!F27*MN!$C$1 -> 0 | G27: =+USD!G27*MN!$C$1 -> 0 | H27: =+USD!H27*MN!$C$1 -> 0 | I27: =+USD!I27*MN!$C$1 -> 0 | J27: =+USD!J27*MN!$C$1 -> 0 | ... N27: =+USD!N27*MN!$C$1 -> 0
A28: ARRENDAMIENTO DE EQ. COMPUTO | B28: =SUM(C28:N28) -> 0 | C28: =+USD!C28*MN!$C$1 -> 0 | D28: =+USD!D28*MN!$C$1 -> 0 | E28: =+USD!E28*MN!$C$1 -> 0 | F28: =+USD!F28*MN!$C$1 -> 0 | G28: =+USD!G28*MN!$C$1 -> 0 | H28: =+USD!H28*MN!$C$1 -> 0 | I28: =+USD!I28*MN!$C$1 -> 0 | J28: =+USD!J28*MN!$C$1 -> 0 | ... N28: =+USD!N28*MN!$C$1 -> 0
A29: EQUIPO DE COMPUTO | B29: =SUM(B27:B28) -> 168006 | C29: =SUM(C27:C28) -> 168006 | D29: =SUM(D27:D28) -> 0 | E29: =SUM(E27:E28) -> 0 | F29: =SUM(F27:F28) -> 0 | G29: =SUM(G27:G28) -> 0 | H29: =SUM(H27:H28) -> 0 | I29: =SUM(I27:I28) -> 0 | ... N29: =SUM(N27:N28) -> 0
A30: ENSERES MENORES DIVERSOS (Acondicionamiento de casas) | B30: =SUM(C30:N30) -> 0 | C30: =+USD!C30*MN!$C$1 -> 0 | D30: =+USD!D30*MN!$C$1 -> 0 | E30: =+USD!E30*MN!$C$1 -> 0 | F30: =+USD!F30*MN!$C$1 -> 0 | G30: =+USD!G30*MN!$C$1 -> 0 | H30: =+USD!H30*MN!$C$1 -> 0 | I30: =+USD!I30*MN!$C$1 -> 0 | J30: =+USD!J30*MN!$C$1 -> 0 | ... N30: =+USD!N30*MN!$C$1 -> 0
A31: EQUIPOS Y ENSERES | B31: =B30 -> 0 | C31: =C30 -> 0 | D31: =D30 -> 0 | E31: =E30 -> 0 | F31: =F30 -> 0 | G31: =G30 -> 0 | H31: =H30 -> 0 | I31: =I30 -> 0 | ... N31: =N30 -> 0
A32: INSUMOS AGRICOLAS | B32: =SUM(C32:N32) -> 0
A33: PAPELERIA Y UTILES DE OFICINA | B33: =SUM(C33:N33) -> 439200 | C33: =+USD!C33*MN!$C$1 -> 36600 | D33: =+USD!D33*MN!$C$1 -> 36600 | E33: =+USD!E33*MN!$C$1 -> 36600 | F33: =+USD!F33*MN!$C$1 -> 36600 | G33: =+USD!G33*MN!$C$1 -> 36600 | H33: =+USD!H33*MN!$C$1 -> 36600 | I33: =+USD!I33*MN!$C$1 -> 36600 | J33: =+USD!J33*MN!$C$1 -> 36600 | ... N33: =+USD!N33*MN!$C$1 -> 36600
A34: ARTICULOS DE ASEO Y SANITARIOS | B34: =SUM(C34:N34) -> 1647000 | C34: =+USD!C34*MN!$C$1 -> 137250 | D34: =+USD!D34*MN!$C$1 -> 137250 | E34: =+USD!E34*MN!$C$1 -> 137250 | F34: =+USD!F34*MN!$C$1 -> 137250 | G34: =+USD!G34*MN!$C$1 -> 137250 | H34: =+USD!H34*MN!$C$1 -> 137250 | I34: =+USD!I34*MN!$C$1 -> 137250 | J34: =+USD!J34*MN!$C$1 -> 137250 | ... N34: =+USD!N34*MN!$C$1 -> 137250
A35: ARTICULOS DE CAFETERIA | B35: =SUM(C35:N35) -> 988200 | C35: =+USD!C35*MN!$C$1 -> 164700 | D35: =+USD!D35*MN!$C$1 -> 0 | E35: =+USD!E35*MN!$C$1 -> 164700 | F35: =+USD!F35*MN!$C$1 -> 0 | G35: =+USD!G35*MN!$C$1 -> 164700 | H35: =+USD!H35*MN!$C$1 -> 0 | I35: =+USD!I35*MN!$C$1 -> 164700 | J35: =+USD!J35*MN!$C$1 -> 0 | ... N35: =+USD!N35*MN!$C$1 -> 0
A36: ARTICULOS DIGITALES Y DE COMPUTO | B36: =SUM(C36:N36) -> 0 | C36: =+USD!C36*MN!$C$1 -> 0 | D36: =+USD!D36*MN!$C$1 -> 0 | E36: =+USD!E36*MN!$C$1 -> 0 | F36: =+USD!F36*MN!$C$1 -> 0 | G36: =+USD!G36*MN!$C$1 -> 0 | H36: =+USD!H36*MN!$C$1 -> 0 | I36: =+USD!I36*MN!$C$1 -> 0 | J36: =+USD!J36*MN!$C$1 -> 0 | ... N36: =+USD!N36*MN!$C$1 -> 0
A37: INSUMOS DE OFICINA | B37: =SUM(B33:B36) -> 3074400 | C37: =SUM(C33:C36) -> 338550 | D37: =SUM(D33:D36) -> 173850 | E37: =SUM(E33:E36) -> 338550 | F37: =SUM(F33:F36) -> 173850 | G37: =SUM(G33:G36) -> 338550 | H37: =SUM(H33:H36) -> 173850 | I37: =SUM(I33:I36) -> 338550 | ... N37: =SUM(N33:N36) -> 173850
A38: SERVICIOS DE MERCADOTECNIA | B38: =SUM(C38:N38) -> 0
A39: PUBLICIDAD Y PROPAGANDA | B39: =SUM(C39:N39) -> 0
A40: MARKETING | B40: =SUM(B38:B39) -> 0 | C40: =SUM(C38:C39) -> 0 | D40: =SUM(D38:D39) -> 0 | E40: =SUM(E38:E39) -> 0 | F40: =SUM(F38:F39) -> 0 | G40: =SUM(G38:G39) -> 0 | H40: =SUM(H38:H39) -> 0 | I40: =SUM(I38:I39) -> 0 | ... N40: =SUM(N38:N39) -> 0 | P40: Servicio mensual Jimena, publicación en periodico o revista digital, renovacion anual en el directorio de la industria enegetica y extras
A41: ABRASIVOS | B41: =SUM(C41:N41) -> 0 | C41: =+USD!C41*MN!$C$1 -> 0 | D41: =+USD!D41*MN!$C$1 -> 0 | E41: =+USD!E41*MN!$C$1 -> 0 | F41: =+USD!F41*MN!$C$1 -> 0 | G41: =+USD!G41*MN!$C$1 -> 0 | H41: =+USD!H41*MN!$C$1 -> 0 | I41: =+USD!I41*MN!$C$1 -> 0 | J41: =+USD!J41*MN!$C$1 -> 0 | ... N41: =+USD!N41*MN!$C$1 -> 0
...
